Workbook
Name IQ_CH: 110000
Name IQ_CQ: 5000
Name IQ_CY: 10000
Name IQ_DAILY: 500000
Name IQ_FH: 100000
Name IQ_FQ: 500
Name IQ_FY: 1000
Name IQ_LTM: 2000
Name IQ_MONTH: 15000
Name IQ_NTM: 6000
Name IQ_WEEK: 50000
Name IQ_YTD: 3000

Sheet 3Q26 Quick Look
A2: AT&T Inc. (T) — Q3 2026 Earnings First Look
A3: $M (except for as noted) | B3: 3Q25A | C3: 2Q26A | D3: 3Q26 Consensus | E3: 3Q26A | F3: YoY Growth (3Q26 vs 3Q25) | G3: Beat/(Miss) %
A4: Total Revenue | B4: =Segment!D30 -> 30709 | C4: =Segment!H30 -> 31558 | D4: =Segment!I30 -> 31667.9 | F4: =IF(E4="","",(E4-B4)/B4) | G4: =IF(E4="","",(E4-D4)/D4)
A5: Advanced Connectivity | B5: =Segment!D25 -> 27503 | C5: =Segment!H25 -> 28615 | D5: =Segment!I25 -> 28914.47 | F5: =IF(E5="","",(E5-B5)/B5) | G5: =IF(E5="","",(E5-D5)/D5)
A6: Consumer | B6: =Segment!D23 -> 21274 | C6: =Segment!H23 -> 22329 | D6: =Segment!I23 -> 22529.96 | F6: =IF(E6="","",(E6-B6)/B6) | G6: =IF(E6="","",(E6-D6)/D6)
A7: Business | B7: =Segment!D24 -> 6229 | C7: =Segment!H24 -> 6286 | D7: =Segment!I24 -> 6351.39 | F7: =IF(E7="","",(E7-B7)/B7) | G7: =IF(E7="","",(E7-D7)/D7)
A8: Legacy | B8: =Segment!D26 -> 2013 | C8: =Segment!H26 -> 1632 | D8: =Segment!I26 -> 1504.54 | F8: =IF(E8="","",(E8-B8)/B8) | G8: =IF(E8="","",(E8-D8)/D8)
A9: Latin America Segment - Mexico | B9: =Segment!D28 -> 1095 | C9: =Segment!H28 -> 1224 | D9: =Segment!I28 -> 1149.49 | F9: =IF(E9="","",(E9-B9)/B9) | G9: =IF(E9="","",(E9-D9)/D9)
A10: Corporate | B10: =Segment!D29 -> 98 | C10: =Segment!H29 -> 87 | D10: =Segment!I29 -> 91.86 | F10: =IF(E10="","",(E10-B10)/B10) | G10: =IF(E10="","",(E10-D10)/D10)
A11: Total EBITDA | B11: ='Income Statement'!D35 -> 11861 | C11: ='Income Statement'!H35 -> 12338 | D11: ='Income Statement'!I35 -> 12325.8 | F11: =IF(E11="","",(E11-B11)/B11) | G11: =IF(E11="","",(E11-D11)/D11)
A12: Advanced Connectivity | B12: =Segment!D43 -> 11493 | C12: =Segment!H43 -> 12032 | D12: =Segment!I43 -> 12240.49 | F12: =IF(E12="","",(E12-B12)/B12) | G12: =IF(E12="","",(E12-D12)/D12)
A13: Legacy | B13: =Segment!D44 -> 679 | C13: =Segment!H44 -> 523 | D13: =Segment!I44 -> 414.73 | F13: =IF(E13="","",(E13-B13)/B13) | G13: =IF(E13="","",(E13-D13)/D13)
A14: Latin America Segment - Mexico | B14: =Segment!D46 -> 199 | C14: =Segment!H46 -> 227 | D14: =Segment!I46 -> 205.57 | F14: =IF(E14="","",(E14-B14)/B14) | G14: =IF(E14="","",(E14-D14)/D14)
A15: Corporate | B15: =B11-B12-B13-B14 -> -510 | C15: =C11-C12-C13-C14 -> -444 | D15: =D11-D12-D13-D14 -> -534.99 | E15: =IF(OR(E11="",E12="",E13="",E14=""),"",E11-E12-E13-E14) | F15: =IF(E15="","",(E15-B15)/B15) | G15: =IF(E15="","",(E15-D15)/D15)
A16: Total EBITDA Margin | B16: =B11/B4 -> 0.38623856 | C16: =C11/C4 -> 0.39096267 | D16: =D11/D4 -> 0.38922063 | E16: =IF(OR(E11="",E4=""),"",E11/E4) | F16: =IF(E16="","",E16-B16) | G16: =IF(E16="","",E16-D16)
A17: Advanced Connectivity Margin | B17: =B12/B5 -> 0.41788169 | C17: =C12/C5 -> 0.42047877 | D17: =D12/D5 -> 0.42333441 | E17: =IF(OR(E12="",E5=""),"",E12/E5) | F17: =IF(E17="","",E17-B17) | G17: =IF(E17="","",E17-D17)
A18: Legacy Margin | B18: =B13/B8 -> 0.3373075 | C18: =C13/C8 -> 0.32046569 | D18: =D13/D8 -> 0.27565236 | E18: =IF(OR(E13="",E8=""),"",E13/E8) | F18: =IF(E18="","",E18-B18) | G18: =IF(E18="","",E18-D18)
A19: Latin America Segment - Mexico Margin | B19: =B14/B9 -> 0.18173516 | C19: =C14/C9 -> 0.18545752 | D19: =D14/D9 -> 0.17883583 | E19: =IF(OR(E14="",E9=""),"",E14/E9) | F19: =IF(E19="","",E19-B19) | G19: =IF(E19="","",E19-D19)
A20: Cash From Operating Activities | B20: ='Cash Flow'!D31 -> 10152 | C20: ='Cash Flow'!H31 -> 10801 | D20: ='Cash Flow'!I31 -> 10667.33 | F20: =IF(E20="","",(E20-B20)/B20) | G20: =IF(E20="","",(E20-D20)/D20)
A21: Capital Investment & Distributions | B21: ='Cash Flow'!D65 -> 5287 | C21: ='Cash Flow'!H65 -> 6131 | D21: ='Cash Flow'!I65 -> 5839.69 | F21: =IF(E21="","",(E21-B21)/B21) | G21: =IF(E21="","",(E21-D21)/D21)
A22: Free Cashflow | B22: ='Free Cash Flow'!D23 -> 4865 | C22: ='Free Cash Flow'!H23 -> 4670 | D22: ='Free Cash Flow'!I23 -> 4900.42 | F22: =IF(E22="","",(E22-B22)/B22) | G22: =IF(E22="","",(E22-D22)/D22)
A23: Adjusted EPS | B23: ='Income Statement'!D62 -> 0.54 | C23: ='Income Statement'!H62 -> 0.65 | D23: ='Income Statement'!I62 -> 0.6 | F23: =IF(E23="","",(E23-B23)/B23) | G23: =IF(E23="","",(E23-D23)/D23)
A25: Operational metrics
A26: Postpaid Phone Net Adds (in 000') | B26: ='AC Wireless'!D38 -> 405 | C26: ='AC Wireless'!H38 -> 432 | D26: ='AC Wireless'!I38 -> 382.61 | F26: =IF(E26="","",(E26-B26)/B26) | G26: =IF(E26="","",(E26-D26)/D26)
A27: Prepaid Phone Net Adds (in 000') | B27: ='AC Wireless'!D60 -> -83 | C27: ='AC Wireless'!H60 -> 4 | D27: ='AC Wireless'!I60 -> -67.97 | F27: =IF(E27="","",(E27-B27)/B27) | G27: =IF(E27="","",(E27-D27)/D27)
A28: Postpaid Phone-Only Churn (in %) | B28: ='AC Wireless'!D36 -> 0.0092 | C28: ='AC Wireless'!H36 -> 0.0086 | D28: ='AC Wireless'!I36 -> 0.0091 | F28: =IF(E28="","",E28-B28) | G28: =IF(E28="","",E28-D28)
A29: Postpaid Phone ARPU (in $) | B29: ='AC Wireless'!D43 -> 56.64 | C29: ='AC Wireless'!H43 -> 58.01 | D29: ='AC Wireless'!I43 -> 57.57 | F29: =IF(E29="","",(E29-B29)/B29) | G29: =IF(E29="","",(E29-D29)/D29)
A30: Cons. Fiber Net Adds (in 000') | B30: ='AC Internet'!D17 -> 288 | C30: ='AC Internet'!H17 -> 344 | D30: ='AC Internet'!I17 -> 364.28 | F30: =IF(E30="","",(E30-B30)/B30) | G30: =IF(E30="","",(E30-D30)/D30)
A31: Fiber ARPU (in $) | B31: ='AC Internet'!D20 -> 73.48 | C31: ='AC Internet'!H20 -> 72.29 | D31: ='AC Internet'!I20 -> 73.05 | F31: =IF(E31="","",(E31-B31)/B31) | G31: =IF(E31="","",(E31-D31)/D31)
A32: Consumer Locations Passed w/ Fiber (in millions) | B32: ='AC Internet'!D77/1000 -> 25.4 | C32: ='AC Internet'!H77/1000 -> 32.1 | D32: ='AC Internet'!I77/1000 -> 33.02435 | F32: =IF(E32="","",(E32-B32)/B32) | G32: =IF(E32="","",(E32-D32)/D32)
A33: Cons. FWA Net Adds (in 000') | B33: ='AC Internet'!D23 -> 270 | C33: ='AC Internet'!H23 -> 215 | D33: ='AC Internet'!I23 -> 245.41 | F33: =IF(E33="","",(E33-B33)/B33) | G33: =IF(E33="","",(E33-D33)/D33)

Sheet CapIQ cons on Oct 20, 2026 ->

Sheet Revenue
A2: AT&T Inc. | Revenue
A3: NYSE:T (MI KEY: 4024242; SPCIQ KEY: 100231)
A5: Visible Alpha
A7: Period Type : Fiscal Quarter, Fiscal Halves, Fiscal Year
A8: Period Start : 2025
A9: Period End : 2030
A10: Currency : Reported
A11: Consensus View : Mean
A12: As Of: 10/20/2026
A14: All numbers in $M unless otherwise indicated | B14: FQ1 2025A | C14: FQ2 2025A | D14: FQ3 2025A | E14: FQ4 2025A | F14: FY2025A | G14: FQ1 2026A | H14: FQ2 2026A | I14: FQ3 2026E | J14: FQ4 2026E | K14: FY2026E | L14: FQ1 2027E | M14: FQ2 2027E | N14: FQ3 2027E | O14: FQ4 2027E | P14: FY2027E | Q14: FQ1 2028E | R14: FQ2 2028E | S14: FQ3 2028E | T14: FQ4 2028E | U14: FY2028E | V14: FQ1 2029E | W14: FQ2 2029E | X14: FQ3 2029E | Y14: FQ4 2029E | Z14: FY2029E | AA14: FQ1 2030E | AB14: FQ2 2030E | AC14: FQ3 2030E | AD14: FQ4 2030E | AE14: FY2030E
A15: Number of Contributors Available | B15: 19 | C15: 19 | D15: 19 | E15: 19 | F15: 20 | G15: 19 | H15: 19 | I15: 20 of 20 | J15: 20 of 20 | K15: 20 of 20 | L15: 14 of 20 | M15: 14 of 20 | N15: 13 of 20 | O15: 13 of 20 | P15: 20 of 20 | Q15: 7 of 20 | R15: 7 of 20 | S15: 7 of 20 | T15: 7 of 20 | U15: 17 of 20 | V15: 5 of 20 | W15: 5 of 20 | X15: 5 of 20 | Y15: 5 of 20 | Z15: 14 of 20 | AA15: 5 of 20 | AB15: 5 of 20 | AC15: 5 of 20 | AD15: 5 of 20 | AE15: 14 of 20
A16: Revenue - Postpaid Phones | B16: 12367.98 | C16: 12529.32 | D16: 12506.88 | E16: 12559.81 | F16: 49963.99 | G16: 12606 | H16: 13002.13 | I16: 12974.19 | J16: 13029.43 | K16: 51619.5 | L16: 13055.68 | M16: 13282.62 | N16: 13309.32 | O16: 13348.75 | P16: 52964.38 | Q16: 13348.78 | R16: 13588.7 | S16: 13554.23 | T16: 13641.23 | U16: 54139.56 | V16: 13602.74 | W16: 13900.58 | X16: 13850.67 | Y16: 13853.6 | Z16: 55176.6 | AA16: 13842.67 | AB16: 14136.45 | AC16: 14092.59 | AD16: 14089.93 | AE16: 56133.23
A17: Revenue - Prepaid Phones | B17: 1885.86 | C17: 1895.5 | D17: 1877.86 | E17: 1838.22 | F17: 7497.44 | G17: 1816.33 | H17: 1826.07 | I17: 1822.32 | J17: 1799.38 | K17: 7261.47 | L17: 1783.48 | M17: 1790.76 | N17: 1791.92 | O17: 1772.23 | P17: 7123.76 | Q17: 1751.46 | R17: 1758.84 | S17: 1761.91 | T17: 1740.3 | U17: 7021.62 | V17: 1710.93 | W17: 1719.23 | X17: 1728.6 | Y17: 1698.59 | Z17: 6908.7 | AA17: 1675.84 | AB17: 1683.56 | AC17: 1696.63 | AD17: 1667.34 | AE17: 6810.33
A18: Revenue - Phone | B18: 14253.84 | C18: 14424.82 | D18: 14384.74 | E18: 14398.03 | F18: 57461.43 | G18: 14422.32 | H18: 14828.2 | I18: 14784.47 | J18: 14818.18 | K18: 58851.72 | L18: 14839.17 | M18: 15073.38 | N18: 15101.24 | O18: 15120.97 | P18: 60063.77 | Q18: 15100.24 | R18: 15347.53 | S18: 15316.14 | T18: 15381.53 | U18: 61106.63 | V18: 15313.67 | W18: 15619.81 | X18: 15579.28 | Y18: 15552.2 | Z18: 61984.93 | AA18: 15518.51 | AB18: 15820.01 | AC18: 15789.22 | AD18: 15757.28 | AE18: 62805.57
A19: Revenue - Other subscribers | B19: 2397.16 | C19: 2428.18 | D19: 2541.26 | E19: 2555.97 | F19: 9922.57 | G19: 2518.68 | H19: 2584.8 | I19: 2737.75 | J19: 2745.11 | K19: 10586.89 | L19: 2664.31 | M19: 2765.9 | N19: 2870.49 | O19: 2865.51 | P19: 11137.22 | Q19: 2789.04 | R19: 2866.47 | S19: 3006.11 | T19: 2992.07 | U19: 11603.55 | V19: 2738.58 | W19: 2832.07 | X19: 2948.97 | Y19: 2955.26 | Z19: 11720.51 | AA19: 2800.05 | AB19: 2878.78 | AC19: 3021.87 | AD19: 3002.58 | AE19: 12024.8
A20: Service revenues - wireless | B20: 16651 | C20: 16853 | D20: 16926 | E20: 16954 | F20: 67384 | G20: 16941 | H20: 17413 | I20: 17526.97 | J20: 17565.72 | K20: 69453.75 | L20: 17503.72 | M20: 17839.36 | N20: 17971.16 | O20: 17985.62 | P20: 71247.05 | Q20: 17888.28 | R20: 18213.15 | S20: 18321.82 | T20: 18373.47 | U20: 72800.94 | V20: 18052.25 | W20: 18451.87 | X20: 18528.25 | Y20: 18507.46 | Z20: 73883.32 | AA20: 18318.56 | AB20: 18698.79 | AC20: 18811.09 | AD20: 18759.85 | AE20: 75056.66
A21: Fiber revenue | B21: 2066 | C21: 2136 | D21: 2198 | E21: 2245 | F21: 8645 | G21: 2505 | H21: 2593 | I21: 2667.53 | J21: 2733.45 | K21: 10498.26 | L21: 2872.55 | M21: 2926.28 | N21: 3016.16 | O21: 3087.23 | P21: 11955.67 | Q21: 3260.63 | R21: 3322.67 | S21: 3429.64 | T21: 3501.33 | U21: 13493.42 | V21: 3745.84 | W21: 3815.16 | X21: 3936.65 | Y21: 4032.36 | Z21: 15207.68 | AA21: 4224.6 | AB21: 4292.53 | AC21: 4417.96 | AD21: 4514.36 | AE21: 16897.84
A22: AT&T Internet Air revenue | B22: 132 | C22: 163 | D22: 213 | E22: 257 | F22: 765 | G22: 294 | H22: 333 | I22: 383.24 | J22: 426.95 | K22: 1437.27 | L22: 464.32 | M22: 499.52 | N22: 553.99 | O22: 596.25 | P22: 2109.42 | Q22: 618.99 | R22: 644.6 | S22: 700.88 | T22: 736.82 | U22: 2717.44 | V22: 754.5 | W22: 774.89 | X22: 835.48 | Y22: 867.05 | Z22: 3255.19 | AA22: 886.28 | AB22: 902.73 | AC22: 965.38 | AD22: 994.24 | AE22: 3734.21
A23: Advanced home internet services revenue - Advanced connectivity | B23: 2198 | C23: 2299 | D23: 2411 | E23: 2502 | F23: 9410 | G23: 2799 | H23: 2926 | I23: 3065.8 | J23: 3181.73 | K23: 11993.31 | L23: 3349.99 | M23: 3432.08 | N23: 3580.82 | O23: 3701.07 | P23: 14128.13 | Q23: 3902.26 | R23: 3977 | S23: 4148.02 | T23: 4268.25 | U23: 16264.78 | V23: 4500.34 | W23: 4590.05 | X23: 4772.13 | Y23: 4899.41 | Z23: 18469.22 | AA23: 5110.89 | AB23: 5195.26 | AC23: 5383.34 | AD23: 5508.6 | AE23: 20618.1
A24: Business fiber and advanced connectivity services revenue - Advanced connectivity | B24: 1755 | C24: 1769 | D24: 1832 | E24: 1887 | F24: 7243 | G24: 1882 | H24: 1946 | I24: 1992 | J24: 2046.85 | K24: 7866.85 | L24: 2037 | M24: 2106.48 | N24: 2146.61 | O24: 2196.75 | P24: 8495 | Q24: 2177.4 | R24: 2237.25 | S24: 2261.04 | T24: 2304.39 | U24: 9092.5 | V24: 2376.18 | W24: 2438.72 | X24: 2476.61 | Y24: 2524.98 | Z24: 9847.16 | AA24: 2545.26 | AB24: 2606.66 | AC24: 2642.05 | AD24: 2689.49 | AE24: 10498.97
A25: Business transitional and other service revenue - Advanced connectivity | B25: 1294 | C25: 1249 | D25: 1198 | E25: 1170 | F25: 4911 | G25: 1083 | H25: 1042 | I25: 1021.53 | J25: 998.08 | K25: 4144.61 | L25: 932.87 | M25: 898.49 | N25: 881.42 | O25: 861.16 | P25: 3570.63 | Q25: 825.83 | R25: 794.57 | S25: 781.55 | T25: 764.06 | U25: 3148.6 | V25: 751.58 | W25: 723.62 | X25: 717.62 | Y25: 702.74 | Z25: 2813.96 | AA25: 677.3 | AB25: 652.18 | AC25: 647.12 | AD25: 633.78 | AE25: 2502.93
A26: Other services revenue - Advanced connectivity | B26: 162 | C26: 164 | D26: 162 | E26: 162 | F26: 650 | G26: 158 | H26: 151 | I26: 156.01 | J26: 156.22 | K26: 621.23 | L26: 152.8 | M26: 145.26 | N26: 150.43 | O26: 151.27 | P26: 597.96 | Q26: 146.75 | R26: 139.75 | S26: 144.31 | T26: 144.33 | U26: 577.04 | V26: 139.03 | W26: 132.63 | X26: 135.72 | Y26: 135.78 | Z26: 553.59 | AA26: 133.37 | AB26: 127.21 | AC26: 130.19 | AD26: 130.25 | AE26: 534.11
A27: Total service revenue - Advanced connectivity | B27: 22060 | C27: 22334 | D27: 22529 | E27: 22675 | F27: 89598 | G27: 22863 | H27: 23478 | I27: 23773.75 | J27: 23938.35 | K27: 94053.1 | L27: 23956.91 | M27: 24425.9 | N27: 24752.97 | O27: 24872.93 | P27: 97976.67 | Q27: 24940.53 | R27: 25361.72 | S27: 25656.74 | T27: 25854.49 | U27: 101853.62 | V27: 25819.37 | W27: 26336.89 | X27: 26630.33 | Y27: 26770.37 | Z27: 105551.96 | AA27: 26785.38 | AB27: 27280.1 | AC27: 27613.79 | AD27: 27721.97 | AE27: 109247.44
... A39: Operating revenues | B39: 30626 | C39: 30847 | D39: 30709 | E39: 33466 | F39: 125648 | G39: 31506 | H39: 31558 | I39: 31667.9 | J39: 34499.33 | K39: 129215.33 | L39: 32202.3 | M39: 32251.94 | N39: 32421.74 | O39: 35255.95 | P39: 132052.75 | Q39: 32816.09 | R39: 32690.07 | S39: 32932.11 | T39: 36065 | U39: 134712.76 | V39: 33509.2 | W39: 33519.5 | X39: 33751.99 | Y39: 36931.43 | Z39: 138007.48 | AA39: 34358.45 | AB39: 34370.16 | AC39: 34660.88 | AD39: 37859.21 | AE39: 141694.19

Sheet Segment
A2: AT&T Inc. | Segment
A3: NYSE:T (MI KEY: 4024242; SPCIQ KEY: 100231)
A5: Visible Alpha
A7: Period Type : Fiscal Quarter, Fiscal Halves, Fiscal Year
A8: Period Start : 2025
A9: Period End : 2030
A10: Currency : Reported
A11: Consensus View : Mean
A12: As Of: 10/20/2026
A14: All numbers in $M unless otherwise indicated | B14: FQ1 2025A | C14: FQ2 2025A | D14: FQ3 2025A | E14: FQ4 2025A | F14: FY2025A | G14: FQ1 2026A | H14: FQ2 2026A | I14: FQ3 2026E | J14: FQ4 2026E | K14: FY2026E | L14: FQ1 2027E | M14: FQ2 2027E | N14: FQ3 2027E | O14: FQ4 2027E | P14: FY2027E | Q14: FQ1 2028E | R14: FQ2 2028E | S14: FQ3 2028E | T14: FQ4 2028E | U14: FY2028E | V14: FQ1 2029E | W14: FQ2 2029E | X14: FQ3 2029E | Y14: FQ4 2029E | Z14: FY2029E | AA14: FQ1 2030E | AB14: FQ2 2030E | AC14: FQ3 2030E | AD14: FQ4 2030E | AE14: FY2030E
A15: Number of Contributors Available | B15: 19 | C15: 19 | D15: 19 | E15: 19 | F15: 20 | G15: 19 | H15: 19 | I15: 20 of 20 | J15: 20 of 20 | K15: 20 of 20 | L15: 14 of 20 | M15: 14 of 20 | N15: 13 of 20 | O15: 13 of 20 | P15: 20 of 20 | Q15: 7 of 20 | R15: 7 of 20 | S15: 7 of 20 | T15: 7 of 20 | U15: 17 of 20 | V15: 5 of 20 | W15: 5 of 20 | X15: 5 of 20 | Y15: 5 of 20 | Z15: 14 of 20 | AA15: 5 of 20 | AB15: 5 of 20 | AC15: 5 of 20 | AD15: 5 of 20 | AE15: 14 of 20
A16: Service revenue
A17: Total service revenue - Advanced connectivity | B17: 22060 | C17: 22334 | D17: 22529 | E17: 22675 | F17: 89598 | G17: 22863 | H17: 23478 | I17: 23773.75 | J17: 23938.35 | K17: 94053.1 | L17: 23956.91 | M17: 24425.9 | N17: 24752.97 | O17: 24872.93 | P17: 97976.67 | Q17: 24940.53 | R17: 25361.72 | S17: 25656.74 | T17: 25854.49 | U17: 101853.62 | V17: 25819.37 | W17: 26336.89 | X17: 26630.33 | Y17: 26770.37 | Z17: 105551.96 | AA17: 26785.38 | AB17: 27280.1 | AC17: 27613.79 | AD17: 27721.97 | AE17: 109247.44
A18: Revenue - Legacy | B18: 2368 | C18: 2202 | D18: 2013 | E18: 1889 | F18: 8472 | G18: 1768 | H18: 1632 | I18: 1504.54 | J18: 1400.95 | K18: 6305.49 | L18: 1259.37 | M18: 1143.27 | N18: 1040.74 | O18: 947.12 | P18: 4358.11 | Q18: 724.43 | R18: 642.29 | S18: 563.6 | T18: 501.43 | U18: 2651.29 | V18: 457.63 | W18: 399.61 | X18: 351.66 | Y18: 311.9 | Z18: 1654.41 | AA18: 346.97 | AB18: 422.12 | AC18: 391.25 | AD18: 358.64 | AE18: 1423.71
A19: Mexico wireless service revenue | B19: 615 | C19: 662 | D19: 696 | E19: 742 | F19: 2715 | G19: 753 | H19: 780 | I19: 713.78 | J19: 732.21 | K19: 2968.51 | L19: 732.73 | M19: 747.95 | N19: 703.81 | O19: 725.43 | P19: 2930.77 | Q19: 730.95 | R19: 759.87 | S19: 687.77 | T19: 716.48 | U19: 2982.09 | V19: 746.61 | W19: 777.66 | X19: 702.78 | Y19: 732.7 | Z19: 3056.4 | AA19: 761.41 | AB19: 792.13 | AC19: 711.2 | AD19: 741.48 | AE19: 3089.88
A20: Total revenue- Services | B20: 25043 | C20: 25198 | D20: 25238 | E20: 25306 | F20: 100785 | G20: 25384 | H20: 25890 | I20: 25981.49 | J20: 26080.84 | K20: 103336.33 | L20: 25962.47 | M20: 26311.25 | N20: 26466.93 | O20: 26555.69 | P20: 105241.21 | Q20: 26395.9 | R20: 26763.88 | S20: 26908.1 | T20: 27072.4 | U20: 107452.64 | V20: 27023.61 | W20: 27514.16 | X20: 27684.76 | Y20: 27814.97 | Z20: 110255.08 | AA20: 27824.37 | AB20: 28320.9 | AC20: 28550.11 | AD20: 28673.04 | AE20: 113402.32
A22: Revenue
A23: Advanced connectivity revenue - Consumer | B23: 20976 | C23: 21295 | D23: 21274 | E23: 23714 | F23: 87259 | G23: 22152 | H23: 22329 | I23: 22529.96 | J23: 25029.95 | K23: 92040.91 | L23: 23462.97 | M23: 23392.31 | N23: 23565.52 | O23: 26179.82 | P23: 96421.23 | Q23: 24714.22 | R23: 24491.93 | S23: 24932.98 | T23: 27733.77 | U23: 100613.03 | V23: 24779.24 | W23: 24718.62 | X23: 24902.3 | Y23: 27397.07 | Z23: 103600.7 | AA23: 25594.82 | AB23: 25389.47 | AC23: 25797.44 | AD23: 28174.46 | AE23: 107201.91
A24: Advanced connectivity revenue - Business | B24: 6216 | C24: 6202 | D24: 6229 | E24: 6518 | F24: 25165 | G24: 6319 | H24: 6286 | I24: 6351.39 | J24: 6646.63 | K24: 25603.02 | L24: 6355.07 | M24: 6318.73 | N24: 6323.6 | O24: 6684.2 | P24: 25891.13 | Q24: 6213.54 | R24: 6127.74 | S24: 6073.02 | T24: 6458.46 | U24: 26338.13 | V24: 6751.83 | W24: 6761.24 | X24: 6830.18 | Y24: 7364.61 | Z24: 27685.84 | AA24: 6911.7 | AB24: 6959.73 | AC24: 6998.7 | AD24: 7571.13 | AE24: 28524.77
A25: Advanced connectivity revenue | B25: 27192 | C25: 27497 | D25: 27503 | E25: 30232 | F25: 112424 | G25: 28471 | H25: 28615 | I25: 28914.47 | J25: 31785.77 | K25: 117786.24 | L25: 29666.41 | M25: 29801.33 | N25: 30135.6 | O25: 32964.52 | P25: 122554.94 | Q25: 30819.32 | R25: 30756.72 | S25: 31139.59 | T25: 34200.76 | U25: 126842.92 | V25: 31761.37 | W25: 31784.6 | X25: 32176.01 | Y25: 35256.45 | Z25: 131064.38 | AA25: 32770.35 | AB25: 32765.27 | AC25: 33199.27 | AD25: 36273.42 | AE25: 135287.83
A26: Revenue - Legacy | B26: 2368 | C26: 2202 | D26: 2013 | E26: 1889 | F26: 8472 | G26: 1768 | H26: 1632 | I26: 1504.54 | J26: 1400.95 | K26: 6305.49 | L26: 1259.37 | M26: 1143.27 | N26: 1040.74 | O26: 947.12 | P26: 4358.11 | Q26: 724.43 | R26: 642.29 | S26: 563.6 | T26: 501.43 | U26: 2651.29 | V26: 457.63 | W26: 399.61 | X26: 351.66 | Y26: 311.9 | Z26: 1654.41 | AA26: 346.97 | AB26: 422.12 | AC26: 391.25 | AD26: 358.64 | AE26: 1423.71
A27: Total Communications Revenue | B27: 29560 | C27: 29699 | D27: 29516 | E27: 32121 | F27: 120896 | G27: 30239 | H27: 30247 | I27: 30400.09 | J27: 33156.3 | K27: 124037.87 | L27: 30930.93 | M27: 30937.15 | N27: 31150.69 | O27: 33884.32 | P27: 126817.07 | Q27: 31543.74 | R27: 31399.01 | S27: 31703.19 | T27: 34702.19 | U27: 129463.7 | V27: 32219 | W27: 32184.21 | X27: 32527.67 | Y27: 35568.35 | Z27: 132680.51 | AA27: 33047.92 | AB27: 33013.94 | AC27: 33424.39 | AD27: 36483.01 | AE27: 136284.21
A28: Latin America revenue | B28: 971 | C28: 1054 | D28: 1095 | E28: 1259 | F28: 4379 | G28: 1173 | H28: 1224 | I28: 1149.49 | J28: 1247.25 | K28: 4784.74 | L28: 1185.98 | M28: 1221.23 | N28: 1155.52 | O28: 1261.88 | P28: 4833.03 | Q28: 1180.21 | R28: 1202.82 | S28: 1138.85 | T28: 1275.94 | U28: 4891.37 | V28: 1198.29 | W28: 1248.73 | X28: 1135.25 | Y28: 1278.41 | Z28: 4975.67 | AA28: 1219.63 | AB28: 1270.61 | AC28: 1148.41 | AD28: 1292.46 | AE28: 5043.04
A29: Revenue - Corporate, Video and other | B29: 95 | C29: 94 | D29: 98 | E29: 86 | F29: 373 | G29: 94 | H29: 87 | I29: 91.86 | J29: 85.73 | K29: 357.8 | L29: 90.65 | M29: 87.67 | N29: 89.24 | O29: 82.57 | P29: 348.55 | Q29: 90.89 | R29: 89.37 | S29: 88.26 | T29: 86.48 | U29: 346.94 | V29: 88.76 | W29: 86.68 | X29: 85.12 | Y29: 82.64 | Z29: 338.27 | AA29: 85.24 | AB29: 83.2 | AC29: 81.65 | AD29: 79.17 | AE29: 330.57
A30: Operating revenues | B30: 30626 | C30: 30847 | D30: 30709 | E30: 33466 | F30: 125648 | G30: 31506 | H30: 31558 | I30: 31667.9 | J30: 34499.33 | K30: 129215.33 | L30: 32202.3 | M30: 32251.94 | N30: 32421.74 | O30: 35255.95 | P30: 132052.75 | Q30: 32816.09 | R30: 32690.07 | S30: 32932.11 | T30: 36065 | U30: 134712.76 | V30: 33509.2 | W30: 33519.5 | X30: 33751.99 | Y30: 36931.43 | Z30: 138007.48 | AA30: 34358.45 | AB30: 34370.16 | AC30: 34660.88 | AD30: 37859.21 | AE30: 141694.19
A32: Operations and support
A33: Operations and support - Advanced connectivity | B33: 16247 | C33: 16356 | D33: 16010 | E33: 19264 | F33: 67877 | G33: 16913 | H33: 16583 | I33: 16676.2 | J33: 20026.37 | K33: 70198.57 | L33: 17398.56 | M33: 16986.46 | N33: 17017.35 | O33: 20522.4 | P33: 71910.54 | Q33: 17636.4 | R33: 17172.41 | S33: 17338.98 | T33: 20944.83 | U33: 73205.38 | V33: 17991.32 | W33: 17540.6 | X33: 17751.89 | Y33: 21431.53 | Z33: 74994.98 | AA33: 18376.86 | AB33: 17916.25 | AC33: 18158.54 | AD33: 21868.9 | AE33: 76752.61
A34: Operations and support - Legacy | B34: 1349 | C34: 1243 | D34: 1334 | E34: 1207 | F34: 5133 | G34: 1156 | H34: 1109 | I34: 1088.62 | J34: 1013.43 | K34: 4367.05 | L34: 954.26 | M34: 918.11 | N34: 904.81 | O34: 849.62 | P34: 3590.8 | Q34: 723.81 | R34: 685.82 | S34: 664.65 | T34: 619.99 | U34: 2722.26 | V34: 562.19 | W34: 519.21 | X34: 486.12 | Y34: 444.68 | Z34: 1903.29 | AA34: 455.7 | AB34: 430.04 | AC34: 412.99 | AD34: 383.05 | AE34: 1541.27
A35: Operations and Support - Communications | B35: 17596 | C35: 17599 | D35: 17344 | E35: 20471 | F35: 73010 | G35: 18069 | H35: 17692 | I35: 17758.46 | J35: 20976.91 | K35: 74508 | L35: 18301.1 | M35: 17953.1 | N35: 18017.66 | O35: 21267.26 | P35: 75477.07 | Q35: 18360.21 | R35: 17858.23 | S35: 18003.64 | T35: 21564.81 | U35: 75931.89 | V35: 18553.51 | W35: 18059.81 | X35: 18238.01 | Y35: 21876.2 | Z35: 76955.08 | AA35: 18741.42 | AB35: 18260.28 | AC35: 18488.93 | AD35: 22175.34 | AE35: 78122.71
A36: Operations and support - Latin America | B36: 778 | C36: 853 | D36: 896 | E36: 1036 | F36: 3563 | G36: 953 | H36: 997 | I36: 940.16 | J36: 1022.58 | K36: 3904.51 | L36: 961.39 | M36: 987.02 | N36: 937.2 | O36: 1027.98 | P36: 3911.34 | Q36: 956.9 | R36: 973.35 | S36: 931.92 | T36: 1042.68 | U36: 3957.45 | V36: 973.78 | W36: 1011.7 | X36: 924.04 | Y36: 1047.28 | Z36: 4010.34 | AA36: 989.46 | AB36: 1027.67 | AC36: 933.24 | AD36: 1057.07 | AE36: 4055.68
A37: Operations and Support - Corporate, Video and other | B37: 719 | C37: 643 | D37: 1033 | E37: 1043 | F37: 4027 | G37: 860 | H37: 865 | I37: 629.37 | J37: 860.51 | K37: 2986.31 | L37: 708.14 | M37: 581.56 | N37: 603.66 | O37: 845.88 | P37: 2639.66 | Q37: 675.39 | R37: 594.5 | S37: 590.87 | T37: 638.17 | U37: 2385.31 | V37: 774.05 | W37: 605.16 | X37: 613.89 | Y37: 679.09 | Z37: 2405.85 | AA37: 753.27 | AB37: 604.02 | AC37: 612.53 | AD37: 691.33 | AE37: 2394.09
A38: Operations and support | B38: 19178 | C38: 19095 | D38: 19273 | E38: 22550 | F38: 80600 | G38: 19882 | H38: 19554 | I38: 19301.39 | J38: 22825.63 | K38: 81467.69 | L38: 19949.35 | M38: 19564.71 | N38: 19653.94 | O38: 23126.5 | P38: 81986.96 | Q38: 19950.66 | R38: 19511.28 | S38: 19678.8 | T38: 23367.68 | U38: 82218.03 | V38: 20278.15 | W38: 19912.19 | X38: 20153.69 | Y38: 23994.39 | Z38: 84002.91 | AA38: 20487.78 | AB38: 20149.55 | AC38: 20421.3 | AD38: 24314.61 | AE38: 85196.02
A40: EBITDA
A41: EBITDA - Consumer - Advanced Connectivity | B41: 9175 | C41: 9429 | D41: 9701 | E41: 9286 | F41: 37591 | G41: 9563 | H41: 10095 | I41: 10259.68 | J41: 9843.87 | K41: 39761.55 | L41: 10288.58 | M41: 10559.43 | N41: 10906.72 | O41: 10370.65 | P41: 41999.89 | Q41: 10874.34 | R41: 11256.16 | S41: 11581.44 | T41: 11085.07 | U41: 44231.89 | V41: 11534.17 | W41: 11987.14 | X41: 12351.48 | Y41: 11762.15 | Z41: 46114.68 | AA41: 12100.96 | AB41: 12489.91 | AC41: 12992.3 | AD41: 12296.11 | AE41: 47966.94
A42: EBITDA - Business - Advanced Connectivity | B42: 1770 | C42: 1712 | D42: 1792 | E42: 1682 | F42: 6956 | G42: 1995 | H42: 1937 | I42: 1889.96 | J42: 1760.05 | K42: 7582.01 | L42: 2114.74 | M42: 2030.57 | N42: 1915.84 | O42: 1853.12 | P42: 8043.82 | Q42: 2278.64 | R42: 2167.74 | S42: 2041.93 | T42: 2044.29 | U42: 8483.89 | V42: 2331.14 | W42: 2283.3 | X42: 2178.08 | Y42: 2161.05 | Z42: 8887.01 | AA42: 2430.99 | AB42: 2400.71 | AC42: 2274.52 | AD42: 2275.18 | AE42: 9326.17
A43: EBITDA - Advanced connectivity | B43: 10945 | C43: 11141 | D43: 11493 | E43: 10968 | F43: 44547 | G43: 11558 | H43: 12032 | I43: 12240.49 | J43: 11713.56 | K43: 47544.04 | L43: 12315.75 | M43: 12759.45 | N43: 13038.25 | O43: 12399.7 | P43: 50510.31 | Q43: 13182.92 | R43: 13584.31 | S43: 13800.61 | T43: 13255.94 | U43: 53603.28 | V43: 13770.05 | W43: 14244 | X43: 14424.12 | Y43: 13824.92 | Z43: 56048.28 | AA43: 14393.48 | AB43: 14849.02 | AC43: 15040.72 | AD43: 14404.53 | AE43: 58480.23
A44: EBITDA - Legacy | B44: 1019 | C44: 959 | D44: 679 | E44: 682 | F44: 3339 | G44: 612 | H44: 523 | I44: 414.73 | J44: 387.29 | K44: 1937.02 | L44: 313.24 | M44: 238.89 | N44: 130.75 | O44: 90.76 | P44: 800.51 | Q44: 0.62 | R44: -43.53 | S44: -101.05 | T44: -118.56 | U44: -64.59 | V44: -104.55 | W44: -119.6 | X44: -134.46 | Y44: -132.77 | Z44: -279.23 | AA44: -48.87 | AB44: -54.61 | AC44: -131.58 | AD44: -121.07 | AE44: -203.86
A45: EBITDA - Communications | B45: 11964 | C45: 12100 | D45: 12172 | E45: 11650 | F45: 47886 | G45: 12170 | H45: 12555 | I45: 12656.3 | J45: 12107.95 | K45: 49465.67 | L45: 12628.99 | M45: 12998.33 | N45: 13169.01 | O45: 12490.46 | P45: 51281.25 | Q45: 13183.53 | R45: 13540.78 | S45: 13699.55 | T45: 13137.38 | U45: 53490.84 | V45: 13665.49 | W45: 14124.4 | X45: 14289.66 | Y45: 13692.15 | Z45: 55697.42 | AA45: 14306.5 | AB45: 14753.66 | AC45: 14935.46 | AD45: 14307.67 | AE45: 58139.93
A46: EBITDA - Latin America | B46: 193 | C46: 201 | D46: 199 | E46: 223 | F46: 816 | G46: 220 | H46: 227 | I46: 205.57 | J46: 224.38 | K46: 875.67 | L46: 220.07 | M46: 229.04 | N46: 209.24 | O46: 233.14 | P46: 907.83 | Q46: 223.31 | R46: 229.47 | S46: 206.93 | T46: 233.26 | U46: 933.92 | V46: 224.51 | W46: 237.03 | X46: 211.22 | Y46: 231.13 | Z46: 965.33 | AA46: 230.18 | AB46: 242.93 | AC46: 215.16 | AD46: 235.39 | AE46: 987.36
A47: EBITDA - Corporate & Other | B47: -624 | C47: -570 | D47: -510 | E47: -957 | F47: -2341 | G47: -766 | H47: -778 | I47: -537.6 | J47: -648.51 | K47: -2407.14 | L47: -591.39 | M47: -495.56 | N47: -509.14 | O47: -695.71 | P47: -2179.03 | Q47: -545.55 | R47: -545.67 | S47: -557.05 | T47: -621.21 | U47: -2008.13 | V47: -499.51 | W47: -500.59 | X47: -524.66 | Y47: -885.27 | Z47: -2070.74 | AA47: -484.94 | AB47: -495.24 | AC47: -518.46 | AD47: -606.26 | AE47: -1947.65
...

Sheet Income Statement
A2: AT&T Inc. | Income statement
A3: NYSE:T (MI KEY: 4024242; SPCIQ KEY: 100231)
A5: Visible Alpha
A7: Period Type : Fiscal Quarter, Fiscal Halves, Fiscal Year
A8: Period Start : 2025
A9: Period End : 2030
A10: Currency : Reported
A11: Consensus View : Mean
A12: As Of: 10/20/2026
A14: All numbers in $M unless otherwise indicated | B14: FQ1 2025A | C14: FQ2 2025A | D14: FQ3 2025A | E14: FQ4 2025A | F14: FY2025A | G14: FQ1 2026A | H14: FQ2 2026A | I14: FQ3 2026E | J14: FQ4 2026E | K14: FY2026E | L14: FQ1 2027E | M14: FQ2 2027E | N14: FQ3 2027E | O14: FQ4 2027E | P14: FY2027E | Q14: FQ1 2028E | R14: FQ2 2028E | S14: FQ3 2028E | T14: FQ4 2028E | U14: FY2028E | V14: FQ1 2029E | W14: FQ2 2029E | X14: FQ3 2029E | Y14: FQ4 2029E | Z14: FY2029E | AA14: FQ1 2030E | AB14: FQ2 2030E | AC14: FQ3 2030E | AD14: FQ4 2030E | AE14: FY2030E
A15: Number of Contributors Available | B15: 19 | C15: 19 | D15: 19 | E15: 19 | F15: 20 | G15: 19 | H15: 19 | I15: 20 of 20 | J15: 20 of 20 | K15: 20 of 20 | L15: 14 of 20 | M15: 14 of 20 | N15: 13 of 20 | O15: 13 of 20 | P15: 20 of 20 | Q15: 7 of 20 | R15: 7 of 20 | S15: 7 of 20 | T15: 7 of 20 | U15: 17 of 20 | V15: 5 of 20 | W15: 5 of 20 | X15: 5 of 20 | Y15: 5 of 20 | Z15: 14 of 20 | AA15: 5 of 20 | AB15: 5 of 20 | AC15: 5 of 20 | AD15: 5 of 20 | AE15: 14 of 20
A16: Service revenue | B16: 25138 | C16: 25292 | D16: 25336 | E16: 25392 | F16: 101158 | G16: 25478 | H16: 25977 | I16: 26084.69 | J16: 26176.83 | K16: 103631.83 | L16: 25994.06 | M16: 26322.71 | N16: 26558.6 | O16: 26629.08 | P16: 105457.07 | Q16: 26502.43 | R16: 26837.57 | S16: 27081.09 | T16: 27245.72 | U16: 107631.46 | V16: 27105.05 | W16: 27545.49 | X16: 27809.42 | Y16: 27934.14 | Z16: 110294.63 | AA16: 27930.57 | AB16: 28368.56 | AC16: 28700.02 | AD16: 28811.82 | AE16: 113527.44
A17: Equipment revenue | B17: 5488 | C17: 5555 | D17: 5373 | E17: 8074 | F17: 24490 | G17: 6028 | H17: 5581 | I17: 5537.36 | J17: 8360.35 | K17: 25604.28 | L17: 6209.08 | M17: 5766.98 | N17: 5671.96 | O17: 8683.29 | P17: 26373.77 | Q17: 6324.85 | R17: 5807.87 | S17: 5801.47 | T17: 8861.17 | U17: 26911.66 | V17: 6334.48 | W17: 5876.7 | X17: 5791.98 | Y17: 8879.75 | Z17: 27349.31 | AA17: 6382.16 | AB17: 5919.4 | AC17: 5830.49 | AD17: 8939.82 | AE17: 27761.39
A18: Operating revenues | B18: 30626 | C18: 30847 | D18: 30709 | E18: 33466 | F18: 125648 | G18: 31506 | H18: 31558 | I18: 31667.9 | J18: 34499.33 | K18: 129215.33 | L18: 32202.3 | M18: 32251.94 | N18: 32421.74 | O18: 35255.95 | P18: 132052.75 | Q18: 32816.09 | R18: 32690.07 | S18: 32932.11 | T18: 36065 | U18: 134712.76 | V18: 33509.2 | W18: 33519.5 | X18: 33751.99 | Y18: 36931.43 | Z18: 138007.48 | AA18: 34358.45 | AB18: 34370.16 | AC18: 34660.88 | AD18: 37859.21 | AE18: 141694.19
A19: Equipment cost | B19: 5694 | C19: 5738 | D19: 5468 | E19: 8496 | F19: 25396 | G19: 6305 | H19: 5741 | I19: 5712.31 | J19: 8108.68 | K19: 25866.99 | L19: 6207.03 | M19: 5773.46 | N19: 5746.54 | O19: 8038.6 | P19: 26019.31 | Q19: 6593.8 | R19: 5847.03 | S19: 5956.86 | T19: 9337.31 | U19: 26434.14 | V19: 6373.75 | W19: 5784.9 | X19: 5766.78 | Y19: 9139.15 | Z19: 26366.55 | AA19: 6352.23 | AB19: 5757.39 | AC19: 5745.86 | AD19: 9106.94 | AE19: 26648.9
A20: Broadcast, programming and operations | B20: - | C20: - | D20: - | E20: - | F20: - | G20: - | H20: - | I20: - | J20: - | K20: - | L20: - | M20: - | N20: - | O20: - | P20: - | Q20: - | R20: - | S20: - | T20: - | U20: - | V20: - | W20: - | X20: - | Y20: - | Z20: - | AA20: - | AB20: - | AC20: - | AD20: - | AE20: -
A21: Other cost of services and sales (ex of D&A) | B21: 6339 | C21: 6412 | D21: 6351 | E21: 6322 | F21: 25424 | G21: 6261 | H21: 6306 | I21: 6273.22 | J21: 6783.43 | K21: 25623.65 | L21: 6541.89 | M21: 6444.22 | N21: 6446.34 | O21: 7138.51 | P21: 25880.2 | Q21: 6665.37 | R21: 6672.95 | S21: 6817.33 | T21: 6819.51 | U21: 25736.19 | V21: 6551.01 | W21: 6565.39 | X21: 6833.35 | Y21: 6822.39 | Z21: 25681.39 | AA21: 6727.24 | AB21: 6741.99 | AC21: 7018.16 | AD21: 7000.74 | AE21: 26202.07
A22: Cost of sales - as reported | B22: 12033 | C22: 12150 | D22: 11819 | E22: 14818 | F22: 50820 | G22: 12566 | H22: 12047 | I22: 12452.47 | J22: 15089 | K22: 52154.47 | L22: 13105.93 | M22: 12802.74 | N22: 13023.69 | O22: 15364.61 | P22: 53619.25 | Q22: 13259.17 | R22: 12519.99 | S22: 12774.19 | T22: 16156.82 | U22: 52093.5 | V22: 12924.76 | W22: 12350.29 | X22: 12600.14 | Y22: 15961.54 | Z22: 52047.94 | AA22: 13079.47 | AB22: 12499.38 | AC22: 12764.02 | AD22: 16107.68 | AE22: 52850.97
A23: Selling, general and administrative | B23: 7145 | C23: 6945 | D23: 7454 | E23: 7398 | F23: 28942 | G23: 7316 | H23: 7221 | I23: 6765.75 | J23: 7653.54 | K23: 28956.3 | L23: 6707.95 | M23: 6679.13 | N23: 6570.44 | O23: 7579.45 | P23: 27841.23 | Q23: 6723.6 | R23: 6827.15 | S23: 6715.83 | T23: 7021.88 | U23: 29362.9 | V23: 7145.06 | W23: 7261.51 | X23: 7036.28 | Y23: 7381.94 | Z23: 30838.56 | AA23: 7092.18 | AB23: 7186.51 | AC23: 6945.25 | AD23: 7325.31 | AE23: 31119.14
A24: Asset abandonments and Impairment Charges | B24: 504 | C24: - | D24: - | E24: 334 | F24: 838 | G24: - | H24: 286 | I24: - | J24: - | K24: 286 | L24: - | M24: - | N24: - | O24: - | P24: - | Q24: - | R24: - | S24: - | T24: - | U24: - | V24: - | W24: - | X24: - | Y24: - | Z24: - | AA24: - | AB24: - | AC24: - | AD24: - | AE24: -
A25: Operations and support | B25: 19178 | C25: 19095 | D25: 19273 | E25: 22550 | F25: 80600 | G25: 19882 | H25: 19554 | I25: 19301.39 | J25: 22825.63 | K25: 81467.69 | L25: 19949.35 | M25: 19564.71 | N25: 19653.94 | O25: 23126.5 | P25: 81986.96 | Q25: 19950.66 | R25: 19511.28 | S25: 19678.8 | T25: 23367.68 | U25: 82218.03 | V25: 20278.15 | W25: 19912.19 | X25: 20153.69 | Y25: 23994.39 | Z25: 84002.91 | AA25: 20487.78 | AB25: 20149.55 | AC25: 20421.3 | AD25: 24314.61 | AE25: 85196.02
A26: Integration cost & other adjustments | B26: 589 | C26: -21 | D26: 425 | E26: 320 | F26: 1313 | G26: 171 | H26: 334 | I26: -86.36 | J26: -95.4 | K26: 379.25 | L26: -97.33 | M26: -118.58 | N26: 84.14 | O26: -19.34 | P26: -505.31 | Q26: 50 | R26: 50 | S26: 50 | T26: 50 | U26: -563.33 | V26: 50 | W26: 50 | X26: 50 | Y26: 50 | Z26: 450 | AA26: 50 | AB26: 50 | AC26: 50 | AD26: 50 | AE26: 450
A27: Operations and support - Operating | B27: 19093 | C27: 19116 | D27: 18848 | E27: 22230 | F27: 79287 | G27: 19711 | H27: 19220 | I27: 19342.03 | J27: 22767.03 | K27: 81058.45 | L27: 19953.36 | M27: 19518.24 | N27: 19550.8 | O27: 23056.69 | P27: 82009.43 | Q27: 19904.8 | R27: 19415.49 | S27: 19532.67 | T27: 23265.57 | U27: 82325.42 | V27: 20088.71 | W27: 19628.66 | X27: 19745.78 | Y27: 23583.42 | Z27: 83339.49 | AA27: 20276.71 | AB27: 19838.8 | AC27: 19998.71 | AD27: 23892.4 | AE27: 84538.59
A28: Depreciation and amortization expense | B28: 5190 | C28: 5251 | D28: 5317 | E28: 5128 | F28: 20886 | G28: 4966 | H28: 4966 | I28: 5101.72 | J28: 5171 | K28: 20214.92 | L28: 5052.15 | M28: 5070.41 | N28: 5116.95 | O28: 5201.93 | P28: 20425.33 | Q28: 5063.17 | R28: 5051.56 | S28: 5167.55 | T28: 5159.51 | U28: 20525.3 | V28: 5147.11 | W28: 5135.96 | X28: 5273.2 | Y28: 5244.16 | Z28: 20868.25 | AA28: 5223.84 | AB28: 5206.56 | AC28: 5350.3 | AD28: 5307.49 | AE28: 21098.74
A29: Amortization of intangible assets - Adjustment | B29: 9 | C29: 9 | D29: 10 | E29: 10 | F29: 38 | G29: 57 | H29: 84 | I29: 26.08 | J29: 24.92 | K29: 117 | L29: 43.22 | M29: 49.89 | N29: 29.11 | O29: 28.6 | P29: 4214.88 | Q29: 20.74 | R29: 29.38 | S29: 5.06 | T29: 5.06 | U29: 5270.1 | V29: 29.18 | W29: 43.01 | X29: 4.1 | Y29: 4.1 | Z29: 164.48 | AA29: 23.35 | AB29: 34.41 | AC29: 3.28 | AD29: 3.28 | AE29: 144.01
A30: Total Depreciation and Amortization - Operating | B30: 5190 | C30: 5251 | D30: 5307 | E30: 5118 | F30: 20848 | G30: 4909 | H30: 4966 | I30: 5067.91 | J30: 5121.46 | K30: 20111.33 | L30: 4995.19 | M30: 4982.79 | N30: 5088.67 | O30: 5144.54 | P30: 20348.35 | Q30: 4954.22 | R30: 4933.48 | S30: 5109.92 | T30: 5004.36 | U30: 20504.16 | V30: 5037.87 | W30: 5011.4 | X30: 5219.34 | Y30: 5057.41 | Z30: 21077.42 | AA30: 5100.97 | AB30: 5071.3 | AC30: 5278.67 | AD30: 5103.9 | AE30: 21390.02
A31: Total cost and expenses | B31: 24872 | C31: 24346 | D31: 24590 | E31: 27678 | F31: 101486 | G31: 24848 | H31: 24520 | I31: 24493.92 | J31: 28097.34 | K31: 101893.34 | L31: 25076.26 | M31: 24718.22 | N31: 24775.16 | O31: 28340.65 | P31: 102711.85 | Q31: 24989.25 | R31: 24546.2 | S31: 24818.17 | T31: 28454.67 | U31: 103053.39 | V31: 25387.03 | W31: 25017.05 | X31: 25397.13 | Y31: 29142.56 | Z31: 104968.45 | AA31: 25666.69 | AB31: 25320.32 | AC31: 25731.95 | AD31: 29520.6 | AE31: 106468.69
A32: Total cost and expenses - Operating | B32: 24283 | C32: 24367 | D32: 24165 | E32: 27348 | F32: 100135 | G32: 24620 | H32: 24102 | I32: 24422.04 | J32: 27859.74 | K32: 101132.3 | L32: 25071.87 | M32: 24581.09 | N32: 24683.68 | O32: 28368.8 | P32: 100257.72 | Q32: 25051.29 | R32: 24421.89 | S32: 24898.66 | T32: 28415.77 | U32: 101086.2 | V32: 25722.93 | W32: 24820.27 | X32: 25567.69 | Y32: 29211.87 | Z32: 105689.93 | AA32: 26027.53 | AB32: 25068.17 | AC32: 25880.46 | AD32: 29573.12 | AE32: 107349.61
A33: EBITDA | B33: 10944 | C33: 11752 | D33: 11436 | E33: 10916 | F33: 45048 | G33: 11624 | H33: 12004 | I33: 12306.16 | J33: 11668.56 | K33: 47751.02 | L33: 12242.29 | M33: 12716.43 | N33: 12852.44 | O33: 12011.22 | P33: 49908.58 | Q33: 12861.29 | R33: 13224.58 | S33: 13349.44 | T33: 12749.42 | U33: 52313.74 | V33: 13390.49 | W33: 13860.84 | X33: 13976.21 | Y33: 13038.01 | Z33: 54455.61 | AA33: 14051.74 | AB33: 14501.35 | AC33: 14632.17 | AD33: 13936.81 | AE33: 56996.15
A34: EBITDA - Corporate and other or Eliminations adjustments | B34: 589 | C34: -21 | D34: 425 | E34: 320 | F34: 1313 | G34: 171 | H34: 334 | I34: 69.19 | J34: 208.81 | K34: 583.61 | L34: 65.65 | M34: 91.49 | N34: 61.99 | O34: 332.49 | P34: 464.18 | Q34: 118.41 | R34: 118.43 | S34: 118.27 | T34: 117.9 | U34: 429.2 | V34: 75 | W34: 75 | X34: 75 | Y34: 775 | Z34: 681.75 | AA34: 75 | AB34: 75 | AC34: 75 | AD34: 75 | AE34: 331.75
A35: EBITDA - Operating | B35: 11533 | C35: 11731 | D35: 11861 | E35: 11236 | F35: 46361 | G35: 11795 | H35: 12338 | I35: 12325.8 | J35: 11732.12 | K35: 48163.77 | L35: 12249.29 | M35: 12734.22 | N35: 12871.66 | O35: 12199.23 | P35: 50045.84 | Q35: 12912.04 | R35: 13275.33 | S35: 13400.12 | T35: 12799.95 | U35: 52390.05 | V35: 13420.49 | W35: 13890.84 | X35: 14006.21 | Y35: 13348.01 | Z35: 54669.92 | AA35: 14081.74 | AB35: 14531.35 | AC35: 14662.17 | AD35: 13966.81 | AE35: 57157.53
A36: Operating income/(loss) | B36: 5754 | C36: 6501 | D36: 6119 | E36: 5788 | F36: 24162 | G36: 6658 | H36: 7038 | I36: 7188.82 | J36: 6489.34 | K36: 27412.86 | L36: 7168.23 | M36: 7642.17 | N36: 7726.89 | O36: 6886.41 | P36: 29443.98 | Q36: 7798.12 | R36: 8173.02 | S36: 8181.89 | T36: 7589.91 | U36: 31708.81 | V36: 8243.38 | W36: 8724.88 | X36: 8703.01 | Y36: 7793.84 | Z36: 33522.51 | AA36: 8827.9 | AB36: 9294.79 | AC36: 9281.87 | AD36: 8629.32 | AE36: 35856.34
... A50: Income From Continuing Operations | B50: 4692 | C50: 4861 | D50: 9677 | E50: 4156 | F50: 23386 | G50: 4219 | H50: 5038 | I50: 4499.28 | J50: 3899.12 | K50: 17607.56 | L50: 4408.64 | M50: 4862.28 | N50: 4850.2 | O50: 4138.34 | P50: 18289.87 | Q50: 4874.44 | R50: 5236.46 | S50: 5195.93 | T50: 4748.65 | U50: 19854.49 | V50: 5321.4 | W50: 5686.98 | X50: 5696.59 | Y50: 4996.1 | Z50: 21234.82 | AA50: 5838.08 | AB50: 6194.94 | AC50: 6205.71 | AD50: 5719.98 | AE50: 23237.76
A51: Income/(loss) from discontinued ops | B51: 90 | C51: - | D51: - | E51: 1 | F51: 45.5 | G51: -38 | H51: -28 | I51: -29 | J51: -29 | K51: -72 | L51: -28 | M51: -28 | N51: -28 | O51: -28 | P51: -112 | Q51: - | R51: - | S51: - | T51: - | U51: -112 | V51: - | W51: - | X51: - | Y51: - | Z51: -112 | AA51: - | AB51: - | AC51: - | AD51: - | AE51: -112
A52: Net income attributable to noncontrolling interest | B52: 341 | C52: 361 | D52: 363 | E52: 368 | F52: 1433 | G52: 352 | H52: 383 | I52: 362.95 | J52: 367.65 | K52: 1466.83 | L52: 349.99 | M52: 361.82 | N52: 358.21 | O52: 357.53 | P52: 1436.39 | Q52: 347.04 | R52: 354.57 | S52: 351.26 | T52: 350.43 | U52: 1448.79 | V52: 345.96 | W52: 356.83 | X52: 352.9 | Y52: 351.54 | Z52: 1460.62 | AA52: 353.69 | AB52: 365.13 | AC52: 361.32 | AD52: 360.48 | AE52: 1482.26
A53: Net income attributable to AT&T | B53: 4351 | C53: 4500 | D53: 9314 | E53: 3788 | F53: 21953 | G53: 3829 | H53: 4627 | I53: 4136.72 | J53: 3526.48 | K53: 16095.93 | L53: 4060.92 | M53: 4520.66 | N53: 4489.66 | O53: 3778.47 | P53: 16877.4 | Q53: 4527.41 | R53: 4881.89 | S53: 4844.67 | T53: 4398.22 | U53: 18429.1 | V53: 4975.44 | W53: 5330.16 | X53: 5343.68 | Y53: 4644.56 | Z53: 19766.9 | AA53: 5484.39 | AB53: 5829.81 | AC53: 5844.39 | AD53: 5359.51 | AE53: 21746.4
A54: Preferred dividend | B54: -44 | C54: 36 | D54: 36 | E54: 36 | F54: 64 | G54: 36 | H54: 36 | I54: 36.85 | J54: 36.85 | K54: 139.47 | L54: 37.52 | M54: 37.52 | N54: 39.86 | O54: 39.86 | P54: 150.67 | Q54: 40.54 | R54: 40.54 | S54: 40.54 | T54: 40.54 | U54: 154.84 | V54: 41.56 | W54: 41.56 | X54: 41.56 | Y54: 41.56 | Z54: 155.28 | AA54: 41.56 | AB54: 41.56 | AC54: 41.56 | AD54: 41.56 | AE54: 155.28
A55: Net income attributable to common shareholder | B55: 4395 | C55: 4464 | D55: 9278 | E55: 3752 | F55: 21889 | G55: 3793 | H55: 4591 | I55: 4086.81 | J55: 3495.38 | K55: 15952.55 | L55: 4030.84 | M55: 4476.47 | N55: 4458.04 | O55: 3754.45 | P55: 16651.56 | Q55: 4486.87 | R55: 4841.35 | S55: 4804.13 | T55: 4357.68 | U55: 18153.07 | V55: 4933.88 | W55: 5288.6 | X55: 5302.13 | Y55: 4603 | Z55: 19535.2 | AA55: 5442.84 | AB55: 5788.25 | AC55: 5802.83 | AD55: 5317.95 | AE55: 21502.72
A56: Net income/(loss) - Adjustments | B56: -686 | C56: -536 | D56: -5387 | E56: -59 | F56: -6668 | G56: 197 | H56: -117 | I56: 7.15 | J56: 14.04 | K56: 77.63 | L56: 29.06 | M56: 36.03 | N56: 28.45 | O56: 37.87 | P56: 118.15 | Q56: 24.51 | R56: 35.98 | S56: 3.7 | T56: 3.7 | U56: -6.67 | V56: 15.43 | W56: 26 | X56: -3.75 | Y56: -3.75 | Z56: -27.72 | AA56: 10.06 | AB56: 14.93 | AC56: -7.81 | AD56: -7.81 | AE56: -35.23
A57: Preferred stock redemption gain | B57: -90 | C57: - | D57: - | E57: - | F57: -90 | G57: - | H57: - | I57: - | J57: - | K57: - | L57: - | M57: - | N57: - | O57: - | P57: - | Q57: - | R57: - | S57: - | T57: - | U57: - | V57: - | W57: - | X57: - | Y57: - | Z57: - | AA57: - | AB57: - | AC57: - | AD57: - | AE57: -
...

Sheet Cash Flow
A2: AT&T Inc. | Cash flow
A3: NYSE:T (MI KEY: 4024242; SPCIQ KEY: 100231)
A5: Visible Alpha
A7: Period Type : Fiscal Quarter, Fiscal Halves, Fiscal Year
A8: Period Start : 2025
A9: Period End : 2030
A10: Currency : Reported
A11: Consensus View : Mean
A12: As Of: 10/20/2026
A14: All numbers in $M unless otherwise indicated | B14: FQ1 2025A | C14: FQ2 2025A | D14: FQ3 2025A | E14: FQ4 2025A | F14: FY2025A | G14: FQ1 2026A | H14: FQ2 2026A | I14: FQ3 2026E | J14: FQ4 2026E | K14: FY2026E | L14: FQ1 2027E | M14: FQ2 2027E | N14: FQ3 2027E | O14: FQ4 2027E | P14: FY2027E | Q14: FQ1 2028E | R14: FQ2 2028E | S14: FQ3 2028E | T14: FQ4 2028E | U14: FY2028E | V14: FQ1 2029E | W14: FQ2 2029E | X14: FQ3 2029E | Y14: FQ4 2029E | Z14: FY2029E | AA14: FQ1 2030E | AB14: FQ2 2030E | AC14: FQ3 2030E | AD14: FQ4 2030E | AE14: FY2030E
A15: Number of Contributors Available | B15: 19 | C15: 19 | D15: 19 | E15: 19 | F15: 20 | G15: 19 | H15: 19 | I15: 20 of 20 | J15: 20 of 20 | K15: 20 of 20 | L15: 14 of 20 | M15: 14 of 20 | N15: 13 of 20 | O15: 13 of 20 | P15: 20 of 20 | Q15: 7 of 20 | R15: 7 of 20 | S15: 7 of 20 | T15: 7 of 20 | U15: 17 of 20 | V15: 5 of 20 | W15: 5 of 20 | X15: 5 of 20 | Y15: 5 of 20 | Z15: 14 of 20 | AA15: 5 of 20 | AB15: 5 of 20 | AC15: 5 of 20 | AD15: 5 of 20 | AE15: 14 of 20
A16: Net income | B16: 4692 | C16: 4861 | D16: 9677 | E16: 4156 | F16: 23386 | G16: 4219 | H16: 5038 | I16: 4406.37 | J16: 3785.31 | K16: 17406.65 | L16: 4384.82 | M16: 4841.97 | N16: 4814.61 | O16: 4070.42 | P16: 18033.47 | Q16: 4874.44 | R16: 5236.46 | S16: 5195.93 | T16: 4748.65 | U16: 19725.56 | V16: 5321.4 | W16: 5686.98 | X16: 5696.59 | Y16: 4996.1 | Z16: 21184.5 | AA16: 5838.08 | AB16: 6194.94 | AC16: 6205.71 | AD16: 5719.98 | AE16: 23228.88
A17: Depreciation and amortization | B17: 5190 | C17: 5251 | D17: 5317 | E17: 5128 | F17: 20886 | G17: 4966 | H17: 4966 | I17: 5063.36 | J17: 5131.84 | K17: 20192.49 | L17: 5044.06 | M17: 5042.7 | N17: 5125.05 | O17: 5176.29 | P17: 20342.64 | Q17: 5063.17 | R17: 5051.56 | S17: 5167.55 | T17: 5159.51 | U17: 20473.75 | V17: 5147.11 | W17: 5135.96 | X17: 5273.2 | Y17: 5244.16 | Z17: 20809.45 | AA17: 5223.84 | AB17: 5206.56 | AC17: 5350.3 | AD17: 5307.49 | AE17: 21044.54
A18: Undistributed earnings from investments in equity affiliates | B18: 81 | C18: -112 | D18: -5691 | E18: -167 | F18: -5889 | G18: 28 | H18: -198 | I18: - | J18: - | K18: -170 | L18: - | M18: - | N18: - | O18: - | P18: -170 | Q18: - | R18: - | S18: - | T18: - | U18: -170 | V18: - | W18: - | X18: - | Y18: - | Z18: -170 | AA18: - | AB18: - | AC18: - | AD18: - | AE18: -170
A19: Provision or uncollectible accounts | B19: 516 | C19: 521 | D19: 555 | E19: 679 | F19: 2271 | G19: 560 | H19: 589 | I19: 588.97 | J19: 632.38 | K19: 2283.82 | L19: 566.03 | M19: 572.02 | N19: 566.88 | O19: 600.16 | P19: 2298.11 | Q19: 569.28 | R19: 577.11 | S19: 570.45 | T19: 607.49 | U19: 2323.65 | V19: 586.91 | W19: 598.87 | X19: 589.26 | Y19: 640.45 | Z19: 2384.18 | AA19: 596.4 | AB19: 608.41 | AC19: 599.53 | AD19: 650.67 | AE19: 2423.44
A20: Deferred income tax expense | B20: 1285 | C20: 378 | D20: 946 | E20: -383 | F20: 2226 | G20: 1147 | H20: 682 | I20: 821.86 | J20: 638.38 | K20: 3036.69 | L20: 908.21 | M20: 771.71 | N20: 1102.31 | O20: 593.05 | P20: 3244.01 | Q20: 859.73 | R20: 624.06 | S20: 1155.07 | T20: 663.05 | U20: 3397.52 | V20: 748.92 | W20: 357.6 | X20: 795.37 | Y20: 491.19 | Z20: 2971.9 | AA20: 730.62 | AB20: 168.11 | AC20: 769.92 | AD20: 456.75 | AE20: 2594.89
A21: Amortization of intangibles | B21: - | C21: - | D21: - | E21: - | F21: - | G21: - | H21: - | I21: - | J21: - | K21: - | L21: - | M21: - | N21: - | O21: - | P21: - | Q21: - | R21: - | S21: - | T21: - | U21: - | V21: - | W21: - | X21: - | Y21: - | Z21: - | AA21: - | AB21: - | AC21: - | AD21: - | AE21: -
A22: Gain on sale of investments | B22: 81 | C22: -112 | D22: -5691 | E22: -167 | F22: -5889 | G22: 28 | H22: -198 | I22: -198 | J22: -198 | K22: -219.5 | L22: -198 | M22: -198 | N22: -198 | O22: -198 | P22: -792 | Q22: -198 | R22: -198 | S22: -198 | T22: -198 | U22: -792 | V22: - | W22: - | X22: - | Y22: - | Z22: - | AA22: - | AB22: - | AC22: - | AD22: - | AE22: -
A23: Change in accounts receivable | B23: 15 | C23: -262 | D23: -366 | E23: -913 | F23: -1526 | G23: -119 | H23: -299 | I23: -343.27 | J23: -533.63 | K23: -1250.55 | L23: 160.78 | M23: -307.21 | N23: -130.02 | O23: -779.61 | P23: -1118.99 | Q23: 276.39 | R23: -233.58 | S23: -21.08 | T23: -693.48 | U23: -1130.79 | V23: 931.29 | W23: -291.9 | X23: 0.79 | Y23: -907.6 | Z23: -995.56 | AA23: 937.71 | AB23: -287.31 | AC23: 15.41 | AD23: -919.19 | AE23: -1130.65
A24: Change in total other current assets | B24: 404 | C24: 95 | D24: -2127 | E24: 284 | F24: -1344 | G24: -245 | H24: -75 | I24: -291.08 | J24: 1333.87 | K24: 546.57 | L24: -1970.39 | M24: 503.32 | N24: -459.23 | O24: 1155.76 | P24: -323.59 | Q24: -2021.13 | R24: 535.82 | S24: -580.51 | T24: 1559.92 | U24: -185.72 | V24: -3167.56 | W24: 643.32 | X24: -794.45 | Y24: 2073.41 | Z24: -763.66 | AA24: -3557.72 | AB24: 716.88 | AC24: -1094.16 | AD24: 2160.23 | AE24: -1102.54
A25: Change in accounts payable and accrued liabilities | B25: -3297 | C25: -1143 | D25: 2411 | E25: 2913 | F25: 884 | G25: -2770 | H25: 205 | I25: 274.77 | J25: 1737.44 | K25: -720.89 | L25: -1394.11 | M25: -46.09 | N25: 287.53 | O25: 2074.94 | P25: 769.69 | Q25: -1498.47 | R25: -196.27 | S25: 548.24 | T25: 1583.93 | U25: 264.88 | V25: -732.8 | W25: -113.72 | X25: 738.15 | Y25: 1338.66 | Z25: 1069.69 | AA25: -543.56 | AB25: -153.34 | AC25: 934.79 | AD25: 1410.01 | AE25: 1334.42
A26: Change in income taxes | B26: 1285 | C26: 378 | D26: 946 | E26: -383 | F26: 2226 | G26: 1147 | H26: 682 | I26: 905.87 | J26: 745.88 | K26: 3480.75 | L26: - | M26: - | N26: - | O26: - | P26: 3956.48 | Q26: - | R26: - | S26: - | T26: - | U26: 4203.28 | V26: - | W26: - | X26: - | Y26: - | Z26: 3510.42 | AA26: - | AB26: - | AC26: - | AD26: - | AE26: 2277
A27: Change in operating assets/liabilities | B27: -2878 | C27: -1310 | D27: -82 | E27: 2284 | F27: -1986 | G27: -3134 | H27: -169 | I27: -270.49 | J27: 2951.44 | K27: -548 | L27: -2994.38 | M27: -47.18 | N27: -0.45 | O27: 2587.65 | P27: -176.71 | Q27: -2795.91 | R27: 70.05 | S27: -27.04 | T27: 2242.83 | U27: -316.86 | V27: -2803.81 | W27: 241.71 | X27: -11.82 | Y27: 2472.79 | Z27: -155.95 | AA27: -2957.8 | AB27: 272.3 | AC27: -83.98 | AD27: 2589.66 | AE27: -440.07
A28: Total other operating activities | B28: 244 | C28: 62 | D28: -570 | E28: -377 | F28: -610 | G28: -191 | H28: -107 | I28: 102.79 | J28: -35.58 | K28: -329.67 | L28: 157.01 | M28: -77.43 | N28: -103.04 | O28: -326.6 | P28: -455.19 | Q28: 356.19 | R28: 38.94 | S28: -197.11 | T28: -107.5 | U28: -155.01 | V28: 327.34 | W28: -70.28 | X28: -494.9 | Y28: -542.52 | Z28: -712.63 | AA28: 463.37 | AB28: -119.24 | AC28: -553.49 | AD28: -631.77 | AE28: -745.52
A29: Net Cash Flows Provided By/(Used In) Operating Activities-Continuing operations | B29: 9049 | C29: 9763 | D29: 10152 | E29: 11320 | F29: 40284 | G29: 7595 | H29: 10801 | I29: 10662.24 | J29: 12668.74 | K29: 41628.53 | L29: 7862.27 | M29: 10911.63 | N29: 11384.3 | O29: 12519.95 | P29: 42765.01 | Q29: 8775.81 | R29: 11480.74 | S29: 11836.56 | T29: 13191.02 | U29: 44987.26 | V29: 9327.88 | W29: 11950.84 | X29: 11847.71 | Y29: 13302.18 | Z29: 46205.87 | AA29: 9894.52 | AB29: 12331.08 | AC29: 12287.98 | AD29: 14092.8 | AE29: 47685.86
A30: Net cash flows provided by/(used in) operating activities-Discontinued operations | B30: - | C30: - | D30: - | E30: - | F30: - | G30: -38 | H30: 69 | I30: -60 | J30: -25 | K30: 9.75 | L30: - | M30: - | N30: - | O30: - | P30: - | Q30: - | R30: - | S30: - | T30: - | U30: - | V30: - | W30: - | X30: - | Y30: - | Z30: - | AA30: - | AB30: - | AC30: - | AD30: - | AE30: -
A31: Net cash provided by (used in) operating activities | B31: 9049 | C31: 9763 | D31: 10152 | E31: 11320 | F31: 40284 | G31: 7595 | H31: 10801 | I31: 10667.33 | J31: 12543.94 | K31: 41598.36 | L31: 7731.49 | M31: 10932.44 | N31: 11411.38 | O31: 12578.61 | P31: 42772.68 | Q31: 8618.07 | R31: 11507.73 | S31: 11847.29 | T31: 13275.84 | U31: 44926.04 | V31: 9134.76 | W31: 12109.35 | X31: 12005.64 | Y31: 13603.38 | Z31: 45983.73 | AA31: 9733.67 | AB31: 12636.67 | AC31: 12440.36 | AD31: 14474.62 | AE31: 47492.33
A32: Purchase of property and equipment | B32: 4240 | C32: 4857 | D32: 4843 | E32: 6737 | F32: 20677 | G32: 4835 | H32: 5651 | I32: 5341.41 | J32: 6256.3 | K32: 22095.08 | L32: 5085.77 | M32: 5531.11 | N32: 5372.17 | O32: 5955.78 | P32: 21855.14 | Q32: 4875.48 | R32: 5468.8 | S32: 5208.01 | T32: 5879.41 | U32: 21552.69 | V32: 4968.91 | W32: 5508.8 | X32: 5352.51 | Y32: 5816.78 | Z32: 21674.27 | AA32: 5001.52 | AB32: 5543.34 | AC32: 5386.76 | AD32: 5860.02 | AE32: 21329.22
A33: Interest during construction | B33: 37 | C33: 40 | D33: 44 | E33: 44 | F33: 165 | G33: 42 | H33: 49 | I33: 40.81 | J33: 41.58 | K33: 173.39 | L33: 38.04 | M33: 40.5 | N33: 39.94 | O33: 40.82 | P33: 157.98 | Q33: 42.13 | R33: 45.63 | S33: 44.95 | T33: 46.25 | U33: 156.8 | V33: 43 | W33: 45.34 | X33: 44.97 | Y33: 46.71 | Z33: 153.01 | AA33: 43.14 | AB33: 45.5 | AC33: 45.12 | AD33: 46.89 | AE33: 153.39
A34: Total capital expenditures | B34: 4277 | C34: 4897 | D34: 4887 | E34: 6781 | F34: 20842 | G34: 4877 | H34: 5700 | I34: 5553.66 | J34: 6262.03 | K34: 22460.63 | L34: 4997.7 | M34: 5546.95 | N34: 5616.37 | O34: 6217.85 | P34: 22488.81 | Q34: 4840.45 | R34: 5488.73 | S34: 5606.05 | T34: 6124.59 | U34: 22309.68 | V34: 4958.76 | W34: 5618.59 | X34: 5604.87 | Y34: 5868.84 | Z34: 22208.62 | AA34: 4932.12 | AB34: 5598.78 | AC34: 5589.8 | AD34: 5848.85 | AE34: 21871.34
A35: Acquisitions, net of cash acquired | B35: -20 | C35: -28 | D35: 1 | E35: -332 | F35: -379 | G35: -2674 | H35: -51 | I35: -21180.58 | J35: -32.5 | K35: -23140.54 | L35: -173.75 | M35: -173.75 | N35: -3449.17 | O35: 550.83 | P35: -1967.69 | Q35: -147.88 | R35: -147.88 | S35: -147.88 | T35: -147.88 | U35: -8706.36 | V35: -117.69 | W35: -117.69 | X35: -1411.79 | Y35: -117.69 | Z35: -5047.66 | AA35: -92.5 | AB35: -92.5 | AC35: -92.5 | AD35: -1892.5 | AE35: -2065.6
A36: Dispositions | B36: 11 | C36: 29 | D36: 399 | E36: 2779 | F36: 3218 | G36: 628 | H36: 119 | I36: - | J36: 3000 | K36: 977.77 | L36: 100 | M36: 100 | N36: 100 | O36: 100 | P36: 250 | Q36: 100 | R36: 100 | S36: 100 | T36: 300 | U36: 450 | V36: 125 | W36: 125 | X36: 125 | Y36: 125 | Z36: 516.67 | AA36: - | AB36: - | AC36: - | AD36: - | AE36: 500
A37: Proceeds from short-term investments | B37: 45 | C37: -1129 | D37: 1109 | E37: 156 | F37: 181 | G37: -14 | H37: -10 | I37: -23000 | J37: - | K37: -3325 | L37: - | M37: - | N37: - | O37: - | P37: - | Q37: - | R37: - | S37: - | T37: - | U37: - | V37: - | W37: - | X37: - | Y37: - | Z37: - | AA37: - | AB37: - | AC37: - | AD37: - | AE37: -
A38: Other investing (excl. acquisition, disposition, purchase and all other) | B38: -672 | C38: -1190 | D38: -11 | E38: -166 | F38: -774 | G38: -547 | H38: -107 | I38: -242.75 | J38: 233.33 | K38: -635 | L38: 7.5 | M38: 7.5 | N38: 7.5 | O38: 7.5 | P38: 30 | Q38: 7.5 | R38: 7.5 | S38: 7.5 | T38: 7.5 | U38: -2125 | V38: 70 | W38: 70 | X38: 70 | Y38: 70 | Z38: -1075 | AA38: 70 | AB38: 70 | AC38: 70 | AD38: 70 | AE38: -2791.67
A39: Net Cash Flows Provided By/(Used In) Investing Activities-Continuing operations | B39: -4958 | C39: -6086 | D39: -3389 | E39: -4344 | F39: -18777 | G39: -7484 | H39: -5749 | I39: -25883.95 | J39: -6052.35 | K39: -46834.91 | L39: -5009.74 | M39: -5568.09 | N39: -6546.6 | O39: -6057.16 | P39: -23064.67 | Q39: -4866.27 | R39: -5514.55 | S39: -5631.87 | T39: -6078.98 | U39: -25415.75 | V39: -4952.83 | W39: -5612.66 | X39: -6398.95 | Y39: -5862.91 | Z39: -23980.55 | AA39: -4941.12 | AB39: -5607.78 | AC39: -5598.8 | AD39: -6577.85 | AE39: -23104.63
A40: Net cash flows provided by/(used in) investing activities-Discontinued operations | B40: - | C40: - | D40: - | E40: - | F40: - | G40: -4171 | H40: -192 | I40: -300 | J40: -100 | K40: -4496.33 | L40: - | M40: - | N40: - | O40: - | P40: - | Q40: - | R40: - | S40: - | T40: - | U40: - | V40: - | W40: - | X40: - | Y40: - | Z40: - | AA40: - | AB40: - | AC40: - | AD40: - | AE40: -
A41: Net cash provided by (used in) investing activities | B41: -4958 | C41: -6086 | D41: -3389 | E41: -4344 | F41: -18777 | G41: -7484 | H41: -5749 | I41: -26915.94 | J41: -6037.56 | K41: -49225.22 | L41: -4984.32 | M41: -5561.99 | N41: -6624.36 | O41: -6042.98 | P41: -23086.51 | Q41: -4866.27 | R41: -5514.55 | S41: -5631.87 | T41: -6078.98 | U41: -25757.58 | V41: -4952.83 | W41: -5612.66 | X41: -6398.95 | Y41: -5862.91 | Z41: -24203.6 | AA41: -4941.12 | AB41: -5607.78 | AC41: -5598.8 | AD41: -6577.85 | AE41: -23141.27
A42: Issuance of long-term debt | B42: 2956 | C42: 3473 | D42: 7598 | E42: - | F42: 14027 | G42: 8098 | H42: 5939 | I42: 9642.86 | J42: - | K42: 21238.41 | L42: 4000 | M42: 3000 | N42: - | O42: - | P42: 5500 | Q42: 4000 | R42: 2000 | S42: - | T42: - | U42: 14267.57 | V42: - | W42: - | X42: - | Y42: - | Z42: 7160.99 | AA42: 1000 | AB42: 1000 | AC42: - | AD42: - | AE42: 3946.38
A43: Repayment of long-term debt | B43: 1526 | C43: 94 | D43: 229 | E43: 3679 | F43: 5528 | G43: 5247 | H43: 151 | I43: 2191.95 | J43: 1880.5 | K43: 6124.74 | L43: 3054 | M43: 1833.33 | N43: 1812.33 | O43: 1348.67 | P43: 6715.5 | Q43: 4232 | R43: 2318 | S43: 2133 | T43: 2264.5 | U43: 7141.6 | V43: 3108 | W43: 180 | X43: 2742 | Y43: 1970 | Z43: 8104.27 | AA43: 4842 | AB43: 2087 | AC43: 2000 | AD43: 2594.5 | AE43: 8977.58
A44: Net change in long term debt | B44: 1430 | C44: 3379 | D44: 7369 | E44: -3679 | F44: 8499 | G44: 2851 | H44: 5788 | I44: 7627.84 | J44: -33.24 | K44: 13966.87 | L44: 680.31 | M44: -1125 | N44: -1445.6 | O44: -1868.01 | P44: -4113.05 | Q44: -488 | R44: -859.67 | S44: -1809.4 | T44: -1742.5 | U44: -1973.17 | V44: -2554 | W44: -1090 | X44: -2494.67 | Y44: -1485 | Z44: -5937.28 | AA44: -1947.33 | AB44: -1724.67 | AC44: -1500 | AD44: -1797.25 | AE44: -5960.91
...

Sheet Free Cash Flow
A2: AT&T Inc. | Free cash flow
A3: NYSE:T (MI KEY: 4024242; SPCIQ KEY: 100231)
A5: Visible Alpha
A7: Period Type : Fiscal Quarter, Fiscal Halves, Fiscal Year
A8: Period Start : 2025
A9: Period End : 2030
A10: Currency : Reported
A11: Consensus View : Mean
A12: As Of: 10/20/2026
A14: All numbers in $M unless otherwise indicated | B14: FQ1 2025A | C14: FQ2 2025A | D14: FQ3 2025A | E14: FQ4 2025A | F14: FY2025A | G14: FQ1 2026A | H14: FQ2 2026A | I14: FQ3 2026E | J14: FQ4 2026E | K14: FY2026E | L14: FQ1 2027E | M14: FQ2 2027E | N14: FQ3 2027E | O14: FQ4 2027E | P14: FY2027E | Q14: FQ1 2028E | R14: FQ2 2028E | S14: FQ3 2028E | T14: FQ4 2028E | U14: FY2028E | V14: FQ1 2029E | W14: FQ2 2029E | X14: FQ3 2029E | Y14: FQ4 2029E | Z14: FY2029E | AA14: FQ1 2030E | AB14: FQ2 2030E | AC14: FQ3 2030E | AD14: FQ4 2030E | AE14: FY2030E
A15: Number of Contributors Available | B15: 19 | C15: 19 | D15: 19 | E15: 19 | F15: 20 | G15: 19 | H15: 19 | I15: 20 of 20 | J15: 20 of 20 | K15: 20 of 20 | L15: 14 of 20 | M15: 14 of 20 | N15: 13 of 20 | O15: 13 of 20 | P15: 20 of 20 | Q15: 7 of 20 | R15: 7 of 20 | S15: 7 of 20 | T15: 7 of 20 | U15: 17 of 20 | V15: 5 of 20 | W15: 5 of 20 | X15: 5 of 20 | Y15: 5 of 20 | Z15: 14 of 20 | AA15: 5 of 20 | AB15: 5 of 20 | AC15: 5 of 20 | AD15: 5 of 20 | AE15: 14 of 20
A16: Free Cash Flow
A17: Net cash provided by (used in) operating activities | B17: 9049 | C17: 9763 | D17: 10152 | E17: 11320 | F17: 40284 | G17: 7595 | H17: 10801 | I17: 10667.33 | J17: 12543.94 | K17: 41598.36 | L17: 7731.49 | M17: 10932.44 | N17: 11411.38 | O17: 12578.61 | P17: 42772.68 | Q17: 8618.07 | R17: 11507.73 | S17: 11847.29 | T17: 13275.84 | U17: 44926.04 | V17: 9134.76 | W17: 12109.35 | X17: 12005.64 | Y17: 13603.38 | Z17: 45983.73 | AA17: 9733.67 | AB17: 12636.67 | AC17: 12440.36 | AD17: 14474.62 | AE17: 47492.33
A18: DTV distribution classified as op activities | B18: 1423 | C18: 503 | D18: 251 | E18: 251 | F18: 1926 | G18: - | H18: - | I18: - | J18: - | K18: - | L18: - | M18: - | N18: - | O18: - | P18: - | Q18: - | R18: - | S18: - | T18: - | U18: - | V18: - | W18: - | X18: - | Y18: - | Z18: - | AA18: - | AB18: - | AC18: - | AD18: - | AE18: -
A19: Cash taxes paid on DTV | B19: - | C19: 251 | D19: - | E19: - | F19: 251 | G19: - | H19: - | I19: - | J19: - | K19: - | L19: - | M19: - | N19: - | O19: - | P19: - | Q19: - | R19: - | S19: - | T19: - | U19: - | V19: - | W19: - | X19: - | Y19: - | Z19: - | AA19: - | AB19: - | AC19: - | AD19: - | AE19: -
A20: Total capital expenditures | B20: 4277 | C20: 4897 | D20: 4887 | E20: 6781 | F20: 20842 | G20: 4877 | H20: 5700 | I20: 5553.66 | J20: 6262.03 | K20: 22460.63 | L20: 4997.7 | M20: 5546.95 | N20: 5616.37 | O20: 6217.85 | P20: 22488.81 | Q20: 4840.45 | R20: 5488.73 | S20: 5606.05 | T20: 6124.59 | U20: 22309.68 | V20: 4958.76 | W20: 5618.59 | X20: 5604.87 | Y20: 5868.84 | Z20: 22208.62 | AA20: 4932.12 | AB20: 5598.78 | AC20: 5589.8 | AD20: 5848.85 | AE20: 21871.34
A21: Cash paid for vendor financing | B21: 203 | C21: 220 | D21: 400 | E21: 358 | F21: 1181 | G21: 212 | H21: 431 | I21: 295.02 | J21: 286.51 | K21: 1201.74 | L21: 292.56 | M21: 315.08 | N21: 303 | O21: 300.65 | P21: 1091.06 | Q21: 305.95 | R21: 325.98 | S21: 312.17 | T21: 309.48 | U21: 1117.57 | V21: 284.42 | W21: 309.65 | X21: 292.26 | Y21: 288.87 | Z21: 1145.48 | AA21: 281.98 | AB21: 304.69 | AC21: 289.03 | AD21: 285.98 | AE21: 1141.35
A22: Cash paid for capital investment | B22: 4480 | C22: 5117 | D22: 5287 | E22: 7139 | F22: 22023 | G22: 5089 | H22: 6131 | I22: 5839.69 | J22: 6550.91 | K22: 23660.41 | L22: 5221.48 | M22: 5852.89 | N22: 5922.42 | O22: 6529.64 | P22: 23544.72 | Q22: 5146.41 | R22: 5814.71 | S22: 5918.22 | T22: 6434.07 | U22: 23301.87 | V22: 5243.18 | W22: 5928.24 | X22: 5897.13 | Y22: 6157.71 | Z22: 23073.21 | AA22: 5214.1 | AB22: 5903.47 | AC22: 5878.83 | AD22: 6134.83 | AE22: 22717.65
A23: Free cash flow | B23: 3146 | C23: 4394 | D23: 4865 | E23: 4181 | F23: 16586 | G23: 2506 | H23: 4670 | I23: 4900.42 | J23: 6008.83 | K23: 18149.5 | L23: 2636.28 | M23: 5090.38 | N23: 5719.31 | O23: 6044.74 | P23: 19460.12 | Q23: 3812.01 | R23: 5333.52 | S23: 6220.82 | T23: 6400.28 | U23: 21535.08 | V23: 4045.77 | W23: 5312.16 | X23: 6235.71 | Y23: 6786.78 | Z23: 22439.87 | AA23: 4476.96 | AB23: 5507.61 | AC23: 6626.08 | AD23: 7777.78 | AE23: 24136.3
