Workbook
Name IQ_CH: 110000
Name IQ_CQ: 5000
Name IQ_CY: 10000
Name IQ_DAILY: 500000
Name IQ_FH: 100000
Name IQ_FQ: 500
Name IQ_FY: 1000
Name IQ_LTM: 2000
Name IQ_MONTH: 15000
Name IQ_NTM: 6000
Name IQ_WEEK: 50000
Name IQ_YTD: 3000

Sheet 3Q26 Quick Look
A1: Comcast Corporation (CMCSA) — Q3 2026 Earnings First Look
A2: $M (except for as noted) | B2: Q3'25 | C2: Q2'26 | D2: Q3'26 (CON) | E2: Actual | F2: YoY Growth (3Q26 vs 3Q25) | G2: Delta (vs Con.)
A3: Total Revenue | B3: ='SPG Segments'!D22 -> 29151 | C3: ='SPG Segments'!H22 -> 29568 | D3: ='SPG Segments'!I22 -> 29229.46 | F3: =IF(E3="","",(E3-B3)/B3) | G3: =IF(E3="","",(E3-D3)/ABS(D3))
A4: C&P | B4: ='SPG Conn & Platforms'!D49 -> 20212 | C4: ='SPG Conn & Platforms'!H49 -> 19795 | D4: ='SPG Conn & Platforms'!I49 -> 19677.91 | F4: =IF(E4="","",(E4-B4)/B4) | G4: =IF(E4="","",(E4-D4)/ABS(D4))
A5: Residential | B5: ='SPG Conn & Platforms'!D64 -> 17636 | C5: ='SPG Conn & Platforms'!H64 -> 17124 | D5: ='SPG Conn & Platforms'!I64 -> 17027.39 | F5: =IF(E5="","",(E5-B5)/B5) | G5: =IF(E5="","",(E5-D5)/ABS(D5))
A6: Convergence Revenue | B6: =B7+B8 -> 7465 | C6: =C7+C8 -> 7287 | D6: =D7+D8 -> 7278.19 | E6: =IF(OR(E7="",E8=""),"",E7+E8) | F6: =IF(E6="","",(E6-B6)/B6) | G6: =IF(E6="","",(E6-D6)/ABS(D6))
A7: Broadband Revenue | B7: ='SPG Conn & Platforms'!D20 -> 6550 | C7: ='SPG Conn & Platforms'!H20 -> 6280 | D7: ='SPG Conn & Platforms'!I20 -> 6221.77 | F7: =IF(E7="","",(E7-B7)/B7) | G7: =IF(E7="","",(E7-D7)/ABS(D7))
A8: Mobile Revenue | B8: ='SPG Wireless'!D28 -> 915 | C8: ='SPG Wireless'!H28 -> 1007 | D8: ='SPG Wireless'!I28 -> 1056.42 | F8: =IF(E8="","",(E8-B8)/B8) | G8: =IF(E8="","",(E8-D8)/ABS(D8))
A9: Business Services | B9: ='SPG Conn & Platforms'!D71 -> 2576 | C9: ='SPG Conn & Platforms'!H71 -> 2671 | D9: ='SPG Conn & Platforms'!I71 -> 2650.53 | F9: =IF(E9="","",(E9-B9)/B9) | G9: =IF(E9="","",(E9-D9)/ABS(D9))
A10: C&E | B10: ='SPG Content & Experiences'!D23 -> 9897 | C10: ='SPG Content & Experiences'!H23 -> 10728 | D10: ='SPG Content & Experiences'!I23 -> 10519.29 | F10: =IF(E10="","",(E10-B10)/B10) | G10: =IF(E10="","",(E10-D10)/ABS(D10))
A11: Media | B11: ='SPG Content & Experiences'!D17 -> 4744 | C11: ='SPG Content & Experiences'!H17 -> 5691 | D11: ='SPG Content & Experiences'!I17 -> 5354.47 | F11: =IF(E11="","",(E11-B11)/B11) | G11: =IF(E11="","",(E11-D11)/ABS(D11))
A12: Studios | B12: ='SPG Content & Experiences'!D18 -> 3000 | C12: ='SPG Content & Experiences'!H18 -> 3040 | D12: ='SPG Content & Experiences'!I18 -> 3076.95 | F12: =IF(E12="","",(E12-B12)/B12) | G12: =IF(E12="","",(E12-D12)/ABS(D12))
A13: Park | B13: ='SPG Content & Experiences'!D19 -> 2717 | C13: ='SPG Content & Experiences'!H19 -> 2413 | D13: ='SPG Content & Experiences'!I19 -> 2668.31 | F13: =IF(E13="","",(E13-B13)/B13) | G13: =IF(E13="","",(E13-D13)/ABS(D13))
A15: Total EBITDA | B15: ='SPG Segments'!D38 -> 9038 | C15: ='SPG Segments'!H38 -> 8923 | D15: ='SPG Segments'!I38 -> 8867.61 | F15: =IF(E15="","",(E15-B15)/B15) | G15: =IF(E15="","",(E15-D15)/ABS(D15))
A16: C&P | B16: ='SPG Conn & Platforms'!D54 -> 7938 | C16: ='SPG Conn & Platforms'!H54 -> 7964 | D16: ='SPG Conn & Platforms'!I54 -> 7568.55 | F16: =IF(E16="","",(E16-B16)/B16) | G16: =IF(E16="","",(E16-D16)/ABS(D16))
A17: Residential | B17: ='SPG Conn & Platforms'!D52 -> 6484 | C17: ='SPG Conn & Platforms'!H52 -> 6448 | D17: ='SPG Conn & Platforms'!I52 -> 6095.11 | F17: =IF(E17="","",(E17-B17)/B17) | G17: =IF(E17="","",(E17-D17)/ABS(D17))
A18: Business Services | B18: ='SPG Conn & Platforms'!D53 -> 1454 | C18: ='SPG Conn & Platforms'!H53 -> 1516 | D18: ='SPG Conn & Platforms'!I53 -> 1491.75 | F18: =IF(E18="","",(E18-B18)/B18) | G18: =IF(E18="","",(E18-D18)/ABS(D18))
A19: EBITDA Margin | B19: =B16/B4 -> 0.39273699 | C19: =C16/C4 -> 0.40232382 | D19: =D16/D4 -> 0.38462164 | E19: =IF(OR(E16="",E4=""),"",E16/E4) | F19: =IF(E19="","",E19-B19) | G19: =IF(E19="","",E19-D19)
A20: C&E | B20: ='SPG Content & Experiences'!D32 -> 1392 | C20: ='SPG Content & Experiences'!H32 -> 1329 | D20: ='SPG Content & Experiences'!I32 -> 1609.76 | F20: =IF(E20="","",(E20-B20)/B20) | G20: =IF(E20="","",(E20-D20)/ABS(D20))
A21: Media | B21: ='SPG Content & Experiences'!D26 -> 247 | C21: ='SPG Content & Experiences'!H26 -> 708 | D21: ='SPG Content & Experiences'!I26 -> 595.67 | F21: =IF(E21="","",(E21-B21)/B21) | G21: =IF(E21="","",(E21-D21)/ABS(D21))
A22: Studios | B22: ='SPG Content & Experiences'!D27 -> 338 | C22: ='SPG Content & Experiences'!H27 -> 202 | D22: ='SPG Content & Experiences'!I27 -> 400.42 | F22: =IF(E22="","",(E22-B22)/B22) | G22: =IF(E22="","",(E22-D22)/ABS(D22))
A23: Park | B23: ='SPG Content & Experiences'!D28 -> 940.4 | C23: ='SPG Content & Experiences'!H28 -> 608 | D23: ='SPG Content & Experiences'!I28 -> 789.64 | F23: =IF(E23="","",(E23-B23)/B23) | G23: =IF(E23="","",(E23-D23)/ABS(D23))
A24: EBITDA Margin | B24: =B20/B10 -> 0.14064868 | C24: =C20/C10 -> 0.12388143 | D24: =D20/D10 -> 0.15302934 | E24: =IF(OR(E20="",E10=""),"",E20/E10) | F24: =IF(E24="","",E24-B24) | G24: =IF(E24="","",E24-D24)
A26: Adjusted EPS | B26: ='SPG Income Statement'!D40 -> 0.95 | C26: ='SPG Income Statement'!H40 -> 1.04 | D26: ='SPG Income Statement'!I40 -> 0.97 | F26: =IF(E26="","",(E26-B26)/B26) | G26: =IF(E26="","",(E26-D26)/ABS(D26))
A27: FCF | B27: ='SPG Free Cash Flow'!D20 -> 4945 | C27: ='SPG Free Cash Flow'!H20 -> 4604 | D27: ='SPG Free Cash Flow'!I20 -> 3425.71 | F27: =IF(E27="","",(E27-B27)/B27) | G27: =IF(E27="","",(E27-D27)/ABS(D27))
A29: Operational metrics
A30: Resi BB Net adds (in 000') | B30: ='SPG C&P Customer Metrics'!D36 -> -91 | C30: ='SPG C&P Customer Metrics'!H36 -> -167 | D30: ='SPG C&P Customer Metrics'!I36 -> -135.59 | F30: =IF(E30="","",(E30-B30)/B30) | G30: =IF(E30="","",(E30-D30)/ABS(D30))
A31: Resi BB ARPU (implied) | B31: ='SPG C&P Customer Metrics'!D46 -> 75.44 | C31: ='SPG C&P Customer Metrics'!H46 -> 73.27 | D31: ='SPG C&P Customer Metrics'!I46 -> 72.96 | F31: =IF(E31="","",(E31-B31)/B31) | G31: =IF(E31="","",(E31-D31)/ABS(D31))
A32: Video net adds (in 000') | B32: ='SPG C&P Customer Metrics'!D53 -> -256 | C32: ='SPG C&P Customer Metrics'!H53 -> -280 | D32: ='SPG C&P Customer Metrics'!I53 -> -246.9 | F32: =IF(E32="","",(E32-B32)/B32) | G32: =IF(E32="","",(E32-D32)/ABS(D32))
A33: Wireless net adds (in 000') | B33: ='SPG C&P Customer Metrics'!D50 -> 414 | C33: ='SPG C&P Customer Metrics'!H50 -> 448 | D33: ='SPG C&P Customer Metrics'!I50 -> 399.29 | F33: =IF(E33="","",(E33-B33)/B33) | G33: =IF(E33="","",(E33-D33)/ABS(D33))
A34: Peacock (EOP sub) | B34: ='SPG Peacock'!D28/1000 -> 41 | C34: ='SPG Peacock'!H28/1000 -> 48 | D34: ='SPG Peacock'!I28/1000 -> 48.22188 | F34: =IF(E34="","",(E34-B34)/B34) | G34: =IF(E34="","",(E34-D34)/ABS(D34))

Sheet CapIQ cons on Oct 20, 2026 ->

Sheet SPG Income Statement
A2: Comcast Corporation | Income statement
A3: NASDAQGS:CMCSA (MI KEY: 4057180; SPCIQ KEY: 173341)
A5: Visible Alpha
A7: Period Type : Fiscal Quarter, Fiscal Halves, Fiscal Year
A8: Period Start : 2025
A9: Period End : 2030
A10: Currency : Reported
A11: Consensus View : Mean
A12: As Of: 10/20/2026
A14: All numbers in $M unless otherwise indicated | B14: FQ1 2025A | C14: FQ2 2025A | D14: FQ3 2025A | E14: FQ4 2025A | F14: FY2025A | G14: FQ1 2026A | H14: FQ2 2026A | I14: FQ3 2026E | J14: FQ4 2026E | K14: FY2026E | L14: FQ1 2027E | M14: FQ2 2027E | N14: FQ3 2027E | O14: FQ4 2027E | P14: FY2027E | Q14: FQ1 2028E | R14: FQ2 2028E | S14: FQ3 2028E | T14: FQ4 2028E | U14: FY2028E | V14: FQ1 2029E | W14: FQ2 2029E | X14: FQ3 2029E | Y14: FQ4 2029E | Z14: FY2029E | AA14: FQ1 2030E | AB14: FQ2 2030E | AC14: FQ3 2030E | AD14: FQ4 2030E | AE14: FY2030E
A15: Number of Contributors Available | B15: 22 | C15: 21 | D15: 21 | E15: 20 | F15: 21 | G15: 21 | H15: 20 | I15: 20 of 20 | J15: 20 of 20 | K15: 20 of 20 | L15: 12 of 20 | M15: 12 of 20 | N15: 11 of 20 | O15: 11 of 20 | P15: 20 of 20 | Q15: 8 of 20 | R15: 8 of 20 | S15: 8 of 20 | T15: 8 of 20 | U15: 19 of 20 | V15: 7 of 20 | W15: 7 of 20 | X15: 7 of 20 | Y15: 7 of 20 | Z15: 16 of 20 | AA15: 7 of 20 | AB15: 7 of 20 | AC15: 7 of 20 | AD15: 7 of 20 | AE15: 16 of 20
A16: Revenue | B16: 27865 | C16: 28249 | D16: 29151 | E16: 30287 | F16: 115552 | G16: 30892 | H16: 29568 | I16: 29229.46 | J16: 30096.76 | K16: 119902.79 | L16: 29232.16 | M16: 29071.52 | N16: 28889.77 | O16: 30006.17 | P16: 117534.94 | Q16: 29428.42 | R16: 29256.84 | S16: 30939.39 | T16: 30410.85 | U16: 120340.38 | V16: 29699.41 | W16: 29443.43 | X16: 29425.33 | Y16: 30534.94 | Z16: 119319.01 | AA16: 31312.12 | AB16: 29925.52 | AC16: 29876.6 | AD16: 30986.23 | AE16: 122294.14
A17: Total cost and exp. excl. D&A | B17: 19170 | C17: 18826 | D17: 20113 | E17: 22989 | F17: 81098 | G17: 22925 | H17: 20645 | I17: 20349.17 | J17: 22678.22 | K17: 86776.23 | L17: 21231.38 | M17: 20184.31 | N17: 19962.22 | O17: 22332.76 | P17: 84173.96 | Q17: 21319.98 | R17: 20268.68 | S17: 21817.52 | T17: 22662.51 | U17: 86309.48 | V17: 21551.81 | W17: 20322.91 | X17: 20206.81 | Y17: 22686.03 | Z17: 85081.04 | AA17: 22962.76 | AB17: 20655.1 | AC17: 20498.39 | AD17: 22887.16 | AE17: 87294.06
A18: Adjusted EBITDA | B18: 8695 | C18: 9423 | D18: 9038 | E18: 7298 | F18: 34454 | G18: 7967 | H18: 8923 | I18: 8867.61 | J18: 7422.42 | K18: 33164.19 | L18: 8035.64 | M18: 8864.77 | N18: 8868.47 | O18: 7609 | P18: 33333.85 | Q18: 8122.09 | R18: 8914.82 | S18: 9026.42 | T18: 7659.09 | U18: 33967.78 | V18: 8158.34 | W18: 8989.6 | X18: 9054.84 | Y18: 7733.29 | Z18: 34127.15 | AA18: 8241.84 | AB18: 9099.61 | AC18: 9198.46 | AD18: 7956.13 | AE18: 34809.51
A19: Depreciation | B19: 2231 | C19: 2349 | D19: 2353 | E19: 2393 | F19: 9326 | G19: 2333 | H19: 2391 | I19: 2349.97 | J19: 2373.61 | K19: 9410.61 | L19: 2358.11 | M19: 2392.05 | N19: 2363.81 | O19: 2382.45 | P19: 9582.01 | Q19: 2348.53 | R19: 2391.8 | S19: 2412.19 | T19: 2444.36 | U19: 9744.82 | V19: 2430.9 | W19: 2465.94 | X19: 2423.56 | Y19: 2446.11 | Z19: 9933.48 | AA19: 2435.65 | AB19: 2472.84 | AC19: 2439.92 | AD19: 2463.54 | AE19: 10047.78
A20: Amortization | B20: 1618 | C20: 1805 | D20: 1666 | E20: 1794 | F20: 6883 | G20: 1533 | H20: 1297 | I20: 1396.77 | J20: 1393.85 | K20: 5609.59 | L20: 1323.38 | M20: 1251.75 | N20: 1323.6 | O20: 1343.82 | P20: 5212.58 | Q20: 1306.37 | R20: 1279.76 | S20: 1346.61 | T20: 1329.01 | U20: 5176.5 | V20: 1303.87 | W20: 1272.44 | X20: 1292.96 | Y20: 1313.96 | Z20: 4946.54 | AA20: 1344.75 | AB20: 1277.75 | AC20: 1296.86 | AD20: 1315.74 | AE20: 4953.76
A21: Depreciation and amortization | B21: 3849 | C21: 4154 | D21: 4020 | E21: 4187 | F21: 16210 | G21: 3866 | H21: 3688 | I21: 3785.68 | J21: 3814.22 | K21: 15125.74 | L21: 3758.04 | M21: 3716.72 | N21: 3793.71 | O21: 3842.65 | P21: 15065.61 | Q21: 3709.96 | R21: 3677.4 | S21: 3802.91 | T21: 3837.1 | U21: 15145.1 | V21: 3781.74 | W21: 3758.57 | X21: 3768.61 | Y21: 3810.11 | Z21: 15141.66 | AA21: 3825.86 | AB21: 3773.78 | AC21: 3791.01 | AD21: 3831.65 | AE21: 15263.18
A22: Total goodwill and other expenses | B22: 25 | C22: 137 | D22: 116 | E22: 225 | F22: 634 | G22: -72 | H22: 75 | I22: - | J22: - | K22: 112.12 | L22: - | M22: -1 | N22: - | O22: - | P22: 1 | Q22: - | R22: - | S22: - | T22: - | U22: 1 | V22: - | W22: - | X22: - | Y22: - | Z22: 1 | AA22: - | AB22: - | AC22: - | AD22: - | AE22: 1
A23: Total costs and expenses | B23: 23043 | C23: 22257 | D23: 24250 | E23: 27401 | F23: 103035 | G23: 27322 | H23: 24408 | I23: 24073.71 | J23: 26435.02 | K23: 101841.75 | L23: 24942.62 | M23: 23875.52 | N23: 23779.09 | O23: 26175.64 | P23: 99057.81 | Q23: 24992.55 | R23: 23950.59 | S23: 25641.58 | T23: 26495.32 | U23: 101305.24 | V23: 25289.23 | W23: 24114.85 | X23: 24053.52 | Y23: 26516.51 | Z23: 100136.37 | AA23: 26875.13 | AB23: 24469.14 | AC23: 24386.86 | AD23: 26779.18 | AE23: 102468.05
A24: Operating income/(loss) | B24: 5658 | C24: 5129 | D24: 4901 | E24: 3488 | F24: 20672 | G24: 4135 | H24: 5160 | I24: 5095.43 | J24: 3583.71 | K24: 17963.32 | L24: 4313.42 | M24: 5149.39 | N24: 5087.04 | O24: 3799.99 | P24: 18309.26 | Q24: 4477.94 | R24: 5237.51 | S24: 5276.56 | T24: 3878.54 | U24: 18887.33 | V24: 4457.46 | W24: 5247.35 | X24: 5337.06 | Y24: 3973.54 | Z24: 19022.08 | AA24: 4497.55 | AB24: 5374.89 | AC24: 5455.27 | AD24: 4160.79 | AE24: 19587.95
A25: Interest expense | B25: 1050 | C25: 1105 | D25: 1128 | E25: 1126 | F25: 4409 | G25: 1094 | H25: 1052 | I25: 1014.6 | J25: 1012.33 | K25: 4172.93 | L25: 1004.38 | M25: 1000.18 | N25: 1000.21 | O25: 1002.11 | P25: 3993.73 | Q25: 995.05 | R25: 990.43 | S25: 993.24 | T25: 994.02 | U25: 3908.06 | V25: 1007.43 | W25: 1002.77 | X25: 1005.59 | Y25: 1005.41 | Z25: 3866.16 | AA25: 1003.84 | AB25: 999.36 | AC25: 1002.3 | AD25: 1003.24 | AE25: 3822.26
A26: Realized and unrealized gains losses on equity securities | B26: -24 | C26: 136 | D26: -60 | E26: -72 | F26: -20 | G26: -5 | H26: -13 | I26: -21.9 | J26: -47.5 | K26: -19.71 | L26: -23.61 | M26: -15.96 | N26: -20.25 | O26: -0.91 | P26: 105.78 | Q26: - | R26: - | S26: - | T26: - | U26: 197.68 | V26: - | W26: - | X26: - | Y26: - | Z26: 221.58 | AA26: - | AB26: - | AC26: - | AD26: - | AE26: 263.17
A27: Other income (expense), net | B27: 102 | C27: 9652 | D27: 212 | E27: 148 | F27: 10114 | G27: 87 | H27: 232 | I27: 102.34 | J27: 93.51 | K27: 361.56 | L27: 112.33 | M27: 100.07 | N27: 111.18 | O27: 90.01 | P27: 361.38 | Q27: 88.73 | R27: 88.37 | S27: 91.64 | T27: 89.85 | U27: 356.46 | V27: 86.69 | W27: 86.24 | X27: 89.41 | Y27: 87.04 | Z27: 341.92 | AA27: 83.28 | AB27: 84.42 | AC27: 89.21 | AD27: 88.34 | AE27: 334.73
A28: Other Income/(loss) | B28: 78 | C28: 9788 | D28: 152 | E28: 76 | F28: 10094 | G28: 82 | H28: 219 | I28: 83.58 | J28: 65.2 | K28: 312.87 | L28: 79.1 | M28: 98.72 | N28: 100.16 | O28: 92.26 | P28: 388.63 | Q28: 63.04 | R28: 113.27 | S28: 106.31 | T28: 98.47 | U28: 426.83 | V28: 63.87 | W28: 116.59 | X28: 109.19 | Y28: 100.8 | Z28: 432.33 | AA28: 64.32 | AB28: 120.2 | AC28: 112.93 | AD28: 104.65 | AE28: 452
A29: Equity in net income (losses) of investees, net | B29: -194 | C29: -29 | D29: -90 | E29: -278 | F29: -591 | G29: -391 | H29: 285 | I29: -51.39 | J29: -107.99 | K29: -98.55 | L29: -200.45 | M29: 172 | N29: -65.65 | O29: -151.48 | P29: -155.11 | Q29: -320.62 | R29: 233.7 | S29: -68.04 | T29: -210.17 | U29: -188.45 | V29: -295.6 | W29: 215.46 | X29: -63.43 | Y29: -195.93 | Z29: -177.97 | AA29: -275.58 | AB29: 200.87 | AC29: -59.75 | AD29: -184.55 | AE29: -169.2
A30: Nonoperating income/(expense) | B30: -1166 | C30: 8654 | D30: -1066 | E30: -1328 | F30: 5094 | G30: -1403 | H30: -548 | I30: -995.08 | J30: -1031.72 | K30: -3979.9 | L30: -1034.13 | M30: -883.79 | N30: -969.46 | O30: -1006.87 | P30: -3840.86 | Q30: -1051.56 | R30: -889.53 | S30: -970.38 | T30: -1009.64 | U30: -3750.23 | V30: -1064.51 | W30: -891.25 | X30: -976.92 | Y30: -1018.19 | Z30: -3677.98 | AA30: -1055.01 | AB30: -890.45 | AC30: -970.98 | AD30: -1011.11 | AE30: -3615.95
A31: Income/(loss) before income taxes | B31: 4492 | C31: 13783 | D31: 3835 | E31: 2160 | F31: 25766 | G31: 2732 | H31: 4612 | I31: 4080.04 | J31: 2559.64 | K31: 13947.19 | L31: 3247.61 | M31: 4231.33 | N31: 4117.58 | O31: 2793.12 | P31: 14437.94 | Q31: 3426.38 | R31: 4347.98 | S31: 4306.18 | T31: 2868.91 | U31: 15084.83 | V31: 3392.95 | W31: 4356.11 | X31: 4360.15 | Y31: 2955.35 | Z31: 15381.58 | AA31: 3442.53 | AB31: 4484.43 | AC31: 4484.29 | AD31: 3149.68 | AE31: 16002.52
A32: Income tax expense/(benefit) | B32: 1196 | C32: 3603 | D32: 1218 | E32: 89 | F32: 6106 | G32: 706 | H32: 1194 | I32: 1043.19 | J32: 633.56 | K32: 3576.73 | L32: 816.86 | M32: 1059.07 | N32: 1030.94 | O32: 702.32 | P32: 3687.62 | Q32: 882.89 | R32: 1113.28 | S32: 1104.14 | T32: 739.86 | U32: 3881.62 | V32: 875.91 | W32: 1116.79 | X32: 1117.54 | Y32: 766.36 | Z32: 3962.45 | AA32: 888.27 | AB32: 1149.73 | AC32: 1149.48 | AD32: 814.46 | AE32: 4119.73
A33: Net income/(loss) before non-controlling interest | B33: 3296 | C33: 10180 | D33: 2617 | E33: 2071 | F33: 19660 | G33: 2026 | H33: 3419 | I33: 3045.58 | J33: 1935.77 | K33: 10412.46 | L33: 2457.02 | M33: 3190.84 | N33: 3086.64 | O33: 2090.8 | P33: 10788.92 | Q33: 2543.5 | R33: 3234.82 | S33: 3202.03 | T33: 2129.05 | U33: 11268.46 | V33: 2517.03 | W33: 3239.46 | X33: 3242.61 | Y33: 2188.99 | Z33: 11419.2 | AA33: 2554.26 | AB33: 3334.85 | AC33: 3334.81 | AD33: 2335.22 | AE33: 11882.86
A34: Noncontrolling interests, net | B34: -79 | C34: -79 | D34: -83 | E34: -97 | F34: -338 | G34: -147 | H34: -107 | I34: -83.82 | J34: -94.23 | K34: -420.84 | L34: -82.79 | M34: -93.66 | N34: -69.77 | O34: -88.63 | P34: -340.1 | Q34: -79.91 | R34: -89.02 | S34: -51.81 | T34: -76.21 | U34: -330.62 | V34: -69.92 | W34: -75.08 | X34: -29.34 | Y34: -58 | Z34: -303.4 | AA34: -71.01 | AB34: -64.36 | AC34: -12.59 | AD34: -40.46 | AE34: -290
A35: Net income/(loss) attributable to CMCSA | B35: 3375 | C35: 10259 | D35: 2700 | E35: 2168 | F35: 19998 | G35: 2174 | H35: 3526 | I35: 3120.67 | J35: 2020.31 | K35: 10789.06 | L35: 2513.54 | M35: 3266.01 | N35: 3156.41 | O35: 2179.43 | P35: 11090.47 | Q35: 2623.41 | R35: 3323.84 | S35: 3253.84 | T35: 2205.25 | U35: 11533.88 | V35: 2586.95 | W35: 3314.55 | X35: 3271.95 | Y35: 2246.99 | Z35: 11722.6 | AA35: 2625.27 | AB35: 3399.21 | AC35: 3347.39 | AD35: 2375.68 | AE35: 12172.86
A36: Net of tax adjustments | B36: 757 | C36: -6471 | D36: 793 | E36: 895 | F36: -4026 | G36: 690 | H36: 185 | I36: 382.75 | J36: 359.49 | K36: 1601.38 | L36: 392.53 | M36: 362.03 | N36: 393.08 | O36: 362.77 | P36: 1487.87 | Q36: 454.55 | R36: 354.08 | S36: 401.3 | T36: 391.95 | U36: 1448.02 | V36: 468.82 | W36: 359.61 | X36: 403.01 | Y36: 415.82 | Z36: 1477.71 | AA36: 457.16 | AB36: 347.99 | AC36: 389.73 | AD36: 402.45 | AE36: 1444.6
A37: Net income/(loss) attributable to CMCSA - operating | B37: 4132 | C37: 4653 | D37: 3493 | E37: 3062 | F37: 15972 | G37: 2863 | H37: 3710 | I37: 3463.72 | J37: 2355.12 | K37: 12384.21 | L37: 2882.53 | M37: 3631.29 | N37: 3571.25 | O37: 2582.3 | P37: 12526.77 | Q37: 3077.96 | R37: 3677.92 | S37: 3655.14 | T37: 2597.21 | U37: 12942.5 | V37: 3055.78 | W37: 3674.15 | X37: 3674.96 | Y37: 2662.81 | Z37: 13126.66 | AA37: 3082.43 | AB37: 3747.19 | AC37: 3737.13 | AD37: 2778.12 | AE37: 13586.02
A38: EPS - basic($) | B38: 0.9 | C38: 2.99 | D38: 0.91 | E38: 0.6 | F38: 5.41 | G38: 0.61 | H38: 0.99 | I38: 0.88 | J38: 0.55 | K38: 3.02 | L38: 0.7 | M38: 0.95 | N38: 0.91 | O38: 0.64 | P38: 3.19 | Q38: 0.74 | R38: 1.01 | S38: 0.96 | T38: 0.71 | U38: 3.48 | V38: 0.78 | W38: 1.06 | X38: 1.01 | Y38: 0.71 | Z38: 3.7 | AA38: 0.85 | AB38: 1.14 | AC38: 1.08 | AD38: 0.78 | AE38: 4.14
... A43: Dividend per share($) | B43: 0.33 | C43: 0.33 | D43: 0.33 | E43: 0.33 | F43: 1.32 | G43: 0.33 | H43: 0.33 | I43: 0.33 | J43: 0.33 | K43: 1.33 | L43: 0.34 | M43: 0.35 | N43: 0.35 | O43: 0.35 | P43: 1.39 | Q43: 0.36 | R43: 0.37 | S43: 0.37 | T43: 0.37 | U43: 1.46 | V43: 0.38 | W43: 0.39 | X43: 0.39 | Y43: 0.39 | Z43: 1.54 | AA43: 0.4 | AB43: 0.42 | AC43: 0.42 | AD43: 0.42 | AE43: 1.62

Sheet SPG Segments
A2: Comcast Corporation | Segments
A3: NASDAQGS:CMCSA (MI KEY: 4057180; SPCIQ KEY: 173341)
A5: Visible Alpha
A7: Period Type : Fiscal Quarter, Fiscal Halves, Fiscal Year
A8: Period Start : 2025
A9: Period End : 2030
A10: Currency : Reported
A11: Consensus View : Mean
A12: As Of: 10/20/2026
A14: All numbers in $M unless otherwise indicated | B14: FQ1 2025A | C14: FQ2 2025A | D14: FQ3 2025A | E14: FQ4 2025A | F14: FY2025A | G14: FQ1 2026A | H14: FQ2 2026A | I14: FQ3 2026E | J14: FQ4 2026E | K14: FY2026E | L14: FQ1 2027E | M14: FQ2 2027E | N14: FQ3 2027E | O14: FQ4 2027E | P14: FY2027E | Q14: FQ1 2028E | R14: FQ2 2028E | S14: FQ3 2028E | T14: FQ4 2028E | U14: FY2028E | V14: FQ1 2029E | W14: FQ2 2029E | X14: FQ3 2029E | Y14: FQ4 2029E | Z14: FY2029E | AA14: FQ1 2030E | AB14: FQ2 2030E | AC14: FQ3 2030E | AD14: FQ4 2030E | AE14: FY2030E
A15: Number of Contributors Available | B15: 22 | C15: 21 | D15: 21 | E15: 20 | F15: 21 | G15: 21 | H15: 20 | I15: 20 of 20 | J15: 20 of 20 | K15: 20 of 20 | L15: 12 of 20 | M15: 12 of 20 | N15: 11 of 20 | O15: 11 of 20 | P15: 20 of 20 | Q15: 8 of 20 | R15: 8 of 20 | S15: 8 of 20 | T15: 8 of 20 | U15: 19 of 20 | V15: 7 of 20 | W15: 7 of 20 | X15: 7 of 20 | Y15: 7 of 20 | Z15: 16 of 20 | AA15: 7 of 20 | AB15: 7 of 20 | AC15: 7 of 20 | AD15: 7 of 20 | AE15: 16 of 20
A16: Revenue
A17: Total connectivity and platforms revenue | B17: 20161 | C17: 20414 | D17: 20212 | E17: 20282 | F17: 81069 | G17: 19962 | H17: 19795 | I17: 19677.91 | J17: 19893.98 | K17: 79329.57 | L17: 19611.38 | M17: 19489.81 | N17: 19338 | O17: 19534.55 | P17: 78171.99 | Q17: 19508.57 | R17: 19392.88 | S17: 19311.31 | T17: 19564.47 | U17: 77831.83 | V17: 19474.87 | W17: 19370.9 | X17: 19255.8 | Y17: 19480.69 | Z17: 77326.17 | AA17: 19502.4 | AB17: 19416.88 | AC17: 19329.09 | AD17: 19604.16 | AE17: 77398.34
A18: Total content and experiences revenue | B18: 8546 | C18: 8728 | D18: 9897 | E18: 10941 | F18: 38114 | G18: 11941 | H18: 10728 | I18: 10519.29 | J18: 11188.49 | K18: 44372.14 | L18: 10500.26 | M18: 10471.82 | N18: 10540.21 | O18: 11446.38 | P18: 43316.08 | Q18: 10879.31 | R18: 10821.01 | S18: 12674.61 | T18: 11823.91 | U18: 46512.26 | V18: 11200.91 | W18: 11037.75 | X18: 11171.84 | Y18: 12042.92 | Z18: 46069.93 | AA18: 12826.75 | AB18: 11486.95 | AC18: 11564.81 | AD18: 12386.32 | AE18: 49005.92
A19: Corporate and other | B19: 390 | C19: 322 | D19: 315 | E19: 379 | F19: 1406 | G19: 424 | H19: 368 | I19: 331.91 | J19: 371.72 | K19: 1598.54 | L19: 404.79 | M19: 365.8 | N19: 331.89 | O19: 374.11 | P19: 1481.95 | Q19: 391.06 | R19: 349.95 | S19: 312.28 | T19: 359.35 | U19: 1480.75 | V19: 386.99 | W19: 347.44 | X19: 311.54 | Y19: 357.71 | Z19: 1481.27 | AA19: 387.97 | AB19: 347.68 | AC19: 311.09 | AD19: 358.33 | AE19: 1488.61
A20: Eliminations | B20: -1231 | C20: -1217 | D20: -1273 | E20: -1315 | F20: -5036 | G20: -1435 | H20: -1324 | I20: -1306.51 | J20: -1348.61 | K20: -5417.1 | L20: -1366.65 | M20: -1330.36 | N20: -1319.45 | O20: -1352.74 | P20: -5343.01 | Q20: -1343.16 | R20: -1307.14 | S20: -1365.85 | T20: -1342.81 | U20: -5447.51 | V20: -1357.6 | W20: -1314.19 | X20: -1314.71 | Y20: -1355.16 | Z20: -5469.96 | AA20: -1406.01 | AB20: -1329.72 | AC20: -1331.72 | AD20: -1373.95 | AE20: -5616.33
A21: Corporate, other and eliminations | B21: -841 | C21: -895 | D21: -958 | E21: -936 | F21: -3630 | G21: -1011 | H21: -956 | I21: -976.59 | J21: -974.37 | K21: -3828.49 | L21: -966.33 | M21: -963.79 | N21: -988.44 | O21: -974.75 | P21: -3885.57 | Q21: -959.47 | R21: -957.05 | S21: -1046.53 | T21: -977.53 | U21: -3990.43 | V21: -976.38 | W21: -965.22 | X21: -1002.32 | Y21: -988.67 | Z21: -3982.79 | AA21: -1017.03 | AB21: -978.32 | AC21: -1017.3 | AD21: -1004.25 | AE21: -4112.56
A22: Revenue | B22: 27865 | C22: 28249 | D22: 29151 | E22: 30287 | F22: 115552 | G22: 30892 | H22: 29568 | I22: 29229.46 | J22: 30096.76 | K22: 119902.79 | L22: 29232.16 | M22: 29071.52 | N22: 28889.77 | O22: 30006.17 | P22: 117534.94 | Q22: 29428.42 | R22: 29256.84 | S22: 30939.39 | T22: 30410.85 | U22: 120340.38 | V22: 29699.41 | W22: 29443.43 | X22: 29425.33 | Y22: 30534.94 | Z22: 119319.01 | AA22: 31312.12 | AB22: 29925.52 | AC22: 29876.6 | AD22: 30986.23 | AE22: 122294.14
A24: Costs and expenses excl. D&A
A25: Total connectivity and platforms - Costs and Exps excl. D&A | B25: 11896 | C25: 11964 | D25: 12274 | E25: 12846 | F25: 48980 | G25: 12053 | H25: 11830 | I25: 12098.09 | J25: 12651.19 | K25: 48632.23 | L25: 11864.01 | M25: 11626.76 | N25: 11819.52 | O25: 12310.38 | P25: 47811 | Q25: 11768.39 | R25: 11579.72 | S25: 11842.3 | T25: 12402.32 | U25: 47407.11 | V25: 11719.49 | W25: 11542.93 | X25: 11810.46 | Y25: 12387.55 | Z25: 47028.68 | AA25: 11739.86 | AB25: 11573.57 | AC25: 11857.3 | AD25: 12445.9 | AE25: 46862.37
A26: Total content and experiences - Costs and exps excl. D&A | B26: 7932 | C26: 7490 | D26: 8507 | E26: 10666 | F26: 34593 | G26: 11609 | H26: 9399 | I26: 8877.66 | J26: 10565.15 | K26: 40450.41 | L26: 9874.52 | M26: 9133.67 | N26: 8861.75 | O26: 10625.75 | P26: 38781.15 | Q26: 10069.33 | R26: 9362.23 | S26: 10765.86 | T26: 10830.34 | U26: 41330.47 | V26: 10331.74 | W26: 9490.14 | X26: 9144.92 | Y26: 10857.68 | Z26: 40533.77 | AA26: 11810.76 | AB26: 9775.61 | AC26: 9383.61 | AD26: 11028.08 | AE26: 42789.96
A27: Corporate and other - Costs and exps excl. D&A | B27: 585 | C27: 609 | D27: 587 | E27: 793 | F27: 2574 | G27: 669 | H27: 742 | I27: 632.23 | J27: 731.66 | K27: 2960.92 | L27: 666.15 | M27: 712.81 | N27: 612.89 | O27: 749.49 | P27: 2721.19 | Q27: 657.26 | R27: 744.3 | S27: 624.76 | T27: 763.27 | U27: 2778.89 | V27: 661.32 | W27: 757.32 | X27: 638.55 | Y27: 767.36 | Z27: 2812.79 | AA27: 666.79 | AB27: 767.45 | AC27: 641.99 | AD27: 775.31 | AE27: 2858.12
A28: Eliminations - Costs and exps excl. D&A | B28: -1244 | C28: -1237 | D28: -1254 | E28: -1315 | F28: -5050 | G28: -1404 | H28: -1327 | I28: -1303.22 | J28: -1361.05 | K28: -5399.48 | L28: -1390.5 | M28: -1352.2 | N28: -1331.17 | O28: -1377.56 | P28: -5401.57 | Q28: -1400.73 | R28: -1350.35 | S28: -1376.74 | T28: -1401.16 | U28: -5493.57 | V28: -1435.64 | W28: -1392.41 | X28: -1393.66 | Y28: -1461.18 | Z28: -5576.12 | AA28: -1511.44 | AB28: -1431.82 | AC28: -1434.23 | AD28: -1506.52 | AE28: -5750.7
A29: Corporate, other and eliminations excl. D&A | B29: -659 | C29: -628 | D29: -667 | E29: -522 | F29: -2476 | G29: -735 | H29: -585 | I29: -676.86 | J29: -633.74 | K29: -2462.76 | L29: -728.93 | M29: -647.71 | N29: -721.9 | O29: -635.31 | P29: -2698.7 | Q29: -746.97 | R29: -626.04 | S29: -751.03 | T29: -647.52 | U29: -2731.55 | V29: -770.99 | W29: -652.82 | X29: -753.15 | Y29: -691.86 | Z29: -2777.02 | AA29: -823.74 | AB29: -674.78 | AC29: -780.99 | AD29: -719.91 | AE29: -2893.35
A30: Total cost and exp. excl. D&A | B30: 19170 | C30: 18826 | D30: 20113 | E30: 22989 | F30: 81098 | G30: 22925 | H30: 20645 | I30: 20349.17 | J30: 22678.22 | K30: 86776.23 | L30: 21231.38 | M30: 20184.31 | N30: 19962.22 | O30: 22332.76 | P30: 84173.96 | Q30: 21319.98 | R30: 20268.68 | S30: 21817.52 | T30: 22662.51 | U30: 86309.48 | V30: 21551.81 | W30: 20322.91 | X30: 20206.81 | Y30: 22686.03 | Z30: 85081.04 | AA30: 22962.76 | AB30: 20655.1 | AC30: 20498.39 | AD30: 22887.16 | AE30: 87294.06
A32: Adjusted EBITDA
A33: Total connectivity and platforms - Adjusted EBITDA | B33: 8264 | C33: 8450 | D33: 7938 | E33: 7437 | F33: 32089 | G33: 7910 | H33: 7964 | I33: 7568.55 | J33: 7256.55 | K33: 30699.78 | L33: 7740.79 | M33: 7846.8 | N33: 7518.48 | O33: 7224.17 | P33: 30358.14 | Q33: 7740.18 | R33: 7813.16 | S33: 7469.01 | T33: 7162.15 | U33: 30414.22 | V33: 7755.39 | W33: 7827.97 | X33: 7445.35 | Y33: 7093.15 | Z33: 30297.5 | AA33: 7762.54 | AB33: 7843.31 | AC33: 7471.8 | AD33: 7158.26 | AE33: 30535.97
A34: Total Content and experiences - Adjusted EBITDA | B34: 614 | C34: 1241 | D34: 1392 | E34: 275 | F34: 3521 | G34: 331 | H34: 1329 | I34: 1609.76 | J34: 581.84 | K34: 3848.34 | L34: 566.37 | M34: 1339.86 | N34: 1661.17 | O34: 796 | P34: 4357.17 | Q34: 721.96 | R34: 1475.83 | S34: 1931.16 | T34: 946.86 | U34: 5038.68 | V34: 763.26 | W34: 1561.51 | X34: 1989.69 | Y34: 1089.93 | Z34: 5365.75 | AA34: 845.54 | AB34: 1697.39 | AC34: 2109.68 | AD34: 1241.02 | AE34: 5903.78
A35: Corporate and other - Adjusted EBITDA | B35: -195 | C35: -287 | D35: -272 | E35: -414 | F35: -1168 | G35: -244 | H35: -374 | I35: -296.47 | J35: -400.62 | K35: -1322.21 | L35: -255 | M35: -354.72 | N35: -278.48 | O35: -384.22 | P35: -1252.78 | Q35: -261.79 | R35: -374.53 | S35: -299.82 | T35: -392 | U35: -1300.59 | V35: -268.97 | W35: -382.52 | X35: -307.28 | Y35: -396.14 | Z35: -1341.9 | AA35: -272.6 | AB35: -389.66 | AC35: -311.45 | AD35: -402 | AE35: -1374.76
A36: Eliminations - Adjusted EBITDA | B36: 13 | C36: 21 | D36: -19 | E36: - | F36: 13 | G36: -31 | H36: 3 | I36: -16.89 | J36: -57.88 | K36: -58.93 | L36: -14.02 | M36: 3.53 | N36: -18.57 | O36: -7.2 | P36: -50.4 | Q36: -10.47 | R36: 5.05 | S36: -20.11 | T36: - | U36: -70.88 | V36: -6.37 | W36: 5.5 | X36: -20.35 | Y36: - | Z36: -74.9 | AA36: -6.84 | AB36: 5.54 | AC36: -20.66 | AD36: - | AE36: -76.85
A37: Corporate, other and eliminations - adjusted EBITDA | B37: -181 | C37: -267 | D37: -291 | E37: -414 | F37: -1154 | G37: -276 | H37: -371 | I37: -310.35 | J37: -409.08 | K37: -1371.9 | L37: -271.94 | M37: -350.1 | N37: -298.89 | O37: -377.52 | P37: -1302.61 | Q37: -274.23 | R37: -374.09 | S37: -320.7 | T37: -393.37 | U37: -1374.92 | V37: -279.45 | W37: -383.56 | X37: -329.36 | Y37: -399.43 | Z37: -1400.04 | AA37: -284.67 | AB37: -392.04 | AC37: -335.2 | AD37: -406.84 | AE37: -1440.51
A38: Adjusted EBITDA | B38: 8695 | C38: 9423 | D38: 9038 | E38: 7298 | F38: 34454 | G38: 7967 | H38: 8923 | I38: 8867.61 | J38: 7422.42 | K38: 33164.19 | L38: 8035.64 | M38: 8864.77 | N38: 8868.47 | O38: 7609 | P38: 33333.85 | Q38: 8122.09 | R38: 8914.82 | S38: 9026.42 | T38: 7659.09 | U38: 33967.78 | V38: 8158.34 | W38: 8989.6 | X38: 9054.84 | Y38: 7733.29 | Z38: 34127.15 | AA38: 8241.84 | AB38: 9099.61 | AC38: 9198.46 | AD38: 7956.13 | AE38: 34809.51
A40: Supplemental
A41: NBCUniversal Adjusted EBITDA | B41: 628.81 | C41: 911.72 | D41: 1012.32 | E41: 387.26 | F41: 3810.48 | G41: 713.01 | H41: 1192.39 | I41: 1307.33 | J41: 664.93 | K41: 4924.82 | L41: 1764.88 | M41: 1228.21 | N41: 1440.23 | O41: 1583.61 | P41: 4402.13 | Q41: - | R41: - | S41: - | T41: - | U41: 4527.56 | V41: - | W41: - | X41: - | Y41: - | Z41: 4862.52 | AA41: - | AB41: - | AC41: - | AD41: - | AE41: 5461.25
A42: Sky Adjusted EBITDA | B42: 256.19 | C42: 210.4 | D42: 112.97 | E42: -159.98 | F42: 983.23 | G42: 195.24 | H42: 274.7 | I42: 406.48 | J42: 57.14 | K42: 1359.29 | L42: 104.31 | M42: 104.14 | N42: 116.9 | O42: 131.76 | P42: 1339.25 | Q42: - | R42: - | S42: - | T42: - | U42: 1569.47 | V42: - | W42: - | X42: - | Y42: - | Z42: 1502.12 | AA42: - | AB42: - | AC42: - | AD42: - | AE42: 1755.56
A43: Cable communications Adjusted EBITDA | B43: 7631.05 | C43: 7818.21 | D43: 7688.96 | E43: 7461.49 | F43: 30908.62 | G43: 6729 | H43: 6816.81 | I43: 6552.51 | J43: 6467.82 | K43: 29305.19 | L43: 5315.61 | M43: 5335.73 | N43: 5320.02 | O43: 4866.38 | P43: 28056.35 | Q43: - | R43: - | S43: - | T43: - | U43: 32064.63 | V43: - | W43: - | X43: - | Y43: - | Z43: 31943.14 | AA43: - | AB43: - | AC43: - | AD43: - | AE43: 32307.11
A44: Corporate and eliminations Adjusted EBITDA | B44: 173.05 | C44: 644.31 | D44: -25.27 | E44: -231.6 | F44: 91.1 | G44: 618.83 | H44: 648.61 | I44: 508.85 | J44: 262.15 | K44: 1143.84 | L44: -492.71 | M44: 764.38 | N44: 1044.67 | O44: 2152.08 | P44: 642.61 | Q44: - | R44: - | S44: 800 | T44: - | U44: -423.41 | V44: 600 | W44: - | X44: -800 | Y44: - | Z44: -708.74 | AA44: 50 | AB44: - | AC44: - | AD44: - | AE44: -577.42

Sheet SPG Free Cash Flow
A2: Comcast Corporation | Free Cash Flow
A3: NASDAQGS:CMCSA (MI KEY: 4057180; SPCIQ KEY: 173341)
A5: Visible Alpha
A7: Period Type : Fiscal Quarter, Fiscal Halves, Fiscal Year
A8: Period Start : 2025
A9: Period End : 2030
A10: Currency : Reported
A11: Consensus View : Mean
A12: As Of: 10/20/2026
A14: All numbers in $M unless otherwise indicated | B14: FQ1 2025A | C14: FQ2 2025A | D14: FQ3 2025A | E14: FQ4 2025A | F14: FY2025A | G14: FQ1 2026A | H14: FQ2 2026A | I14: FQ3 2026E | J14: FQ4 2026E | K14: FY2026E | L14: FQ1 2027E | M14: FQ2 2027E | N14: FQ3 2027E | O14: FQ4 2027E | P14: FY2027E | Q14: FQ1 2028E | R14: FQ2 2028E | S14: FQ3 2028E | T14: FQ4 2028E | U14: FY2028E | V14: FQ1 2029E | W14: FQ2 2029E | X14: FQ3 2029E | Y14: FQ4 2029E | Z14: FY2029E | AA14: FQ1 2030E | AB14: FQ2 2030E | AC14: FQ3 2030E | AD14: FQ4 2030E | AE14: FY2030E
A15: Number of Contributors Available | B15: 22 | C15: 21 | D15: 21 | E15: 20 | F15: 21 | G15: 21 | H15: 20 | I15: 20 of 20 | J15: 20 of 20 | K15: 20 of 20 | L15: 12 of 20 | M15: 12 of 20 | N15: 11 of 20 | O15: 11 of 20 | P15: 20 of 20 | Q15: 8 of 20 | R15: 8 of 20 | S15: 8 of 20 | T15: 8 of 20 | U15: 19 of 20 | V15: 7 of 20 | W15: 7 of 20 | X15: 7 of 20 | Y15: 7 of 20 | Z15: 16 of 20 | AA15: 7 of 20 | AB15: 7 of 20 | AC15: 7 of 20 | AD15: 7 of 20 | AE15: 16 of 20
A16: Net cash provided by (used in) operating activities | B16: 8294 | C16: 7815 | D16: 8693 | E16: 8841 | F16: 33643 | G16: 6891 | H16: 8092 | I16: 7001.35 | J16: 6018.83 | K16: 27655.01 | L16: 6135.92 | M16: 6783.34 | N16: 7258.61 | O16: 6465.71 | P16: 26871.55 | Q16: 6319 | R16: 6848.69 | S16: 7316.64 | T16: 6670.71 | U16: 27855.68 | V16: 6303.2 | W16: 6892.89 | X16: 7248.68 | Y16: 6770.94 | Z16: 28332.21 | AA16: 6478.25 | AB16: 7006.89 | AC16: 7405.78 | AD16: 6946.68 | AE16: 28838.83
A17: Capital expenditures | B17: 2252 | C17: 2679 | D17: 3071 | E17: 3749 | F17: 11750 | G17: 2351 | H17: 2902 | I17: 3008.63 | J17: 3414.4 | K17: 11697.53 | L17: 2533.47 | M17: 2889.47 | N17: 2944.27 | O17: 3364.73 | P17: 11716.07 | Q17: 2495.59 | R17: 2889.56 | S17: 2991.8 | T17: 3449.46 | U17: 11828.09 | V17: 2618.33 | W17: 2994.08 | X17: 3032.18 | Y17: 3488.74 | Z17: 12097.24 | AA17: 2666.01 | AB17: 2998.68 | AC17: 3048.83 | AD17: 3510.75 | AE17: 12211.56
A18: Cash paid for capitalized software and other intangibles | B18: 622 | C18: 635 | D18: 677 | E18: 724 | F18: 2658 | G18: 639 | H18: 587 | I18: 657.95 | J18: 708.22 | K18: 2597.07 | L18: 623.25 | M18: 603.68 | N18: 650.4 | O18: 686.13 | P18: 2578.62 | Q18: 641.08 | R18: 624.04 | S18: 679.9 | T18: 700.06 | U18: 2642.91 | V18: 645.72 | W18: 632.75 | X18: 670.78 | Y18: 699.48 | Z18: 2644.42 | AA18: 656.95 | AB18: 637.21 | AC18: 675.29 | AD18: 704.55 | AE18: 2683.72
A19: Capex (incl. intangible invest) | B19: -2874 | C19: -3314 | D19: -3748 | E19: -4473 | F19: -14408 | G19: -2990 | H19: -3489 | I19: -3680.37 | J19: -4139.18 | K19: -14323.15 | L19: -3086.06 | M19: -3396.92 | N19: -3594.67 | O19: -4050.86 | P19: -14340.95 | Q19: -3136.67 | R19: -3513.61 | S19: -3671.7 | T19: -4149.52 | U19: -14536.36 | V19: -3264.05 | W19: -3626.83 | X19: -3702.95 | Y19: -4188.22 | Z19: -14811.29 | AA19: -3322.95 | AB19: -3635.9 | AC19: -3724.12 | AD19: -4215.3 | AE19: -14974.17
A20: Free cash flow incl. economic stimulus | B20: 4584 | C20: 4500 | D20: 4945 | E20: 4369 | F20: 19236 | G20: 3901 | H20: 4604 | I20: 3425.71 | J20: 1974.58 | K20: 13863.87 | L20: 3171.49 | M20: 3464.99 | N20: 3783.32 | O20: 2546.54 | P20: 12922.37 | Q20: 3191.22 | R20: 3270.93 | S20: 3612.08 | T20: 2503.3 | U20: 13259.15 | V20: 3041.8 | W20: 3196.54 | X20: 3505.63 | Y20: 2557.22 | Z20: 13382.58 | AA20: 3152.04 | AB20: 3304.09 | AC20: 3638.9 | AD20: 2700.97 | AE20: 13773.22
A22: FCF calculation
A23: Adjusted EBITDA - FCF | B23: 8695 | C23: 9423 | D23: 9038 | E23: 7298 | F23: 34454 | G23: 7966 | H23: 8923 | I23: 8805.09 | J23: 7302.03 | K23: 32768.07 | L23: 7992.17 | M23: 8831.62 | N23: 8888.92 | O23: 7739.29 | P23: 32929.89 | Q23: 8156.03 | R23: 8941.32 | S23: 9141.41 | T23: 7810.4 | U23: 33573.11 | V23: 8206.17 | W23: 8978.81 | X23: 9124.69 | Y23: 7722.94 | Z23: 33736.76 | AA23: 8225.65 | AB23: 9145.88 | AC23: 9262.04 | AD23: 7891.56 | AE23: 34446.25
A24: Capital expenditures | B24: 2252 | C24: 2679 | D24: 3071 | E24: 3749 | F24: 11750 | G24: 2351 | H24: 2902 | I24: 3008.63 | J24: 3414.4 | K24: 11697.53 | L24: 2533.47 | M24: 2889.47 | N24: 2944.27 | O24: 3364.73 | P24: 11716.07 | Q24: 2495.59 | R24: 2889.56 | S24: 2991.8 | T24: 3449.46 | U24: 11828.09 | V24: 2618.33 | W24: 2994.08 | X24: 3032.18 | Y24: 3488.74 | Z24: 12097.24 | AA24: 2666.01 | AB24: 2998.68 | AC24: 3048.83 | AD24: 3510.75 | AE24: 12211.56
A25: Cash paid for capitalized software and other intangibles | B25: 622 | C25: 635 | D25: 677 | E25: 724 | F25: 2658 | G25: 639 | H25: 587 | I25: 657.95 | J25: 708.22 | K25: 2597.07 | L25: 623.25 | M25: 603.68 | N25: 650.4 | O25: 686.13 | P25: 2578.62 | Q25: 641.08 | R25: 624.04 | S25: 679.9 | T25: 700.06 | U25: 2642.91 | V25: 645.72 | W25: 632.75 | X25: 670.78 | Y25: 699.48 | Z25: 2644.42 | AA25: 656.95 | AB25: 637.21 | AC25: 675.29 | AD25: 704.55 | AE25: 2683.72
A26: Capex (incl. intangible invest) | B26: -2874 | C26: -3314 | D26: -3748 | E26: -4473 | F26: -14408 | G26: -2990 | H26: -3489 | I26: -3680.37 | J26: -4139.18 | K26: -14323.15 | L26: -3086.06 | M26: -3396.92 | N26: -3594.67 | O26: -4050.86 | P26: -14340.95 | Q26: -3136.67 | R26: -3513.61 | S26: -3671.7 | T26: -4149.52 | U26: -14536.36 | V26: -3264.05 | W26: -3626.83 | X26: -3702.95 | Y26: -4188.22 | Z26: -14811.29 | AA26: -3322.95 | AB26: -3635.9 | AC26: -3724.12 | AD26: -4215.3 | AE26: -14974.17
A27: Cash interest expense - FCF | B27: 674 | C27: 1129 | D27: 879 | E27: 1189 | F27: 3871 | G27: 727 | H27: 1053.12 | I27: 831.23 | J27: 1006.94 | K27: 3702.01 | L27: 854.8 | M27: 947.23 | N27: 873.34 | O27: 980.33 | P27: 3565.15 | Q27: 734.51 | R27: 922.92 | S27: 769.83 | T27: 988.57 | U27: 3402.04 | V27: 731.77 | W27: 919.2 | X27: 763.98 | Y27: 976.66 | Z27: 3295.66 | AA27: 723.81 | AB27: 909.51 | AC27: 756.22 | AD27: 969.64 | AE27: 3213.7
A28: Cash taxes - FCF | B28: 400 | C28: 1685 | D28: 293 | E28: -1623 | F28: 755 | G28: 249 | H28: 515.67 | I28: 1039.49 | J28: 815 | K28: 2573.34 | L28: 646.66 | M28: 903.2 | N28: 1013.21 | O28: 745.16 | P28: 3101.97 | Q28: 601.2 | R28: 889 | S28: 1126.55 | T28: 730.64 | U28: 3226.81 | V28: 602.61 | W28: 888.08 | X28: 1132.4 | Y28: 677.66 | Z28: 3044.39 | AA28: 603.66 | AB28: 906.57 | AC28: 1146.79 | AD28: 602.36 | AE28: 3377.08
A29: Change in operating assets and liabilities - FCF | B29: 636 | C29: -22 | D29: 169 | E29: -232 | F29: 551 | G29: 555 | H29: -157 | I29: 498.39 | J29: 68.49 | K29: 574.48 | L29: 986.67 | M29: 697.17 | N29: -152.32 | O29: -281.01 | P29: 1151.22 | Q29: 1434.72 | R29: 962.82 | S29: -147.47 | T29: -630.57 | U29: 948.86 | V29: 1425.97 | W29: 930.91 | X29: 185.56 | Y29: -686.49 | Z29: 1148.66 | AA29: 1221.03 | AB29: 1019.9 | AC29: 134.08 | AD29: -591.09 | AE29: 1117.95
A30: Noncash share based compensation - FCF | B30: -382 | C30: -321 | D30: -311 | E30: -274 | F30: -1288 | G30: -427 | H30: -359 | I30: -328.47 | J30: -312.4 | K30: -1474.31 | L30: -381.69 | M30: -354.47 | N30: -339.22 | O30: -327.92 | P30: -1463.01 | Q30: -394.05 | R30: -343.17 | S30: -320.79 | T30: -293.19 | U30: -1491.64 | V30: -400.42 | W30: -348.26 | X30: -320.26 | Y30: -298.19 | Z30: -1497.29 | AA30: -411.53 | AB30: -354.64 | AC30: -326.33 | AD30: -303.55 | AE30: -1519.22
A31: Other adjustment - FCF | B31: -90 | C31: -3 | D31: -54 | E31: -2 | F31: -149 | G31: 55.22 | H31: -232.45 | I31: -25.26 | J31: -156.21 | K31: -309.62 | L31: -101.75 | M31: -97.73 | N31: -120.78 | O31: -101.12 | P31: -389.18 | Q31: - | R31: - | S31: - | T31: - | U31: -360.3 | V31: - | W31: - | X31: - | Y31: - | Z31: -411.25 | AA31: - | AB31: - | AC31: - | AD31: - | AE31: -412
A32: Adjustment - FCF | B32: -419.5 | C32: -859.5 | D32: -657.5 | E32: -402.33 | F32: -1693.33 | G32: 18.5 | H32: -319 | I32: - | J32: - | K32: -141 | L32: - | M32: - | N32: - | O32: - | P32: - | Q32: - | R32: - | S32: - | T32: - | U32: - | V32: - | W32: - | X32: - | Y32: - | Z32: - | AA32: - | AB32: - | AC32: - | AD32: - | AE32: -
A33: Free cash flow incl. economic stimulus | B33: 4584 | C33: 4500 | D33: 4945 | E33: 4369 | F33: 19236 | G33: 3901 | H33: 4604 | I33: 3425.71 | J33: 1974.58 | K33: 13863.87 | L33: 3171.49 | M33: 3464.99 | N33: 3783.32 | O33: 2546.54 | P33: 12922.37 | Q33: 3191.22 | R33: 3270.93 | S33: 3612.08 | T33: 2503.3 | U33: 13259.15 | V33: 3041.8 | W33: 3196.54 | X33: 3505.63 | Y33: 2557.22 | Z33: 13382.58 | AA33: 3152.04 | AB33: 3304.09 | AC33: 3638.9 | AD33: 2700.97 | AE33: 13773.22

Sheet SPG Conn & Platforms
A2: Comcast Corporation | Connectivity and Platforms
A3: NASDAQGS:CMCSA (MI KEY: 4057180; SPCIQ KEY: 173341)
A5: Visible Alpha
A7: Period Type : Fiscal Quarter, Fiscal Halves, Fiscal Year
A8: Period Start : 2025
A9: Period End : 2030
A10: Currency : Reported
A11: Consensus View : Mean
A12: As Of: 10/20/2026
A14: All numbers in $M unless otherwise indicated | B14: FQ1 2025A | C14: FQ2 2025A | D14: FQ3 2025A | E14: FQ4 2025A | F14: FY2025A | G14: FQ1 2026A | H14: FQ2 2026A | I14: FQ3 2026E | J14: FQ4 2026E | K14: FY2026E | L14: FQ1 2027E | M14: FQ2 2027E | N14: FQ3 2027E | O14: FQ4 2027E | P14: FY2027E | Q14: FQ1 2028E | R14: FQ2 2028E | S14: FQ3 2028E | T14: FQ4 2028E | U14: FY2028E | V14: FQ1 2029E | W14: FQ2 2029E | X14: FQ3 2029E | Y14: FQ4 2029E | Z14: FY2029E | AA14: FQ1 2030E | AB14: FQ2 2030E | AC14: FQ3 2030E | AD14: FQ4 2030E | AE14: FY2030E
A15: Number of Contributors Available | B15: 22 | C15: 21 | D15: 21 | E15: 20 | F15: 21 | G15: 21 | H15: 20 | I15: 20 of 20 | J15: 20 of 20 | K15: 20 of 20 | L15: 12 of 20 | M15: 12 of 20 | N15: 11 of 20 | O15: 11 of 20 | P15: 20 of 20 | Q15: 8 of 20 | R15: 8 of 20 | S15: 8 of 20 | T15: 8 of 20 | U15: 19 of 20 | V15: 7 of 20 | W15: 7 of 20 | X15: 7 of 20 | Y15: 7 of 20 | Z15: 16 of 20 | AA15: 7 of 20 | AB15: 7 of 20 | AC15: 7 of 20 | AD15: 7 of 20 | AE15: 16 of 20
A16: Domestic broadband residential customers
A17: Domestic broadband residential customers(K#) | B17: 29190 | C17: 28989 | D17: 28897 | E17: 28719 | F17: 28719 | G17: 28654 | H17: 28486 | I17: 28350.5 | J17: 28182.12 | K17: 28182.18 | L17: 28072.16 | M17: 27913.09 | N17: 27808.48 | O17: 27672.93 | P17: 27673.11 | Q17: 27617.89 | R17: 27466.44 | S17: 27384.01 | T17: 27259.07 | U17: 27169.88 | V17: 27288.94 | W17: 27166.39 | X17: 27116.23 | Y17: 27022.81 | Z17: 26785.05 | AA17: 26939.22 | AB17: 26818.32 | AC17: 26777.62 | AD17: 26689.54 | AE17: 26385.42
A18: Avg domestic broadband residential customers(K#) | B18: 29281.5 | C18: 29089.5 | D18: 28943 | E18: 28808 | F18: 29046 | G18: 28686.5 | H18: 28570 | I18: 28418.29 | J18: 28266.31 | K18: 28461.72 | L18: 28126.9 | M18: 27992.62 | N18: 27860.79 | O18: 27740.7 | P18: 27932.57 | Q18: 27663.14 | R18: 27542.16 | S18: 27425.22 | T18: 27321.54 | U18: 27424.53 | V18: 27327.8 | W18: 27227.66 | X18: 27141.31 | Y18: 27069.52 | Z18: 27006.17 | AA18: 26981.01 | AB18: 26878.77 | AC18: 26797.97 | AD18: 26733.58 | AE18: 26586.97
A19: Average monthly domestic broadband residential revenue per subscriber($) | B19: 76.03 | C19: 76.19 | D19: 75.44 | E19: 74.17 | F19: 75.42 | G19: 73.65 | H19: 73.27 | I19: 72.96 | J19: 72.79 | K19: 73.22 | L19: 73.38 | M19: 73.37 | N19: 73.24 | O19: 73.13 | P19: 73.14 | Q19: 74.02 | R19: 74.09 | S19: 73.93 | T19: 73.77 | U19: 73.47 | V19: 75.11 | W19: 75.26 | X19: 75.07 | Y19: 74.88 | Z19: 74.1 | AA19: 76.17 | AB19: 76.38 | AC19: 76.18 | AD19: 75.99 | AE19: 74.78
A20: Domestic broadband revenue | B20: 6679 | C20: 6649 | D20: 6550 | E20: 6410 | F20: 26288 | G20: 6338 | H20: 6280 | I20: 6221.77 | J20: 6167.32 | K20: 25007.2 | L20: 6197.42 | M20: 6164.08 | N20: 6120.45 | O20: 6084.53 | P20: 24560.83 | Q20: 6143.04 | R20: 6122.2 | S20: 6083.01 | T20: 6046.37 | U20: 24300.69 | V20: 6158.06 | W20: 6148.2 | X20: 6112.78 | Y20: 6081.47 | Z20: 24178.19 | AA20: 6166.36 | AB20: 6161.65 | AC20: 6126.33 | AD20: 6097.19 | AE20: 24076.69
A22: Domestic wireless customers
A23: Total domestic wireless lines(K#) | B23: 8148 | C23: 8527 | D23: 8941 | E23: 9305 | F23: 9305 | G23: 9739 | H23: 10187 | I23: 10586.4 | J23: 10972.44 | K23: 10972.49 | L23: 11352.17 | M23: 11741.5 | N23: 12118.03 | O23: 12480.89 | P23: 12490.77 | Q23: 12823.06 | R23: 13200.51 | S23: 13557.76 | T23: 13898.8 | U23: 13860.48 | V23: 14235.31 | W23: 14601.13 | X23: 14942.62 | Y23: 15274.73 | Z23: 15130.43 | AA23: 15593.72 | AB23: 15951.35 | AC23: 16288.43 | AD23: 16614.15 | AE23: 16324.41
A24: Avg total domestic wireless lines(K#) | B24: 7987 | C24: 8337.5 | D24: 8733.5 | E24: 9123 | F24: 8565.5 | G24: 9522 | H24: 9963 | I24: 10386.31 | J24: 10777.86 | K24: 10144.86 | L24: 11161.24 | M24: 11546.84 | N24: 11929.77 | O24: 12299.46 | P24: 11733.84 | Q24: 12646.02 | R24: 13011.78 | S24: 13379.13 | T24: 13728.28 | U24: 13171.84 | V24: 14070.04 | W24: 14418.22 | X24: 14771.88 | Y24: 15108.68 | Z24: 14497.69 | AA24: 15434.23 | AB24: 15772.54 | AC24: 16119.89 | AD24: 16451.29 | AE24: 15729.52
A25: Average monthly total domestic wireless revenue per subscriber($) | B25: 46.87 | C25: 47.78 | D25: 47.56 | E25: 51.26 | F25: 48.32 | G25: 48.83 | H25: 47.21 | I25: 46.51 | J25: 49.6 | K25: 48.12 | L25: 47.14 | M25: 46.42 | N25: 45.7 | O25: 48.47 | P25: 47.21 | Q25: 47.16 | R25: 46.49 | S25: 45.86 | T25: 48.49 | U25: 46.76 | V25: 47.06 | W25: 46.3 | X25: 45.96 | Y25: 48.51 | Z25: 46.71 | AA25: 47.38 | AB25: 46.53 | AC25: 46.22 | AD25: 48.65 | AE25: 46.87
A26: Domestic wireless revenue | B26: 1123 | C26: 1195 | D26: 1246 | E26: 1403 | F26: 4967 | G26: 1395 | H26: 1411 | I26: 1450.07 | J26: 1606.28 | K26: 5861.71 | L26: 1579.24 | M26: 1606.7 | N26: 1635.53 | O26: 1788.53 | P26: 6647.92 | Q26: 1789.19 | R26: 1814.69 | S26: 1840.72 | T26: 1997.6 | U26: 7387.21 | V26: 1987.02 | W26: 2003.07 | X26: 2037.68 | Y26: 2199.91 | Z26: 8130.32 | AA26: 2194.91 | AB26: 2202.83 | AC26: 2236.92 | AD26: 2403.21 | AE26: 8856.12
A28: International residential connectivity customer relationships
A29: International residential connectivity & platforms customer relationships(K#) | B29: 17674 | C29: 17573 | D29: 17477 | E29: 17499 | F29: 17499 | G29: 17603 | H29: 17539 | I29: 17485.47 | J29: 17507.69 | K29: 17505.89 | L29: 17553.54 | M29: 17506.92 | N29: 17467.62 | O29: 17485.98 | P29: 17483.63 | Q29: 17566.02 | R29: 17529.27 | S29: 17491.85 | T29: 17513.48 | U29: 17473.44 | V29: 17525.64 | W29: 17479.43 | X29: 17431.6 | Y29: 17452.07 | Z29: 17432.49 | AA29: 17504.57 | AB29: 17458.73 | AC29: 17411.72 | AD29: 17432.51 | AE29: 17417.99
A30: Avg international residential connectivity & platforms customer relationships(K#) | B30: 17680 | C30: 17623.5 | D30: 17525 | E30: 17488 | F30: 17592.5 | G30: 17551 | H30: 17571 | I30: 17512.23 | J30: 17496.58 | K30: 17515.48 | L30: 17535.94 | M30: 17530.23 | N30: 17487.27 | O30: 17476.8 | P30: 17497.94 | Q30: 17541 | R30: 17547.65 | S30: 17510.56 | T30: 17502.67 | U30: 17482.4 | V30: 17499.88 | W30: 17502.53 | X30: 17455.51 | Y30: 17441.83 | Z30: 17444.27 | AA30: 17478.32 | AB30: 17481.65 | AC30: 17435.22 | AD30: 17422.12 | AE30: 17427.92
A31: Average monthly international residential customer relationship revenue per customer($) | B31: 21.34 | C31: 23.06 | D31: 24.25 | E31: 25.48 | F31: 23.51 | G31: 23.55 | H31: 23.64 | I31: 24.82 | J31: 26.14 | K31: 24.53 | L31: 24.29 | M31: 24.69 | N31: 25.93 | O31: 27.37 | P31: 25.53 | Q31: 24.76 | R31: 25.12 | S31: 26.5 | T31: 27.9 | U31: 26.08 | V31: 25.39 | W31: 25.79 | X31: 27.15 | Y31: 28.57 | Z31: 26.78 | AA31: 26.06 | AB31: 26.47 | AC31: 27.87 | AD31: 29.33 | AE31: 27.51
A32: International connectivity revenue | B32: 1132 | C32: 1219 | D32: 1275 | E32: 1337 | F32: 4963 | G32: 1240 | H32: 1246 | I32: 1307.89 | J32: 1375.54 | K32: 5169.43 | L32: 1284.12 | M32: 1297.36 | N32: 1364.57 | O32: 1439.77 | P32: 5363.82 | Q32: 1313.69 | R32: 1323.98 | S32: 1398.05 | T32: 1471.61 | U32: 5479.77 | V32: 1345.21 | W32: 1355.86 | X32: 1428.83 | Y32: 1502.49 | Z32: 5619.41 | AA32: 1378.87 | AB32: 1390.26 | AC32: 1465.08 | AD32: 1540.67 | AE32: 5767.35
A34: Business services connectivity customer relationships
A35: Business services connectivity customer relationships(K#) | B35: 2613 | C35: 2713 | D35: 2702 | E35: 2702 | F35: 2702 | G35: 2685.26 | H35: 2687.57 | I35: 2680.75 | J35: 2669.38 | K35: 2669.38 | L35: 2681.99 | M35: 2680.71 | N35: 2672.66 | O35: 2669.36 | P35: 2661.24 | Q35: 2664.08 | R35: 2663.35 | S35: 2653.85 | T35: 2650.08 | U35: 2642.91 | V35: 2655.24 | W35: 2655.26 | X35: 2646.78 | Y35: 2643.75 | Z35: 2631.4 | AA35: 2649.32 | AB35: 2649.92 | AC35: 2642.32 | AD35: 2639.92 | AE35: 2621.06
A36: Avg business services connectivity customer relationships(K#) | B36: 2619.5 | C36: 2663 | D36: 2707.5 | E36: 2702 | F36: 2664 | G36: 2686.98 | H36: 2688.81 | I36: 2682.6 | J36: 2674.88 | K36: 2675.34 | L36: 2680.58 | M36: 2678.51 | N36: 2673.9 | O36: 2671.22 | P36: 2665.13 | Q36: 2662.34 | R36: 2660.62 | S36: 2655.51 | T36: 2652.78 | U36: 2649.38 | V36: 2653.7 | W36: 2652.6 | X36: 2648.33 | Y36: 2646.43 | Z36: 2637.16 | AA36: 2647.89 | AB36: 2647.26 | AC36: 2643.69 | AD36: 2642.51 | AE36: 2626.23
A37: Average monthly business services connectivity revenue per cust relationship($) | B37: 317.62 | C37: 322.32 | D37: 317.14 | E37: 319.52 | F37: 320.23 | G37: 327.49 | H37: 331.47 | I37: 330.19 | J37: 332.14 | K37: 330.94 | L37: 340.27 | M37: 344.59 | N37: 343.77 | O37: 343.9 | P37: 341.87 | Q37: 355.1 | R37: 359.61 | S37: 356.62 | T37: 355.29 | U37: 353.1 | V37: 370.03 | W37: 374.62 | X37: 370.36 | Y37: 368.52 | Z37: 364.97 | AA37: 385.13 | AB37: 389.81 | AC37: 384.25 | AD37: 381.88 | AE37: 376.99
A38: Business services connectivity revenue | B38: 2495.5 | C38: 2575 | D38: 2576 | E38: 2590 | F38: 10237 | G38: 2640 | H38: 2671 | I38: 2650.53 | J38: 2662.95 | K38: 10624.37 | L38: 2723.3 | M38: 2752.07 | N38: 2741.73 | O38: 2755.18 | P38: 10925.54 | Q38: 2815.68 | R38: 2849.16 | S38: 2821.24 | T38: 2830.95 | U38: 11242.7 | V38: 2908.96 | W38: 2943.46 | X38: 2909.77 | Y38: 2917.86 | Z38: 11586.78 | AA38: 3003.03 | AB38: 3038.57 | AC38: 3000.28 | AD38: 3007.2 | AE38: 11913.58
A40: Total domestic broadband customers
A41: Total domestic broadband customers(K#) | B41: 29190 | C41: 28989 | D41: 28897 | E41: 31255 | F41: 31255 | G41: 30472.76 | H41: 30479.01 | I41: 30345.96 | J41: 30189.27 | K41: 30189.1 | L41: 30120.74 | M41: 29978.71 | N41: 29903.28 | O41: 29818.95 | P41: 29705.03 | Q41: 30347.57 | R41: 30229.35 | S41: 30212.03 | T41: 30170.69 | U41: 29220.81 | V41: 30133.03 | W41: 30038.83 | X41: 30056.8 | Y41: 30039.84 | Z41: 28867.52 | AA41: 30014.78 | AB41: 29934.74 | AC41: 29984.98 | AD41: 29990.7 | AE41: 28564.14
A42: Avg total domestic broadband customers(K#) | B42: 31742.5 | C42: 29089.5 | D42: 28943 | E42: 31345 | F42: 31548.5 | G42: 30633.29 | H42: 30566.87 | I42: 30412.53 | J42: 30267.61 | K42: 30589.15 | L42: 30174.61 | M42: 30049.73 | N42: 29941 | O42: 29861.12 | P42: 29928.07 | Q42: 30374.14 | R42: 30288.46 | S42: 30220.69 | T42: 30191.36 | U42: 29421.88 | V42: 30151.86 | W42: 30085.93 | X42: 30047.82 | Y42: 30048.32 | Z42: 29044.16 | AA42: 30027.31 | AB42: 29974.76 | AC42: 29959.86 | AD42: 29987.84 | AE42: 28715.83
A43: Average monthly domestic broadband revenue per customer($) | B43: 70.14 | C43: 70.16 | D43: 69.34 | E43: 68.17 | F43: 69.44 | G43: 67.68 | H43: 68.62 | I43: 68.35 | J43: 68.21 | K43: 68.27 | L43: 68.92 | M43: 68.76 | N43: 68.62 | O43: 68.62 | P43: 68.79 | Q43: 67.9 | R43: 67.8 | S43: 67.61 | T43: 67.47 | U43: 69.61 | V43: 68.63 | W43: 68.68 | X43: 68.47 | Y43: 68.34 | Z43: 70.56 | AA43: 69.58 | AB43: 69.77 | AC43: 69.55 | AD43: 69.43 | AE43: 71.62
A44: Domestic broadband revenue | B44: 6679 | C44: 6649 | D44: 6550 | E44: 6410 | F44: 26288 | G44: 6338 | H44: 6280 | I44: 6221.77 | J44: 6167.32 | K44: 25007.2 | L44: 6197.42 | M44: 6164.08 | N44: 6120.45 | O44: 6084.53 | P44: 24560.83 | Q44: 6143.04 | R44: 6122.2 | S44: 6083.01 | T44: 6046.37 | U44: 24300.69 | V44: 6158.06 | W44: 6148.2 | X44: 6112.78 | Y44: 6081.47 | Z44: 24178.19 | AA44: 6166.36 | AB44: 6161.65 | AC44: 6126.33 | AD44: 6097.19 | AE44: 24076.69
A46: Connectivity & platforms revenue
A47: Residential connectivity and platforms revenue | B47: 17665 | C47: 17839 | D47: 17636 | E47: 17692 | F47: 70832 | G47: 17323 | H47: 17124 | I47: 17027.39 | J47: 17231.02 | K47: 68705.46 | L47: 16888.08 | M47: 16737.75 | N47: 16596.26 | O47: 16779.37 | P47: 67246.49 | Q47: 16692.89 | R47: 16543.72 | S47: 16490.07 | T47: 16733.52 | U47: 66589.14 | V47: 16565.92 | W47: 16427.44 | X47: 16346.04 | Y47: 16562.84 | Z47: 65739.39 | AA47: 16499.37 | AB47: 16378.31 | AC47: 16328.82 | AD47: 16596.95 | AE47: 65484.73
A48: Business services connectivity revenue | B48: 2495.5 | C48: 2575 | D48: 2576 | E48: 2590 | F48: 10237 | G48: 2640 | H48: 2671 | I48: 2650.53 | J48: 2662.95 | K48: 10624.37 | L48: 2723.3 | M48: 2752.07 | N48: 2741.73 | O48: 2755.18 | P48: 10925.54 | Q48: 2815.68 | R48: 2849.16 | S48: 2821.24 | T48: 2830.95 | U48: 11242.7 | V48: 2908.96 | W48: 2943.46 | X48: 2909.77 | Y48: 2917.86 | Z48: 11586.78 | AA48: 3003.03 | AB48: 3038.57 | AC48: 3000.28 | AD48: 3007.2 | AE48: 11913.58
A49: Total connectivity and platforms revenue | B49: 20161 | C49: 20414 | D49: 20212 | E49: 20282 | F49: 81069 | G49: 19962 | H49: 19795 | I49: 19677.91 | J49: 19893.98 | K49: 79329.57 | L49: 19611.38 | M49: 19489.81 | N49: 19338 | O49: 19534.55 | P49: 78171.99 | Q49: 19508.57 | R49: 19392.88 | S49: 19311.31 | T49: 19564.47 | U49: 77831.83 | V49: 19474.87 | W49: 19370.9 | X49: 19255.8 | Y49: 19480.69 | Z49: 77326.17 | AA49: 19502.4 | AB49: 19416.88 | AC49: 19329.09 | AD49: 19604.16 | AE49: 77398.34
...

Sheet SPG C&P Customer Metrics
A2: Comcast Corporation | Connectivity and Platforms - Customer Metrics
A3: NASDAQGS:CMCSA (MI KEY: 4057180; SPCIQ KEY: 173341)
A5: Visible Alpha
A7: Period Type : Fiscal Quarter, Fiscal Halves, Fiscal Year
A8: Period Start : 2025
A9: Period End : 2030
A10: Currency : Reported
A11: Consensus View : Mean
A12: As Of: 10/20/2026
A14: All numbers in $M unless otherwise indicated | B14: FQ1 2025A | C14: FQ2 2025A | D14: FQ3 2025A | E14: FQ4 2025A | F14: FY2025A | G14: FQ1 2026A | H14: FQ2 2026A | I14: FQ3 2026E | J14: FQ4 2026E | K14: FY2026E | L14: FQ1 2027E | M14: FQ2 2027E | N14: FQ3 2027E | O14: FQ4 2027E | P14: FY2027E | Q14: FQ1 2028E | R14: FQ2 2028E | S14: FQ3 2028E | T14: FQ4 2028E | U14: FY2028E | V14: FQ1 2029E | W14: FQ2 2029E | X14: FQ3 2029E | Y14: FQ4 2029E | Z14: FY2029E | AA14: FQ1 2030E | AB14: FQ2 2030E | AC14: FQ3 2030E | AD14: FQ4 2030E | AE14: FY2030E
A15: Number of Contributors Available | B15: 22 | C15: 21 | D15: 21 | E15: 20 | F15: 21 | G15: 21 | H15: 20 | I15: 20 of 20 | J15: 20 of 20 | K15: 20 of 20 | L15: 12 of 20 | M15: 12 of 20 | N15: 11 of 20 | O15: 11 of 20 | P15: 20 of 20 | Q15: 8 of 20 | R15: 8 of 20 | S15: 8 of 20 | T15: 8 of 20 | U15: 19 of 20 | V15: 7 of 20 | W15: 7 of 20 | X15: 7 of 20 | Y15: 7 of 20 | Z15: 16 of 20 | AA15: 7 of 20 | AB15: 7 of 20 | AC15: 7 of 20 | AD15: 7 of 20 | AE15: 16 of 20
A16: Connectivity & platforms: Customer metrics
A18: Homes and businesses passed - net adds(K#) | B18: 236 | C18: 293 | D18: 285 | E18: 344 | F18: 1291 | G18: 229 | H18: 279 | I18: 307.37 | J18: 299.86 | K18: 1162.01 | L18: 286.6 | M18: 283.83 | N18: 286.14 | O18: 281 | P18: 1173.11 | Q18: 251.72 | R18: 299.65 | S18: 302.65 | T18: 311.41 | U18: 1151.37 | V18: 234.66 | W18: 299.19 | X18: 302.77 | Y18: 313.01 | Z18: 1116.99 | AA18: 227.39 | AB18: 301.41 | AC18: 305.06 | AD18: 315.43 | AE18: 1093.76
A19: Homes and businesses passed(K#) | B19: 58063 | C19: 58356 | D19: 58641 | E19: 64983 | F19: 64983 | G19: 59164 | H19: 59443 | I19: 63582.89 | J19: 63882.75 | K19: 64219.22 | L19: 63988.87 | M19: 64272.7 | N19: 64558.84 | O19: 64839.84 | P19: 65315.17 | Q19: 65311.96 | R19: 65611.61 | S19: 65914.26 | T19: 66225.67 | U19: 66344.52 | V19: 66108.15 | W19: 66407.34 | X19: 66710.11 | Y19: 67023.12 | Z19: 67281.01 | AA19: 67250.52 | AB19: 67551.93 | AC19: 67856.98 | AD19: 68172.41 | AE19: 68374.77
A21: Customer relationships
A22: Domestic residential connectivity & platforms customer relationships net additions (losses)(K#) | B22: -203 | C22: -223 | D22: -104 | E22: -203 | F22: -733 | G22: -94 | H22: -166 | I22: -128.61 | J22: -135.25 | K22: -523.86 | L22: -73.33 | M22: -99.92 | N22: -53.97 | O22: -86.34 | P22: -415.99 | Q22: -54.53 | R22: -81.71 | S22: -36.8 | T22: -73.28 | U22: -398.67 | V22: -37.08 | W22: -48.76 | X22: -8.98 | Y22: -41.03 | Z22: -337.34 | AA22: -31.55 | AB22: -38.63 | AC22: -1.61 | AD22: -32.01 | AE22: -288.38
A23: Domestic residential connectivity & platforms customer relationships(K#) | B23: 30969 | C23: 30746 | D23: 30642 | E23: 30439 | F23: 30439 | G23: 30345 | H23: 30179 | I23: 30050.39 | J23: 29915.14 | K23: 29915.14 | L23: 29884.05 | M23: 29784.12 | N23: 29730.16 | O23: 29643.81 | P23: 29502.44 | Q23: 29644.34 | R23: 29562.64 | S23: 29525.84 | T23: 29452.56 | U23: 29081.52 | V23: 29537.99 | W23: 29489.23 | X23: 29480.24 | Y23: 29439.21 | Z23: 28781.6 | AA23: 29407.66 | AB23: 29369.03 | AC23: 29367.43 | AD23: 29335.41 | AE23: 28493.22
A24: International residential connectivity & platforms customer relationships net additions (losses)(K#) | B24: -12 | C24: -101 | D24: -96 | E24: 22 | F24: -187 | G24: 104 | H24: -64 | I24: -60.67 | J24: 23.62 | K24: -7.88 | L24: 38.61 | M24: -51.28 | N24: -43.23 | O24: 20.19 | P24: -30.35 | Q24: 57.21 | R24: -42 | S24: -42.77 | T24: 24.71 | U24: -15.88 | V24: 60.11 | W24: -53.92 | X24: -55.8 | Y24: 23.89 | Z24: -23.44 | AA24: 61.24 | AB24: -53.48 | AC24: -54.84 | AD24: 24.26 | AE24: -18.45
A25: International residential connectivity & platforms customer relationships(K#) | B25: 17674 | C25: 17573 | D25: 17477 | E25: 17499 | F25: 17499 | G25: 17603 | H25: 17539 | I25: 17485.47 | J25: 17507.69 | K25: 17505.89 | L25: 17553.54 | M25: 17506.92 | N25: 17467.62 | O25: 17485.98 | P25: 17483.63 | Q25: 17566.02 | R25: 17529.27 | S25: 17491.85 | T25: 17513.48 | U25: 17473.44 | V25: 17525.64 | W25: 17479.43 | X25: 17431.6 | Y25: 17452.07 | Z25: 17432.49 | AA25: 17504.57 | AB25: 17458.73 | AC25: 17411.72 | AD25: 17432.51 | AE25: 17417.99
A26: Business services connectivity customer relationships net additions (losses)(K#) | B26: -13 | C26: 100 | D26: -11 | E26: 1 | F26: 76 | G26: -4.71 | H26: -18.61 | I26: -5.03 | J26: -19.1 | K26: -18.73 | L26: 2.22 | M26: -0.24 | N26: -7.08 | O26: -10 | P26: -8.88 | Q26: 3.94 | R26: 0.17 | S26: -6.22 | T26: -8.85 | U26: -12.94 | V26: 4.05 | W26: 0.6 | X26: -5.34 | Y26: -7.7 | Z26: -11.51 | AA26: 4.17 | AB26: 1.03 | AC26: -4.44 | AD26: -6.57 | AE26: -10.34
A27: Business services connectivity customer relationships(K#) | B27: 2613 | C27: 2713 | D27: 2702 | E27: 2702 | F27: 2702 | G27: 2685.26 | H27: 2687.57 | I27: 2680.75 | J27: 2669.38 | K27: 2669.38 | L27: 2681.99 | M27: 2680.71 | N27: 2672.66 | O27: 2669.36 | P27: 2661.24 | Q27: 2664.08 | R27: 2663.35 | S27: 2653.85 | T27: 2650.08 | U27: 2642.91 | V27: 2655.24 | W27: 2655.26 | X27: 2646.78 | Y27: 2643.75 | Z27: 2631.4 | AA27: 2649.32 | AB27: 2649.92 | AC27: 2642.32 | AD27: 2639.92 | AE27: 2621.06
A28: Total customer relationships net additions (losses) - Connectivity and platforms(K#) | B28: -228 | C28: -224 | D28: -211 | E28: -181 | F28: -844 | G28: 9 | H28: -230 | I28: -192.58 | J28: -130.35 | K28: -767.73 | L28: -22.04 | M28: -138.45 | N28: -85.46 | O28: -72.23 | P28: -422.13 | Q28: 12.52 | R28: -107.93 | S28: -62.2 | T28: -53.32 | U28: -401.54 | V28: 37.87 | W28: -77.91 | X28: -39.13 | Y28: -9.18 | Z28: -336.04 | AA28: 45.73 | AB28: -64.93 | AC28: -28.92 | AD28: 4.68 | AE28: -271.83
A29: Total customer relationships - Connectivity and platforms(K#) | B29: 51256 | C29: 51032 | D29: 50821 | E29: 50640 | F29: 50640 | G29: 50022.66 | H29: 47718 | I29: 49391.74 | J29: 49270.98 | K29: 49434.17 | L29: 48819.47 | M29: 48668.45 | N29: 48572.21 | O29: 48493.85 | P29: 48752.53 | Q29: 48605.95 | R29: 48486.78 | S29: 48414.52 | T29: 48353.44 | U29: 48206.46 | V29: 48798.8 | W29: 48714.53 | X29: 48669.06 | Y29: 48651.71 | Z29: 48023.33 | AA29: 48714.2 | AB29: 48646.65 | AC29: 48614.58 | AD29: 48612.23 | AE29: 47731.11
A30: Average Total Customer Relationships - Connectivity and Platforms(K#) | B30: 51370 | C30: 51144 | D30: 50926.5 | E30: 50730.5 | F30: 51062 | G30: 50064.87 | H30: 49713.02 | I30: 49362.7 | J30: 49204.56 | K30: 49570.19 | L30: 48854.85 | M30: 48596.17 | N30: 48482.07 | O30: 48404.55 | P30: 49038.41 | Q30: 48429.5 | R30: 48383.1 | S30: 48295.27 | T30: 48237.87 | U30: 48351.68 | V30: 48545.51 | W30: 48526.81 | X30: 48465.07 | Y30: 48437.66 | Z30: 48143.56 | AA30: 48463.28 | AB30: 48454.83 | AC30: 48404.68 | AD30: 48388.15 | AE30: 47839.91
