Workbook
Name IQ_CH: 110000
Name IQ_CQ: 5000
Name IQ_CY: 10000
Name IQ_DAILY: 500000
Name IQ_FH: 100000
Name IQ_FQ: 500
Name IQ_FY: 1000
Name IQ_LTM: 2000
Name IQ_MONTH: 15000
Name IQ_NTM: 6000
Name IQ_WEEK: 50000
Name IQ_YTD: 3000

Sheet 3Q26 First look
A1: EXHIBIT 1: TMUS 3Q26 earnings first look
A3: T-Mobile US — Q3 2026 Earnings First Look
A4: $M (except for as noted) | B4: Q3'25 | C4: Q2'26 | D4: Consensus | E4: Actual 3Q26 | F4: YoY Growth | G4: Beat/Miss
A5: Total Revenue | B5: =Revenue!D38 -> 21957 | C5: =Revenue!H38 -> 22791 | D5: =Revenue!I38 -> 23184.12 | E5: 23584 | F5: =IF(E5="","",E5/B5-1) -> 0.074099376 | G5: =IF(E5="","",E5/D5-1) -> 0.017248013
A6: Service Revenue | B6: =Revenue!D31 -> 18241 | C6: =Revenue!H31 -> 18983 | D6: =Revenue!I31 -> 19311.99 | E6: 19375 | F6: =IF(E6="","",E6/B6-1) -> 0.062167644 | G6: =IF(E6="","",E6/D6-1) -> 0.0032627399
A7: Postpaid revenue | B7: =Revenue!D25 -> 14882 | C7: =Revenue!H25 -> 15853 | D7: =Revenue!I25 -> 16096.01 | E7: 16269 | F7: =IF(E7="","",E7/B7-1) -> 0.093199839 | G7: =IF(E7="","",E7/D7-1) -> 0.010747384
A8: Prepaid revenue | B8: =Revenue!D26 -> 2625 | C8: =Revenue!H26 -> 2473 | D8: =Revenue!I26 -> 2481.39 | E8: 2427 | F8: =IF(E8="","",E8/B8-1) -> -0.075428571 | G8: =IF(E8="","",E8/D8-1) -> -0.021919166
A9: Wholesale and other service revenues | B9: =Revenue!D30 -> 734 | C9: =Revenue!H30 -> 657 | D9: =Revenue!I30 -> 733.62 | E9: 679 | F9: =IF(E9="","",E9/B9-1) -> -0.07493188 | G9: =IF(E9="","",E9/D9-1) -> -0.074452714
A10: Equipment Revenues | B10: =Revenue!D34 -> 3465 | C10: =Revenue!H34 -> 3524 | D10: =Revenue!I34 -> 3607.84 | E10: 3929 | F10: =IF(E10="","",E10/B10-1) -> 0.13391053 | G10: =IF(E10="","",E10/D10-1) -> 0.089017251
A11: Cost of services | B11: ='Income statement'!D21 -> 2873 | C11: ='Income statement'!H21 -> 2978 | D11: ='Income statement'!I21 -> 3131.93 | E11: 3007 | F11: =IF(E11="","",E11/B11-1) -> 0.046641142 | G11: =IF(E11="","",E11/D11-1) -> -0.039889142
A12: Cost of equipment sales | B12: ='Income statement'!D24 -> 4853 | C12: ='Income statement'!H24 -> 5055 | D12: ='Income statement'!I24 -> 5045.7 | E12: 5444 | F12: =IF(E12="","",E12/B12-1) -> 0.12178034 | G12: =IF(E12="","",E12/D12-1) -> 0.078938502
A13: Adj. EBITDA | B13: =EBITDA!D22 -> 8684 | C13: =EBITDA!H22 -> 9537 | D13: =EBITDA!I22 -> 9413.94 | E13: 9620 | F13: =IF(E13="","",E13/B13-1) -> 0.10778443 | G13: =IF(E13="","",E13/D13-1) -> 0.021888816
A14: Adj. EBITDA Margin | B14: =B13/B6 -> 0.47607039 | C14: =C13/C6 -> 0.50239688 | D14: =D13/D6 -> 0.48746608 | E14: =IF(E13="","",E13/E6) -> 0.49651613 | F14: =IF(E14="","",E14-B14) -> 0.020445738 | G14: =IF(E14="","",E14-D14) -> 0.0090500523
A15: Core Adj. EBITDA | B15: =EBITDA!D26 -> 8680 | C15: =EBITDA!H26 -> 9537 | D15: =EBITDA!I26 -> 9409.55 | E15: 9620 | F15: =IF(E15="","",E15/B15-1) -> 0.10829493 | G15: =IF(E15="","",E15/D15-1) -> 0.022365575
A16: Core Adj. EBITDA Margin | B16: =B15/B6 -> 0.4758511 | C16: =C15/C6 -> 0.50239688 | D16: =D15/D6 -> 0.48723876 | E16: =IF(E15="","",E15/E6) -> 0.49651613 | F16: =IF(E16="","",E16-B16) -> 0.020665024 | G16: =IF(E16="","",E16-D16) -> 0.0092773722
A17: CapEx | B17: ='Cash flow'!D25 -> 2639 | C17: ='Cash flow'!H25 -> 2703 | D17: ='Cash flow'!I25 -> 2425.62 | E17: 2270 | F17: =IF(E17="","",E17/B17-1) -> -0.13982569 | G17: =IF(E17="","",E17/D17-1) -> -0.064156793
A18: Adj. Free Cash Flow | B18: ='Cash flow'!D54 -> 4818 | C18: ='Cash flow'!H54 -> 4797 | D18: ='Cash flow'!I54 -> 4859.12 | E18: 5071 | F18: =IF(E18="","",E18/B18-1) -> 0.052511416 | G18: =IF(E18="","",E18/D18-1) -> 0.043604603
A19: Diluted EPS | B19: ='Income statement'!D47 -> 2.41 | C19: ='Income statement'!H47 -> 2.99 | D19: ='Income statement'!I47 -> 2.92 | E19: 3.22 | F19: =IF(E19="","",E19/B19-1) -> 0.33609959 | G19: =IF(E19="","",E19/D19-1) -> 0.10273973
A21: Operational metrics
A22: Postpaid Account Net Adds (in 000') | B22: =Retail!D69 -> 396 | C22: =Retail!H69 -> 277 | D22: =Retail!I69 -> 251.92 | E22: 274 | F22: =IF(E22="","",E22/B22-1) -> -0.30808081 | G22: =IF(E22="","",E22/D22-1) -> 0.087646872
A23: Postpaid ARPA (in $) | B23: =Retail!D63 -> 149.44 | C23: =Retail!H63 -> 152.91 | D23: =Retail!I63 -> 153.96 | E23: 155.73 | F23: =IF(E23="","",E23/B23-1) -> 0.042090471 | G23: =IF(E23="","",E23/D23-1) -> 0.011496493
A24: Postpaid Account Churn | B24: =Retail!D67 -> 0.97% | C24: =Retail!H67 -> 0.99% | D24: =Retail!I67 -> 1.05% | E24: 0.0109 | F24: =IF(E24="","",E24-B24) -> 0.0012 | G24: =IF(E24="","",E24-D24) -> 0.0004
A26: Note: Q3'25, Q2'26 and Consensus link to the Visible Alpha consensus tabs (as of 10/28/26). Enter 3Q26 actuals in the shaded 'Actual 3Q26' column; margins, YoY and Beat/Miss calculate automatically. Margins are on service revenue; margin and churn YoY / Beat-Miss shown as percentage-point differences.
Q32: Key takeaways — TMUS 3Q26
Q33: • Clean beat on all headline lines: Total revenue $23,584M (+7.4% YoY) beat consensus by 1.7%, service revenue $19,375M (+6.2% YoY) beat by 0.3%, Adj. EBITDA $9,620M (+10.8% YoY) beat by 2.2%, and diluted EPS of $3.22 (+33.6% YoY) beat the $2.92 consensus by 10.3%.
Q34: • EPS growth is flattered by an easy comp: 3Q25 included a $208M after-tax ($0.18/sh) capitalized-software impairment. 3Q26 still absorbed $0.09/sh of UScellular merger costs (vs. $0.05 in 3Q25), and diluted shares fell to 1,071.6M from 1,126.6M on ongoing buybacks.
Q35: • Adj. EBITDA margin of 49.7% of service revenue was ~90bp above consensus (48.7%) and +204bp YoY. Management credits higher service and equipment revenues, partly offset by higher equipment and service costs. Cost of services ($3,007M, +4.7% YoY) was 4.0% below consensus despite higher wholesale network access costs, Metronet/Lumos installation-fee amortization, and repair & maintenance.
Q36: • Postpaid service revenue of $16,269M grew 9.3% YoY and beat consensus by 1.1%, driven by more average accounts (including the 3Q25 UScellular and Metronet acquisitions) and higher ARPA. Weak spots: prepaid revenue $2,427M (-7.5% YoY, 2.2% below consensus) and wholesale & other $679M (-7.5% YoY, 7.4% below consensus); the materials give no driver for either.
Q37: • Postpaid ARPA of $155.73 (+4.2% YoY, +1.8% QoQ) beat consensus ($153.96) by 1.1%. Drivers: higher fee revenue (tax- and fee-exclusive plans), rate plan modernization, and more customers per account (5G broadband, T-Mobile for Business), partly offset by heavier promotions and bundled offers.
Q38: • Postpaid net account adds of 274K beat consensus (252K) by 8.8% but fell 31% YoY (396K) and were roughly flat QoQ (277K). Churn of 1.09% was 4bp worse than consensus (1.05%), +12bp YoY and +10bp QoQ. Management blames broadband-only accounts (higher churn), the temporary impact of rate plan modernization, and seasonally higher switching.
Q39: • Equipment revenue of $3,929M (+13.4% YoY) beat consensus by 8.9%, while cost of equipment sales of $5,444M (+12.2% YoY) came in 7.9% above consensus. Both reflect a richer high-end phone mix, higher manufacturer pricing and more device liquidations, partly offset by fewer prepaid devices sold. Net impact on EBITDA was largely neutral.
Q40: • Adj. FCF of $5,071M (+5.3% YoY) beat consensus by 4.4%, helped by CapEx of $2,270M (-14.0% YoY, 6.4% below consensus) on the 'planned timing of capital purchases'. With the FY26 ~$10.0B CapEx guide unchanged, Q4 CapEx should step up to ~$2.4B. Operating cash flow of $7,341M fell 1.6% YoY on working-capital outflows; merger-related payments were $198M (vs. $96M).
Q41: • FY26 guidance raised at the midpoint: Core Adj. EBITDA to $37.35–37.45B (from $37.1–37.5B, +$100M at midpoint); operating cash flow to $28.7–28.8B (from $28.4–28.8B, +$150M); Adj. FCF to $18.7–18.8B (from $18.4–18.8B, +$150M). Effective tax rate cut to 24–25% (from 25–26%). Net adds narrowed to ~1.0M (was 950K–1.05M); CapEx ~$10.0B unchanged.
Q42: • Capital returns: $3.5B returned in 3Q26 ($2.4B buybacks of 13.6M shares and $1.1B dividends), and another $791M repurchased through 10/23. The quarterly dividend was raised 15% to $1.17/sh. Net debt / LTM Core Adj. EBITDA eased to 2.2x (from 2.3x in 2Q26).

Sheet 3Q26 Fill-in Prompt
A1: 3Q26 Earnings Fill-in Prompt — for a Claude / Copilot agent in Excel
A2: How to use: select A5:A54, copy (Ctrl+C), and paste into the agent's chat along with the attached earnings files.
A3: Copy the prompt below ↓
A5: ROLE & GOAL
A6: You are a sell-side equity research analyst covering T-Mobile US (TMUS). T-Mobile has just released its 3Q26 earnings. I have attached the earnings materials (these may include the press release, financial statements, investor factbook / trending schedules, and non-GAAP reconciliations). Your job is to (1) fill in the 3Q26 actuals on the '3Q26 First look' sheet of this workbook, (2) verify the automatic YoY Growth and Beat/Miss calculations, and (3) write a short list of key takeaways. Work quickly, but accuracy comes first — every number must be traceable to the attached documents.
A8: STEP 1 — READ THE MATERIALS
A9: • Read all attached files before writing anything. Find the Q3 2026 column (quarter ended September 30, 2026) in each table. Use the quarterly figures only — not year-to-date, nine-month, or full-year totals.
A10: • If two documents show different values for the same metric, use the financial statements / reconciliation tables over the narrative text, and tell me about the conflict at the end.
A12: STEP 2 — FILL IN COLUMN E ('Actual 3Q26') ON THE '3Q26 First look' SHEET
A13: Enter hardcoded values (not formulas) in these cells only. Units: $ in millions unless noted. Enter costs and CapEx as positive numbers.
A14: • E5 Total Revenue — 'Total revenues' from the income statement
A15: • E6 Service Revenue — 'Total service revenues'
... A54: When you finish, reply with: (a) a confirmation of which cells in column E you filled in; (b) a list of any KPIs you could not find; (c) any data conflicts between documents or anything unusual (e.g., restated prior periods or definition changes); and (d) confirmation that you checked columns F and G.

Sheet Consensus 10-28-26 ->

Sheet Retail
A2: T-Mobile US, Inc. | Retail
A3: NASDAQGS:TMUS (MI KEY: 4091145; SPCIQ KEY: 93339)
A5: Visible Alpha
A7: Period Type : Fiscal Quarter, Fiscal Halves, Fiscal Year
A8: Period Start : 2025
A9: Period End : 2030
A10: Currency : Reported
A11: Consensus View : Mean
A12: As Of: 10/28/2026
A14: All numbers in $M unless otherwise indicated | B14: FQ1 2025A | C14: FQ2 2025A | D14: FQ3 2025A | E14: FQ4 2025A | F14: FY2025A | G14: FQ1 2026A | H14: FQ2 2026A | I14: FQ3 2026E | J14: FQ4 2026E | K14: FY2026E | L14: FQ1 2027E | M14: FQ2 2027E | N14: FQ3 2027E | O14: FQ4 2027E | P14: FY2027E | Q14: FQ1 2028E | R14: FQ2 2028E | S14: FQ3 2028E | T14: FQ4 2028E | U14: FY2028E | V14: FQ1 2029E | W14: FQ2 2029E | X14: FQ3 2029E | Y14: FQ4 2029E | Z14: FY2029E | AA14: FQ1 2030E | AB14: FQ2 2030E | AC14: FQ3 2030E | AD14: FQ4 2030E | AE14: FY2030E
A15: Number of Contributors Available | B15: 20 | C15: 20 | D15: 20 | E15: 20 | F15: 22 | G15: 21 | H15: 21 | I15: 21 of 22 | J15: 21 of 22 | K15: 22 of 22 | L15: 13 of 22 | M15: 13 of 22 | N15: 12 of 22 | O15: 12 of 22 | P15: 22 of 22 | Q15: 6 of 22 | R15: 6 of 22 | S15: 6 of 22 | T15: 6 of 22 | U15: 19 of 22 | V15: 5 of 22 | W15: 5 of 22 | X15: 5 of 22 | Y15: 5 of 22 | Z15: 15 of 22 | AA15: 4 of 22 | AB15: 4 of 22 | AC15: 4 of 22 | AD15: 4 of 22 | AE15: 14 of 22
A16: Phone postpaid
A17: Beginning phone - postpaid subscribers(K#) | B17: 79013 | C17: 79508 | D17: 80338 | E17: 84632 | F17: 79013 | G17: 85594 | H17: 85882.28 | I17: 86535.63 | J17: 87252.4 | K17: 85485.82 | L17: 88143.33 | M17: 88512.62 | N17: 89135.84 | O17: 89811.76 | P17: 88053.8 | Q17: 90439.98 | R17: 90737.08 | S17: 91258.98 | T17: 91894.31 | U17: 90384.87 | V17: 92459.84 | W17: 92693.93 | X17: 93165.3 | Y17: 93739.28 | Z17: 92457.91 | AA17: 94316.88 | AB17: 94536.12 | AC17: 94965.13 | AD17: 95459.31 | AE17: 94397.64
A18: Phone - postpaid gross adds(K#) | B18: 2658.81 | C18: 2987.92 | D18: 3209.35 | E18: 3566.46 | F18: 12422.54 | G18: 2794.57 | H18: 2897.53 | I18: 3083.33 | J18: 3381.73 | K18: 12168.93 | L18: 2802.36 | M18: 2903.16 | N18: 3109.06 | O18: 3390.43 | P18: 12193.18 | Q18: 2830.47 | R18: 2858.25 | S18: 3135.66 | T18: 3400.81 | U18: 12256.73 | V18: 2847.79 | W18: 2874.29 | X18: 3139.84 | Y18: 3428.81 | Z18: 12358.37 | AA18: 2870.67 | AB18: 2869.02 | AC18: 3145.6 | AD18: 3409.1 | AE18: 12415.56
A19: Churn rate - phone postpaid(%) | B19: 0.91% | C19: 0.90% | D19: 0.89% | E19: 1.02% | F19: 0.93% | G19: 0.94% | H19: 0.85% | I19: 0.91% | J19: 0.99% | K19: 0.93% | L19: 0.93% | M19: 0.87% | N19: 0.92% | O19: 0.99% | P19: 0.92% | Q19: 0.93% | R19: 0.87% | S19: 0.92% | T19: 1.00% | U19: 0.92% | V19: 0.94% | W19: 0.88% | X19: 0.93% | Y19: 1.02% | Z19: 0.93% | AA19: 0.94% | AB19: 0.86% | AC19: 0.93% | AD19: 1.01% | AE19: 0.92%
A20: Phone - postpaid disconnects(K#) | B20: 2163.81 | C20: 2157.92 | D20: 2202.35 | E20: 2604.46 | F20: 9128.54 | G20: 2394.47 | H20: 2257.01 | I20: 2376.52 | J20: 2603.04 | K20: 9627.26 | L20: 2460.69 | M20: 2304.26 | N20: 2464.24 | O20: 2675.1 | P20: 9826.75 | Q20: 2533.41 | R20: 2371.61 | S20: 2537.7 | T20: 2776.86 | U20: 10097.61 | V20: 2612.7 | W20: 2443.91 | X20: 2608.86 | Y20: 2873.63 | Z20: 10357.84 | AA20: 2651.43 | AB20: 2440.01 | AC20: 2651.42 | AD20: 2888.62 | AE20: 10501.53
A21: Phone - postpaid internal/ organic net adds(K#) | B21: 495 | C21: 830 | D21: 1007 | E21: 962 | F21: 3294 | G21: 406.03 | H21: 653.35 | I21: 712.79 | J21: 780.14 | K21: 2554.04 | L21: 369.29 | M21: 623.23 | N21: 675.91 | O21: 734.29 | P21: 2341.78 | Q21: 297.1 | R21: 521.91 | S21: 635.32 | T21: 656.46 | U21: 2120.46 | V21: 234.08 | W21: 471.38 | X21: 573.98 | Y21: 592.18 | Z21: 1939.13 | AA21: 219.23 | AB21: 429.01 | AC21: 494.18 | AD21: 520.48 | AE21: 1799.95
A22: Phone - postpaid - Base Adjustments(K#) | B22: - | C22: - | D22: 3287 | E22: - | F22: 3287 | G22: -45.1 | H22: - | I22: 63.59 | J22: - | K22: -4.54 | L22: - | M22: - | N22: - | O22: - | P22: 3.85 | Q22: - | R22: - | S22: - | T22: - | U22: - | V22: - | W22: - | X22: - | Y22: - | Z22: - | AA22: - | AB22: - | AC22: - | AD22: - | AE22: -
A23: Phone - postpaid - Total Change in Subscribers(K#) | B23: 495 | C23: 830 | D23: 4294 | E23: 962 | F23: 6581 | G23: 403.21 | H23: 653.35 | I23: 716.77 | J23: 780.14 | K23: 2567.97 | L23: 369.29 | M23: 623.23 | N23: 675.91 | O23: 734.29 | P23: 2351.31 | Q23: 297.1 | R23: 521.91 | S23: 635.32 | T23: 656.46 | U23: 2144.18 | V23: 234.08 | W23: 471.38 | X23: 573.98 | Y23: 592.18 | Z23: 1939.13 | AA23: 219.23 | AB23: 429.01 | AC23: 494.18 | AD23: 520.48 | AE23: 1799.95
A24: Phone - postpaid subscribers(K#) | B24: 79508 | C24: 80338 | D24: 84632 | E24: 85594 | F24: 85594 | G24: 85882.28 | H24: 86535.63 | I24: 87252.4 | J24: 88032.54 | K24: 88053.8 | L24: 88512.62 | M24: 89135.84 | N24: 89811.76 | O24: 90546.04 | P24: 90405.11 | Q24: 90737.08 | R24: 91258.98 | S24: 91894.31 | T24: 92550.77 | U24: 92529.05 | V24: 92693.93 | W24: 93165.3 | X24: 93739.28 | Y24: 94331.47 | Z24: 94397.04 | AA24: 94536.12 | AB24: 94965.13 | AC24: 95459.31 | AD24: 95979.79 | AE24: 96197.59
A25: Phone - postpaid average subscribers(K#) | B25: 79260.5 | C25: 79923 | D25: 82485 | E25: 85113 | F25: 82303.5 | G25: 85680.67 | H25: 86208.95 | I25: 86894.01 | J25: 87642.47 | K25: 86718.28 | L25: 88327.98 | M25: 88824.23 | N25: 89473.8 | O25: 90178.9 | P25: 89208.32 | Q25: 90588.53 | R25: 90998.03 | S25: 91576.65 | T25: 92222.54 | U25: 91442.67 | V25: 92576.88 | W25: 92929.62 | X25: 93452.29 | Y25: 94035.37 | Z25: 93409.87 | AA25: 94426.5 | AB25: 94750.62 | AC25: 95212.22 | AD25: 95719.55 | AE25: 95278.45
A26: Phone - postpaid ARPU($) | B26: 49.38 | C26: 50.62 | D26: 50.71 | E26: 50.71 | F26: 50.35 | G26: 50.4 | H26: 51.17 | I26: 51.21 | J26: 51.53 | K26: 51.11 | L26: 51.04 | M26: 51.8 | N26: 51.8 | O26: 52.11 | P26: 51.8 | Q26: 51.36 | R26: 52.25 | S26: 52.18 | T26: 52.47 | U26: 52.42 | V26: 51.96 | W26: 52.85 | X26: 52.74 | Y26: 53.1 | Z26: 52.73 | AA26: 51.99 | AB26: 52.78 | AC26: 52.62 | AD26: 53.06 | AE26: 53.03
A27: Phone - postpaid revenue | B27: 11741.65 | C27: 12137.11 | D27: 12548.44 | E27: 12948.24 | F27: 49375.44 | G27: 12965.46 | H27: 13210.99 | I27: 13348.32 | J27: 13544.35 | K27: 53153.76 | L27: 13526.59 | M27: 13802.02 | N27: 13903.09 | O27: 14091.55 | P27: 55423.6 | Q27: 13964.73 | R27: 14270.18 | S27: 14342.04 | T27: 14519.31 | U27: 57484.97 | V27: 14442.14 | W27: 14742.81 | X27: 14797.68 | Y27: 14983.23 | Z27: 59022.21 | AA27: 14746.02 | AB27: 15016.36 | AC27: 15046.88 | AD27: 15245.42 | AE27: 60502.33
A29: Postpaid other
A30: Beginning postpaid other - subscribers(K#) | B30: 25105 | C30: 25947 | D30: 26946 | E30: 29431 | F30: 25105 | G30: 30851 | H30: 31634.01 | I30: 32437.83 | J30: 33400.64 | K30: 30808.19 | L30: 34691.01 | M30: 35479.99 | N30: 36282.04 | O30: 37248.13 | P30: 34412.09 | Q30: 38422.18 | R30: 39147.07 | S30: 39879.31 | T30: 40765.04 | U30: 37741.4 | V30: 42089.45 | W30: 42722.35 | X30: 43366.25 | Y30: 44187.17 | Z30: 41157.03 | AA30: 44958.67 | AB30: 45592.65 | AC30: 46253.18 | AD30: 46982.51 | AE30: 43899.09
A31: Postpaid other - gross adds(K#) | B31: 2014.55 | C31: 2109.52 | D31: 2586.89 | E31: 2804.62 | F31: 9515.57 | G31: 2382.84 | H31: 2358.49 | I31: 2445.83 | J31: 2743.26 | K31: 9930.41 | L31: 2130.86 | M31: 2123.83 | N31: 2234.58 | O31: 2555.1 | P31: 10143.06 | Q31: 2379.92 | R31: 2429.38 | S31: 2523.53 | T31: 2788.53 | U31: 10857.63 | V31: 2407.46 | W31: 2450.11 | X31: 2536.66 | Y31: 2798.91 | Z31: 11187.77 | AA31: 2433.53 | AB31: 2473.76 | AC31: 2556.35 | AD31: 2819.35 | AE31: 11546.16
A32: Churn rate - postpaid other(%) | B32: 1.62% | C32: 1.62% | D32: 1.56% | E32: 1.61% | F32: 1.60% | G32: 1.34% | H32: 1.28% | I32: 1.25% | J32: 1.35% | K32: 1.30% | L32: 1.16% | M32: 1.10% | N32: 1.11% | O32: 1.20% | P32: 1.54% | Q32: 1.26% | R32: 1.32% | S32: 1.32% | T32: 1.32% | U32: 1.62% | V32: 1.23% | W32: 1.29% | X32: 1.28% | Y32: 1.28% | Z32: 1.60% | AA32: 1.20% | AB32: 1.25% | AC32: 1.25% | AD32: 1.25% | AE32: 1.58%
A33: Postpaid other - disconnects(K#) | B33: 1239.79 | C33: 1277.14 | D33: 1291.79 | E33: 1461.94 | F33: 5270.66 | G33: 1252.22 | H33: 1225.13 | I33: 1235.28 | J33: 1377.9 | K33: 5090.53 | L33: 1218.04 | M33: 1186.48 | N33: 1231.76 | O33: 1365.22 | P33: 6720.74 | Q33: 1506.93 | R33: 1609.71 | S33: 1644.8 | T33: 1690.46 | U33: 7742.67 | V33: 1611.9 | W33: 1711.98 | X33: 1742.96 | Y33: 1784.58 | Z33: 8264.5 | AA33: 1698.41 | AB33: 1794.53 | AC33: 1821.55 | AD33: 1859.43 | AE33: 8743.33
A34: Postpaid other internal/ organic net adds(K#) | B34: 842 | C34: 902 | D34: 1340 | E34: 1420 | F34: 4504 | G34: 843.56 | H34: 817.48 | I34: 971.1 | J34: 1082.43 | K34: 3714.58 | L34: 817.1 | M34: 832.18 | N34: 992.22 | O34: 1148.33 | P34: 3446.96 | Q34: 776.39 | R34: 783.45 | S34: 929.4 | T34: 1143.35 | U34: 3159.32 | V34: 703.68 | W34: 711.19 | X34: 885.89 | Y34: 1027.13 | Z34: 2947.12 | AA34: 762.05 | AB34: 782.25 | AC34: 815.24 | AD34: 948.9 | AE34: 2851.18
A35: Postpaid other Base Adjustments(K#) | B35: - | C35: 97 | D35: 1145 | E35: - | F35: 1242 | G35: -16.05 | H35: - | I35: - | J35: - | K35: -16.05 | L35: - | M35: - | N35: - | O35: - | P35: - | Q35: - | R35: - | S35: - | T35: - | U35: - | V35: - | W35: - | X35: - | Y35: - | Z35: - | AA35: - | AB35: - | AC35: - | AD35: - | AE35: -
A36: Postpaid other - Total Change in Subscribers(K#) | B36: 842 | C36: 999 | D36: 2485 | E36: 1420 | F36: 5746 | G36: 828.47 | H36: 805.36 | I36: 964.64 | J36: 1065.69 | K36: 3603.9 | L36: 794.8 | M36: 808.13 | N36: 973.52 | O36: 1107.2 | P36: 3349.47 | Q36: 740.84 | R36: 749.31 | S36: 903.92 | T36: 1074.93 | U36: 3081.49 | V36: 657.33 | W36: 669.6 | X36: 846.87 | Y36: 951.55 | Z36: 2894.46 | AA36: 668.26 | AB36: 695.07 | AC36: 764.13 | AD36: 854.51 | AE36: 2774.03
A37: Postpaid other - subscribers(K#) | B37: 25947 | C37: 26946 | D37: 29431 | E37: 30851 | F37: 30851 | G37: 31634.01 | H37: 32437.83 | I37: 33400.64 | J37: 34463.66 | K37: 34412.09 | L37: 35479.99 | M37: 36282.04 | N37: 37248.13 | O37: 38346.58 | P37: 37761.56 | Q37: 39147.07 | R37: 39879.31 | S37: 40765.04 | T37: 41820.7 | U37: 40822.88 | V37: 42722.35 | W37: 43366.25 | X37: 44187.17 | Y37: 45112.53 | Z37: 44051.49 | AA37: 45592.65 | AB37: 46253.18 | AC37: 46982.51 | AD37: 47801.98 | AE37: 46673.12
A38: Postpaid other - average subscribers(K#) | B38: 25526 | C38: 26446.5 | D38: 28188.5 | E38: 30141 | F38: 27978 | G38: 31220.47 | H38: 32035.92 | I38: 32919.23 | J38: 33932.15 | K38: 32573.12 | L38: 35085.5 | M38: 35881.01 | N38: 36765.08 | O38: 37797.35 | P38: 36054.14 | Q38: 38784.62 | R38: 39513.19 | S38: 40322.17 | T38: 41292.87 | U38: 39256.61 | V38: 42405.9 | W38: 43044.3 | X38: 43776.71 | Y38: 44649.85 | Z38: 42573.02 | AA38: 45275.66 | AB38: 45922.92 | AC38: 46617.84 | AD38: 47392.24 | AE38: 45252.09
A39: Postpaid other - ARPU($) | B39: 24.19 | C39: 24.46 | D39: 27.59 | E39: 26.87 | F39: 25.28 | G39: 27.9 | H39: 27.34 | I39: 28.14 | J39: 27.96 | K39: 27.31 | L39: 28.5 | M39: 28.19 | N39: 29.33 | O39: 29.08 | P39: 28.21 | Q39: 29.61 | R39: 29.18 | S39: 30.72 | T39: 30.07 | U39: 29.12 | V39: 30.71 | W39: 30.48 | X39: 32.36 | Y39: 31.23 | Z39: 30.96 | AA39: 31.8 | AB39: 31.58 | AC39: 33.12 | AD39: 32.05 | AE39: 32.24
A40: Postpaid other - revenue | B40: 1852.35 | C40: 1940.89 | D40: 2333.56 | E40: 2429.76 | F40: 8556.56 | G40: 2626.24 | H40: 2621.72 | I40: 2749.18 | J40: 2825.44 | K40: 10675.47 | L40: 3000.84 | M40: 3011.94 | N40: 3175.7 | O40: 3258.5 | P40: 12226.99 | Q40: 3440.68 | R40: 3418.05 | S40: 3612.08 | T40: 3652.95 | U40: 13760.16 | V40: 3889.42 | W40: 3875.68 | X40: 4105.61 | Y40: 4085.1 | Z40: 15902.68 | AA40: 4320.35 | AB40: 4353.97 | AC40: 4633.18 | AD40: 4557.94 | AE40: 17615.69
A42: Postpaid 5G broadband net adds(K#) | B42: 387 | C42: 427 | D42: 607 | E42: 439 | F42: 1860 | G42: 392.29 | H42: 371.96 | I42: 380.55 | J42: 374.24 | K42: 1519.05 | L42: 333.3 | M42: 325.6 | N42: 334.39 | O42: 331.06 | P42: 1310.33 | Q42: 274.49 | R42: 259.32 | S42: 264.74 | T42: 257.14 | U42: 1095.62 | V42: 219.46 | W42: 201.59 | X42: 208.75 | Y42: 199.58 | Z42: 932.98 | AA42: 177.69 | AB42: 161.06 | AC42: 168.83 | AD42: 160.23 | AE42: 804.75
A43: Postpaid other internal/ organic net adds excl 5G broadband(K#) | B43: 453 | C43: 464.33 | D43: 838 | E43: 939 | F43: 2694.33 | G43: 443.11 | H43: 412.42 | I43: 492.39 | J43: 526.51 | K43: 1874.42 | L43: 345.44 | M43: 362.33 | N43: 448.3 | O43: 459.23 | P43: 1554.75 | Q43: 337.45 | R43: 356.7 | S43: 448.4 | T43: 461.21 | U43: 1503.77 | V43: 334.6 | W43: 356 | X43: 453.39 | Y43: 467.89 | Z43: 1478.2 | AA43: 335.94 | AB43: 359.33 | AC43: 462.46 | AD43: 478.5 | AE43: 1472.61
A44: Postpaid other internal/ organic net adds(K#) | B44: 842 | C44: 902 | D44: 1340 | E44: 1420 | F44: 4504 | G44: 843.56 | H44: 817.48 | I44: 971.1 | J44: 1082.43 | K44: 3714.58 | L44: 817.1 | M44: 832.18 | N44: 992.22 | O44: 1148.33 | P44: 3446.96 | Q44: 776.39 | R44: 783.45 | S44: 929.4 | T44: 1143.35 | U44: 3159.32 | V44: 703.68 | W44: 711.19 | X44: 885.89 | Y44: 1027.13 | Z44: 2947.12 | AA44: 762.05 | AB44: 782.25 | AC44: 815.24 | AD44: 948.9 | AE44: 2851.18
A46: 5G broadband customers(K#) | B46: 6854 | C46: 7308 | D46: 7955 | E46: 8450 | F46: 8450 | G46: 8881.54 | H46: 9294.06 | I46: 9709.79 | J46: 10124.35 | K46: 10112.73 | L46: 10458.22 | M46: 10810.55 | N46: 11170.64 | O46: 11529.6 | P46: 11557.8 | Q46: 11679.62 | R46: 11952.89 | S46: 12232.36 | T46: 12507.65 | U46: 12720.55 | V46: 12757.54 | W46: 12939.63 | X46: 13129.41 | Y46: 13314.35 | Z46: 13600.45 | AA46: 13846.93 | AB46: 14031.98 | AC46: 14227.19 | AD46: 14416.83 | AE46: 14641.42
A47: Postpaid other subscribers excl 5G broadband(K#) | B47: 19093 | C47: 19638 | D47: 21476 | E47: 22401 | F47: 22401 | G47: 22756.62 | H47: 23151.76 | I47: 23710.47 | J47: 24376.99 | K47: 24331.09 | L47: 25021.76 | M47: 25471.48 | N47: 26077.49 | O47: 26816.98 | P47: 26232.56 | Q47: 27467.45 | R47: 27926.42 | S47: 28532.68 | T47: 29313.05 | U47: 28138.54 | V47: 29964.81 | W47: 30426.63 | X47: 31057.76 | Y47: 31798.17 | Z47: 30533.15 | AA47: 31745.72 | AB47: 32221.2 | AC47: 32755.32 | AD47: 33385.14 | AE47: 32116.83
...

Sheet Wholesale
A2: T-Mobile US, Inc. | Wholesale
A3: NASDAQGS:TMUS (MI KEY: 4091145; SPCIQ KEY: 93339)
A5: Visible Alpha
A7: Period Type : Fiscal Quarter, Fiscal Halves, Fiscal Year
A8: Period Start : 2025
A9: Period End : 2030
A10: Currency : Reported
A11: Consensus View : Mean
A12: As Of: 10/28/2026
A14: All numbers in $M unless otherwise indicated | B14: FQ1 2025A | C14: FQ2 2025A | D14: FQ3 2025A | E14: FQ4 2025A | F14: FY2025A | G14: FQ1 2026A | H14: FQ2 2026A | I14: FQ3 2026E | J14: FQ4 2026E | K14: FY2026E | L14: FQ1 2027E | M14: FQ2 2027E | N14: FQ3 2027E | O14: FQ4 2027E | P14: FY2027E | Q14: FQ1 2028E | R14: FQ2 2028E | S14: FQ3 2028E | T14: FQ4 2028E | U14: FY2028E | V14: FQ1 2029E | W14: FQ2 2029E | X14: FQ3 2029E | Y14: FQ4 2029E | Z14: FY2029E | AA14: FQ1 2030E | AB14: FQ2 2030E | AC14: FQ3 2030E | AD14: FQ4 2030E | AE14: FY2030E
A15: Number of Contributors Available | B15: 20 | C15: 20 | D15: 20 | E15: 20 | F15: 22 | G15: 21 | H15: 21 | I15: 21 of 22 | J15: 21 of 22 | K15: 22 of 22 | L15: 13 of 22 | M15: 13 of 22 | N15: 12 of 22 | O15: 12 of 22 | P15: 22 of 22 | Q15: 6 of 22 | R15: 6 of 22 | S15: 6 of 22 | T15: 6 of 22 | U15: 19 of 22 | V15: 5 of 22 | W15: 5 of 22 | X15: 5 of 22 | Y15: 5 of 22 | Z15: 15 of 22 | AA15: 4 of 22 | AB15: 4 of 22 | AC15: 4 of 22 | AD15: 4 of 22 | AE15: 14 of 22
A16: Total wholesale beginning subscribers - Boost(K#) | B16: 19222 | C16: 18472 | D16: 17722 | E16: 16972 | F16: 19222 | G16: 16222 | H16: 15972 | I16: 15722 | J16: 15472 | K16: 16222 | L16: - | M16: - | N16: - | O16: - | P16: 15222 | Q16: - | R16: - | S16: - | T16: - | U16: 14222 | V16: - | W16: - | X16: - | Y16: - | Z16: 14222 | AA16: - | AB16: - | AC16: - | AD16: - | AE16: 14222
A17: Total wholesale gross addition - Boost(K#) | B17: 2359.76 | C17: 2236.01 | D17: 2112.26 | E17: 1988.51 | F17: 8696.52 | G17: 2406.01 | H17: 2364.76 | I17: 2323.51 | J17: 2282.26 | K17: 9376.52 | L17: - | M17: - | N17: - | O17: - | P17: 8716.52 | Q17: - | R17: - | S17: - | T17: - | U17: 9386.52 | V17: - | W17: - | X17: - | Y17: - | Z17: 9386.52 | AA17: - | AB17: - | AC17: - | AD17: - | AE17: 9386.52
A18: Total wholesale net adds - Boost(K#) | B18: -750 | C18: -750 | D18: -750 | E18: -750 | F18: -3000 | G18: -250 | H18: -250 | I18: -250 | J18: -250 | K18: -1000 | L18: - | M18: - | N18: - | O18: - | P18: -1000 | Q18: - | R18: - | S18: - | T18: - | U18: - | V18: - | W18: - | X18: - | Y18: - | Z18: - | AA18: - | AB18: - | AC18: - | AD18: - | AE18: -
A19: Total wholesale subscribers - Boost(K#) | B19: 18472 | C19: 17722 | D19: 16972 | E19: 16222 | F19: 16222 | G19: 15972 | H19: 15722 | I19: 15472 | J19: 15222 | K19: 15222 | L19: - | M19: - | N19: - | O19: - | P19: 14222 | Q19: - | R19: - | S19: - | T19: - | U19: 14222 | V19: - | W19: - | X19: - | Y19: - | Z19: 14222 | AA19: - | AB19: - | AC19: - | AD19: - | AE19: 14222
A20: Total wholesale average subscribers - Boost(K#) | B20: 18847 | C20: 18097 | D20: 17347 | E20: 16597 | F20: 17722 | G20: 16097 | H20: 15847 | I20: 15597 | J20: 15347 | K20: 15722 | L20: - | M20: - | N20: - | O20: - | P20: 14722 | Q20: - | R20: - | S20: - | T20: - | U20: 14222 | V20: - | W20: - | X20: - | Y20: - | Z20: 14222 | AA20: - | AB20: - | AC20: - | AD20: - | AE20: 14222
A21: Total wholesale ARPU - Boost($) | B21: 4.15 | C21: 3.78 | D21: 4.01 | E21: 5.28 | F21: 4.95 | G21: 4.35 | H21: 3.83 | I21: 5.08 | J21: 5.49 | K21: 4.68 | L21: - | M21: - | N21: - | O21: - | P21: 4.91 | Q21: - | R21: - | S21: - | T21: - | U21: 5.16 | V21: - | W21: - | X21: - | Y21: - | Z21: 5.41 | AA21: - | AB21: - | AC21: - | AD21: - | AE21: 5.69
A23: Total wholesale beginning subscribers(K#) | B23: - | C23: - | D23: - | E23: - | F23: - | G23: - | H23: - | I23: - | J23: - | K23: - | L23: - | M23: - | N23: - | O23: - | P23: - | Q23: - | R23: - | S23: - | T23: - | U23: - | V23: - | W23: - | X23: - | Y23: - | Z23: - | AA23: - | AB23: - | AC23: - | AD23: - | AE23: -
A24: Total wholesale gross addition(K#) | B24: - | C24: - | D24: - | E24: - | F24: - | G24: - | H24: - | I24: - | J24: - | K24: - | L24: - | M24: - | N24: - | O24: - | P24: - | Q24: - | R24: - | S24: - | T24: - | U24: - | V24: - | W24: - | X24: - | Y24: - | Z24: - | AA24: - | AB24: - | AC24: - | AD24: - | AE24: -
A25: Total wholesale net adds(K#) | B25: 202.22 | C25: 180.24 | D25: 21.59 | E25: 204.26 | F25: 608.32 | G25: 182 | H25: 162.22 | I25: 19.43 | J25: 183.83 | K25: 547.48 | L25: 182 | M25: 162.22 | N25: 19.43 | O25: 183.83 | P25: 547.48 | Q25: 182 | R25: 162.22 | S25: 19.43 | T25: 183.83 | U25: 547.48 | V25: 182 | W25: 162.22 | X25: 19.43 | Y25: 183.83 | Z25: 547.48 | AA25: 182 | AB25: 162.22 | AC25: 19.43 | AD25: 183.83 | AE25: 547.48
A26: Total wholesale subscribers(K#) | B26: 35051.32 | C26: 35231.57 | D26: 35253.16 | E26: 35457.42 | F26: 35457.42 | G26: 35639.42 | H26: 35801.64 | I26: 35821.07 | J26: 36004.9 | K26: 36004.9 | L26: 36186.9 | M26: 36349.12 | N26: 36368.55 | O26: 36552.39 | P26: 36552.39 | Q26: 36734.39 | R26: 36896.61 | S26: 36916.04 | T26: 37099.87 | U26: 37099.87 | V26: 37281.87 | W26: 37444.09 | X26: 37463.52 | Y26: 37647.35 | Z26: 37647.35 | AA26: 37829.36 | AB26: 37991.57 | AC26: 38011.01 | AD26: 38194.84 | AE26: 38194.84
A27: Total wholesale average subscribers(K#) | B27: 34950.21 | C27: 35141.44 | D27: 35242.36 | E27: 35355.29 | F27: 35248.37 | G27: 35548.42 | H27: 35720.53 | I27: 35811.35 | J27: 35912.98 | K27: 35816.76 | L27: 36095.9 | M27: 36268.01 | N27: 36358.84 | O27: 36460.47 | P27: 36364.24 | Q27: 36643.39 | R27: 36815.5 | S27: 36906.32 | T27: 37007.95 | U27: 36911.73 | V27: 37190.87 | W27: 37362.98 | X27: 37453.81 | Y27: 37555.44 | Z27: 37459.21 | AA27: 37738.35 | AB27: 37910.47 | AC27: 38001.29 | AD27: 38102.92 | AE27: 38006.69
A28: Total wholesale ARPU($) | B28: 2.89 | C28: 2.71 | D28: 2.54 | E28: 2.36 | F28: 2.62 | G28: 2.35 | H28: 2.34 | I28: 2.53 | J28: 2.44 | K28: 2.41 | L28: 2.43 | M28: 2.42 | N28: 2.81 | O28: 3.63 | P28: 2.82 | Q28: 2.59 | R28: 2.57 | S28: 2.99 | T28: 3.87 | U28: 3 | V28: 2.7 | W28: 2.69 | X28: 3.13 | Y28: 4.04 | Z28: 3.13 | AA28: 2.77 | AB28: 2.76 | AC28: 3.2 | AD28: 4.14 | AE28: 3.21
A29: Wholesale revenues | B29: 354.99 | C29: 355.35 | D29: 371.11 | E29: 365.54 | F29: 1446.99 | G29: 337.17 | H29: 311.19 | I29: 363.99 | J29: 388.77 | K29: 1401.13 | L29: 351.05 | M29: 348.73 | N29: 374.01 | O29: 420.77 | P29: 1392.14 | Q29: 365.97 | R29: 363.6 | S29: 390.69 | T29: 441.11 | U29: 1377.43 | V29: 374.5 | W29: 372.13 | X29: 400.63 | Y29: 453.99 | Z29: 1293.51 | AA29: 380.53 | AB29: 378.16 | AC29: 407.65 | AD29: 463.09 | AE29: 1307.89

Sheet Revenue
A2: T-Mobile US, Inc. | Revenue
A3: NASDAQGS:TMUS (MI KEY: 4091145; SPCIQ KEY: 93339)
A5: Visible Alpha
A7: Period Type : Fiscal Quarter, Fiscal Halves, Fiscal Year
A8: Period Start : 2025
A9: Period End : 2030
A10: Currency : Reported
A11: Consensus View : Mean
A12: As Of: 10/28/2026
A14: All numbers in $M unless otherwise indicated | B14: FQ1 2025A | C14: FQ2 2025A | D14: FQ3 2025A | E14: FQ4 2025A | F14: FY2025A | G14: FQ1 2026A | H14: FQ2 2026A | I14: FQ3 2026E | J14: FQ4 2026E | K14: FY2026E | L14: FQ1 2027E | M14: FQ2 2027E | N14: FQ3 2027E | O14: FQ4 2027E | P14: FY2027E | Q14: FQ1 2028E | R14: FQ2 2028E | S14: FQ3 2028E | T14: FQ4 2028E | U14: FY2028E | V14: FQ1 2029E | W14: FQ2 2029E | X14: FQ3 2029E | Y14: FQ4 2029E | Z14: FY2029E | AA14: FQ1 2030E | AB14: FQ2 2030E | AC14: FQ3 2030E | AD14: FQ4 2030E | AE14: FY2030E
A15: Number of Contributors Available | B15: 20 | C15: 20 | D15: 20 | E15: 20 | F15: 22 | G15: 21 | H15: 21 | I15: 21 of 22 | J15: 21 of 22 | K15: 22 of 22 | L15: 13 of 22 | M15: 13 of 22 | N15: 12 of 22 | O15: 12 of 22 | P15: 22 of 22 | Q15: 6 of 22 | R15: 6 of 22 | S15: 6 of 22 | T15: 6 of 22 | U15: 19 of 22 | V15: 5 of 22 | W15: 5 of 22 | X15: 5 of 22 | Y15: 5 of 22 | Z15: 15 of 22 | AA15: 4 of 22 | AB15: 4 of 22 | AC15: 4 of 22 | AD15: 4 of 22 | AE15: 14 of 22
A16: Segments
A17: Phone - postpaid revenue | B17: 11741.65 | C17: 12137.11 | D17: 12548.44 | E17: 12948.24 | F17: 49375.44 | G17: 12965.46 | H17: 13210.99 | I17: 13348.32 | J17: 13544.35 | K17: 53153.76 | L17: 13526.59 | M17: 13802.02 | N17: 13903.09 | O17: 14091.55 | P17: 55423.6 | Q17: 13964.73 | R17: 14270.18 | S17: 14342.04 | T17: 14519.31 | U17: 57484.97 | V17: 14442.14 | W17: 14742.81 | X17: 14797.68 | Y17: 14983.23 | Z17: 59022.21 | AA17: 14746.02 | AB17: 15016.36 | AC17: 15046.88 | AD17: 15245.42 | AE17: 60502.33
A18: Postpaid 5G broadband revenue | B18: 871.7 | C18: 933.26 | D18: 1019.66 | E18: 1091.77 | F18: 3916.39 | G18: 1172.48 | H18: 1224.29 | I18: 1294.77 | J18: 1350.15 | K18: 5041.69 | L18: 1476.98 | M18: 1512.02 | N18: 1578.2 | O18: 1616.54 | P18: 5984.87 | Q18: 1472.45 | R18: 1510.21 | S18: 1582.4 | T18: 1592.43 | U18: 6783.17 | V18: 1635.88 | W18: 1666.5 | X18: 1735.52 | Y18: 1736.86 | Z18: 7516.8 | AA18: 1775.29 | AB18: 1800.25 | AC18: 1866.96 | AD18: 1861.26 | AE18: 8209.64
A19: Prepaid 5G broadband revenue | B19: 102.09 | C19: 106.71 | D19: 111.55 | E19: 118.49 | F19: 438.85 | G19: 126.01 | H19: 131.07 | I19: 135.77 | J19: 140.38 | K19: 533.23 | L19: 146.03 | M19: 149.35 | N19: 152.53 | O19: 155.49 | P19: 599.4 | Q19: 157.73 | R19: 161.56 | S19: 165.17 | T19: 168.57 | U19: 653.12 | V19: 171.76 | W19: 174.75 | X19: 177.57 | Y19: 180.22 | Z19: 702.04 | AA19: 182.71 | AB19: 185.05 | AC19: 187.25 | AD19: 189.32 | AE19: 747.21
A20: 5G broadband revenue | B20: 976.56 | C20: 1045.66 | D20: 1131.45 | E20: 1213.26 | F20: 4388.58 | G20: 1299.35 | H20: 1361.46 | I20: 1424.25 | J20: 1484.65 | K20: 5586.15 | L20: 1601.41 | M20: 1652.45 | N20: 1711.91 | O20: 1760.32 | P20: 6622.18 | Q20: 1736.63 | R20: 1775.09 | S20: 1824.81 | T20: 1854.03 | U20: 7434.29 | V20: 1846.32 | W20: 1878.66 | X20: 1929.87 | Y20: 1947.62 | Z20: 8116.54 | AA20: 1981.24 | AB20: 2004.79 | AC20: 2048.92 | AD20: 2057.23 | AE20: 8762.67
A21: Fiber revenue | B21: 2.05 | C21: 14.2 | D21: 102.89 | E21: 188.27 | F21: 296.2 | G21: 200.78 | H21: 213.26 | I21: 228.43 | J21: 246 | K21: 888.48 | L21: 280.43 | M21: 311.46 | N21: 335.55 | O21: 360.79 | P21: 1282.9 | Q21: 435.09 | R21: 464.71 | S21: 496.34 | T21: 528.94 | U21: 1762.59 | V21: 615.21 | W21: 656.82 | X21: 699.53 | Y21: 743.36 | Z21: 2321.53 | AA21: 803.15 | AB21: 848.26 | AC21: 894.43 | AD21: 941.68 | AE21: 2978.35
A22: Other revenue - Non FWA | B22: 872.29 | C22: 899.55 | D22: 1117.98 | E22: 1118.3 | F22: 4008.13 | G22: 1326.82 | H22: 1173.95 | I22: 1229.03 | J22: 1241.14 | K22: 4970.94 | L22: - | M22: - | N22: - | O22: - | P22: 5359.85 | Q22: - | R22: - | S22: - | T22: - | U22: 5701.97 | V22: - | W22: - | X22: - | Y22: - | Z22: 6017.11 | AA22: - | AB22: - | AC22: - | AD22: - | AE22: 6306.97
A23: Other excl. 5G broadband revenue | B23: 907.3 | C23: 929.52 | D23: 1165.25 | E23: 1205.4 | F23: 4188.53 | G23: 1326.36 | H23: 1267.92 | I23: 1296.9 | J23: 1303.79 | K23: 5180.58 | L23: 1387.81 | M23: 1341.08 | N23: 1440.15 | O23: 1437.29 | P23: 5761.62 | Q23: 1597.63 | R23: 1548.36 | S23: 1675.31 | T23: 1655.88 | U23: 6537.09 | V23: 1847.03 | W23: 1837.62 | X23: 2025.47 | Y23: 1912.44 | Z23: 7491.1 | AA23: 2070.81 | AB23: 2059.37 | AC23: 2260.64 | AD23: 2135.38 | AE23: 8361.48
A24: Postpaid other - revenue | B24: 1852.35 | C24: 1940.89 | D24: 2333.56 | E24: 2429.76 | F24: 8556.56 | G24: 2626.24 | H24: 2621.72 | I24: 2749.18 | J24: 2825.44 | K24: 10675.47 | L24: 3000.84 | M24: 3011.94 | N24: 3175.7 | O24: 3258.5 | P24: 12226.99 | Q24: 3440.68 | R24: 3418.05 | S24: 3612.08 | T24: 3652.95 | U24: 13760.16 | V24: 3889.42 | W24: 3875.68 | X24: 4105.61 | Y24: 4085.1 | Z24: 15902.68 | AA24: 4320.35 | AB24: 4353.97 | AC24: 4633.18 | AD24: 4557.94 | AE24: 17615.69
A25: Postpaid revenues | B25: 13594 | C25: 14078 | D25: 14882 | E25: 15378 | F25: 57932 | G25: 15629 | H25: 15853 | I25: 16096.01 | J25: 16403.48 | K25: 63930.52 | L25: 16596.92 | M25: 16812.97 | N25: 17069.83 | O25: 17340.86 | P25: 67767.9 | Q25: 17487.63 | R25: 17658.59 | S25: 17930.42 | T25: 18169.87 | U25: 71428.58 | V25: 18418.68 | W25: 18566.42 | X25: 18859.26 | Y25: 19051.47 | Z25: 75190.17 | AA25: 19160.79 | AB25: 19282.62 | AC25: 19600.88 | AD25: 19757.8 | AE25: 78549.24
A26: Prepaid revenues | B26: 2643 | C26: 2643 | D26: 2625 | E26: 2586 | F26: 10497 | G26: 2517 | H26: 2473 | I26: 2481.39 | J26: 2482.49 | K26: 9967.21 | L26: 2469.5 | M26: 2443.48 | N26: 2447.14 | O26: 2441.2 | P26: 9886.9 | Q26: 2519.36 | R26: 2476.79 | S26: 2490.96 | T26: 2479.85 | U26: 9914.01 | V26: 2503.4 | W26: 2461.09 | X26: 2452.49 | Y26: 2420.45 | Z26: 9835.13 | AA26: 2427.69 | AB26: 2408.96 | AC26: 2373.86 | AD26: 2338.09 | AE26: 9735.64
A27: Retail service revenue | B27: 16237 | C27: 16721 | D27: 17507 | E27: 17964 | F27: 68429 | G27: 18146 | H27: 18326 | I27: 18577.4 | J27: 18885.98 | K27: 73897.73 | L27: 19066.42 | M27: 19256.45 | N27: 19516.97 | O27: 19782.06 | P27: 77654.8 | Q27: 20006.99 | R27: 20135.38 | S27: 20421.38 | T27: 20649.72 | U27: 81342.59 | V27: 20922.09 | W27: 21027.51 | X27: 21311.75 | Y27: 21471.92 | Z27: 85025.3 | AA27: 21588.47 | AB27: 21691.58 | AC27: 21974.74 | AD27: 22095.89 | AE27: 88284.88
A28: Wholesale revenues | B28: 354.99 | C28: 355.35 | D28: 371.11 | E28: 365.54 | F28: 1446.99 | G28: 337.17 | H28: 311.19 | I28: 363.99 | J28: 388.77 | K28: 1401.13 | L28: 351.05 | M28: 348.73 | N28: 374.01 | O28: 420.77 | P28: 1392.14 | Q28: 365.97 | R28: 363.6 | S28: 390.69 | T28: 441.11 | U28: 1377.43 | V28: 374.5 | W28: 372.13 | X28: 400.63 | Y28: 453.99 | Z28: 1293.51 | AA28: 380.53 | AB28: 378.16 | AC28: 407.65 | AD28: 463.09 | AE28: 1307.89
A29: Roaming and other service revenues | B29: 333.01 | C29: 361.65 | D29: 362.89 | E29: 372.46 | F29: 1430.01 | G29: 347.83 | H29: 345.81 | I29: 385.85 | J29: 414.18 | K29: 1493.67 | L29: 395.68 | M29: 382.02 | N29: 426.89 | O29: 438.6 | P29: 1527.89 | Q29: 403.6 | R29: 389.66 | S29: 435.43 | T29: 447.37 | U29: 1558.02 | V29: 411.67 | W29: 397.45 | X29: 444.14 | Y29: 456.32 | Z29: 1660.91 | AA29: 419.9 | AB29: 405.4 | AC29: 453.02 | AD29: 465.45 | AE29: 1688.48
A30: Wholesale, roaming and other service revenues | B30: 688 | C30: 717 | D30: 734 | E30: 738 | F30: 2877 | G30: 685 | H30: 657 | I30: 733.62 | J30: 781.67 | K30: 2883.41 | L30: 709.84 | M30: 695.14 | N30: 759 | O30: 792.71 | P30: 2960.38 | Q30: 836.44 | R30: 688.15 | S30: 750.06 | T30: 791.61 | U30: 3084.55 | V30: 859.66 | W30: 686.45 | X30: 753.05 | Y30: 782.31 | Z30: 3083.01 | AA30: 953.58 | AB30: 745.61 | AC30: 827.69 | AD30: 864.78 | AE30: 3227.02
A31: Total service revenues | B31: 16925 | C31: 17438 | D31: 18241 | E31: 18702 | F31: 71306 | G31: 18831 | H31: 18983 | I31: 19311.99 | J31: 19665.06 | K31: 76774.73 | L31: 19777.07 | M31: 19950.65 | N31: 20275.97 | O31: 20574.78 | P31: 80614.1 | Q31: 20843.43 | R31: 20823.53 | S31: 21171.44 | T31: 21441.33 | U31: 84422.97 | V31: 21781.74 | W31: 21713.96 | X31: 22064.79 | Y31: 22254.23 | Z31: 88108.33 | AA31: 22542.06 | AB31: 22437.19 | AC31: 22802.42 | AD31: 22960.68 | AE31: 91511.92
A32: Equipment sales | B32: 3703 | C32: 3433 | D32: 3461 | E32: 5362 | F32: 15959 | G32: 3995 | H32: 3524 | I32: 3613.03 | J32: 5415.77 | K32: 16448.98 | L32: 4041 | M32: 3588.16 | N32: 3690.74 | O32: 5569.75 | P32: 16841.98 | Q32: 4227.77 | R32: 3712.17 | S32: 3821.18 | T32: 5757.47 | U32: 17202.1 | V32: 4328.04 | W32: 3789.86 | X32: 3888.98 | Y32: 5891.73 | Z32: 17731.85 | AA32: 4423.45 | AB32: 3862.73 | AC32: 3974.78 | AD32: 6006.9 | AE32: 18094.43
A33: Lease revenues | B33: 1 | C33: 6 | D33: 4 | E33: 2 | F33: 13 | G33: 1 | H33: 11 | I33: 5.58 | J33: 4.94 | K33: 2.3 | L33: 1.9 | M33: 1.88 | N33: 1.86 | O33: 1.85 | P33: 7.52 | Q33: - | R33: - | S33: - | T33: - | U33: 6.73 | V33: - | W33: - | X33: - | Y33: - | Z33: 6.25 | AA33: - | AB33: - | AC33: - | AD33: - | AE33: 5.56
A34: Equipment revenues | B34: 3704 | C34: 3439 | D34: 3465 | E34: 5364 | F34: 15972 | G34: 3996 | H34: 3524 | I34: 3607.84 | J34: 5412.2 | K34: 16497.78 | L34: 4059.07 | M34: 3600.41 | N34: 3699.42 | O34: 5570.28 | P34: 16923.6 | Q34: 4227.77 | R34: 3712.17 | S34: 3821.18 | T34: 5757.47 | U34: 17346.38 | V34: 4328.04 | W34: 3789.86 | X34: 3888.98 | Y34: 5891.73 | Z34: 17732.74 | AA34: 4423.45 | AB34: 3862.73 | AC34: 3974.78 | AD34: 6006.9 | AE34: 18095.29
A35: Other revenues | B35: 257 | C35: 255 | D35: 251 | E35: 268 | F35: 1031 | G35: 280 | H35: 284 | I35: 268.41 | J35: 276.42 | K35: 1105.62 | L35: 289.73 | M35: 294.26 | N35: 277.09 | O35: 290.62 | P35: 1132.6 | Q35: 300.97 | R35: 303.52 | S35: 286.66 | T35: 302.35 | U35: 1166.93 | V35: 306.01 | W35: 310.01 | X35: 287 | Y35: 302.58 | Z35: 1194.11 | AA35: 294.8 | AB35: 299.01 | AC35: 273.3 | AD35: 287.34 | AE35: 1198.86
A36: Equipment sales and other revenue | B36: 3961 | C36: 3694 | D36: 3716 | E36: 5632 | F36: 17003 | G36: 4276 | H36: 3808 | I36: 3876.26 | J36: 5688.61 | K36: 17603.4 | L36: 4348.81 | M36: 3894.67 | N36: 3976.51 | O36: 5860.9 | P36: 18056.2 | Q36: 4528.74 | R36: 4015.69 | S36: 4107.84 | T36: 6059.82 | U36: 18513.31 | V36: 4572.86 | W36: 4037.87 | X36: 4118.58 | Y36: 6133.79 | Z36: 18841.56 | AA36: 4644.55 | AB36: 4086.99 | AC36: 4179.75 | AD36: 6222.41 | AE36: 19201.93
A37: Total wireless revenue | B37: 20886 | C37: 21132 | D37: 21957 | E37: 24334 | F37: 88309 | G37: 23107 | H37: 22791 | I37: 23188.25 | J37: 25353.67 | K37: 94378.13 | L37: 24125.87 | M37: 23845.32 | N37: 24252.48 | O37: 26435.68 | P37: 98670.3 | Q37: 25372.17 | R37: 24839.22 | S37: 25279.28 | T37: 27501.15 | U37: 102936.28 | V37: 26354.6 | W37: 25751.82 | X37: 26183.37 | Y37: 28388.02 | Z37: 106949.89 | AA37: 27186.61 | AB37: 26524.18 | AC37: 26982.17 | AD37: 29183.09 | AE37: 110713.85
A38: Total revenues | B38: 20886 | C38: 21132 | D38: 21957 | E38: 24334 | F38: 88309 | G38: 23107 | H38: 22791 | I38: 23184.12 | J38: 25344.2 | K38: 94367.96 | L38: 24125.87 | M38: 23845.32 | N38: 24252.48 | O38: 26435.68 | P38: 98611.83 | Q38: 25372.17 | R38: 24839.22 | S38: 25279.28 | T38: 27501.15 | U38: 102811.96 | V38: 26354.6 | W38: 25751.82 | X38: 26183.37 | Y38: 28388.02 | Z38: 106733.85 | AA38: 27186.61 | AB38: 26524.18 | AC38: 26982.17 | AD38: 29183.09 | AE38: 110416.98
A40: Equipment revenue
A41: Postpaid revenues | B41: 13594 | C41: 14078 | D41: 14882 | E41: 15378 | F41: 57932 | G41: 15629 | H41: 15853 | I41: 16096.01 | J41: 16403.48 | K41: 63930.52 | L41: 16596.92 | M41: 16812.97 | N41: 17069.83 | O41: 17340.86 | P41: 67767.9 | Q41: 17487.63 | R41: 17658.59 | S41: 17930.42 | T41: 18169.87 | U41: 71428.58 | V41: 18418.68 | W41: 18566.42 | X41: 18859.26 | Y41: 19051.47 | Z41: 75190.17 | AA41: 19160.79 | AB41: 19282.62 | AC41: 19600.88 | AD41: 19757.8 | AE41: 78549.24
A42: EIP Billing | B42: 3551 | C42: 3553 | D42: 3766 | E42: 4066 | F42: 14936 | G42: 4167 | H42: 4132 | I42: 4179.08 | J42: 4214.71 | K42: 16789.62 | L42: 4461.65 | M42: 4611.17 | N42: 4765.71 | O42: 4925.42 | P42: 18116.77 | Q42: - | R42: - | S42: - | T42: - | U42: 19460.43 | V42: - | W42: - | X42: - | Y42: - | Z42: 20940.76 | AA42: - | AB42: - | AC42: - | AD42: - | AE42: 22526.98
A43: Lease revenues | B43: 1 | C43: 6 | D43: 4 | E43: 2 | F43: 13 | G43: 1 | H43: 11 | I43: 5.58 | J43: 4.94 | K43: 2.3 | L43: 1.9 | M43: 1.88 | N43: 1.86 | O43: 1.85 | P43: 7.52 | Q43: - | R43: - | S43: - | T43: - | U43: 6.73 | V43: - | W43: - | X43: - | Y43: - | Z43: 6.25 | AA43: - | AB43: - | AC43: - | AD43: - | AE43: 5.56
A44: EIP Billings & Lease revenue | B44: 3552 | C44: 3559 | D44: 3770 | E44: 4068 | F44: 14949 | G44: 4168 | H44: 4132 | I44: 4180.05 | J44: 4215.67 | K44: 16791.24 | L44: 4463.55 | M44: 4613.06 | N44: 4767.57 | O44: 4927.27 | P44: 13589.45 | Q44: - | R44: - | S44: - | T44: - | U44: 14597.12 | V44: - | W44: - | X44: - | Y44: - | Z44: 20944.22 | AA44: - | AB44: - | AC44: - | AD44: - | AE44: 22530.3
A45: Total Billing | B45: 17146 | C45: 17637 | D45: 18652 | E45: 19446 | F45: 72881 | G45: 19797 | H45: 19985 | I45: 18936.05 | J45: 19291.84 | K45: 76703.5 | L45: 18839.02 | M45: 19184.66 | N45: 19553.52 | O45: 19989.32 | P45: 78912.89 | Q45: - | R45: - | S45: - | T45: - | U45: 83420.8 | V45: - | W45: - | X45: - | Y45: - | Z45: 89612.91 | AA45: - | AB45: - | AC45: - | AD45: - | AE45: 94128.97
...

Sheet Income statement
A2: T-Mobile US, Inc. | Income statement
A3: NASDAQGS:TMUS (MI KEY: 4091145; SPCIQ KEY: 93339)
A5: Visible Alpha
A7: Period Type : Fiscal Quarter, Fiscal Halves, Fiscal Year
A8: Period Start : 2025
A9: Period End : 2030
A10: Currency : Reported
A11: Consensus View : Mean
A12: As Of: 10/28/2026
A14: All numbers in $M unless otherwise indicated | B14: FQ1 2025A | C14: FQ2 2025A | D14: FQ3 2025A | E14: FQ4 2025A | F14: FY2025A | G14: FQ1 2026A | H14: FQ2 2026A | I14: FQ3 2026E | J14: FQ4 2026E | K14: FY2026E | L14: FQ1 2027E | M14: FQ2 2027E | N14: FQ3 2027E | O14: FQ4 2027E | P14: FY2027E | Q14: FQ1 2028E | R14: FQ2 2028E | S14: FQ3 2028E | T14: FQ4 2028E | U14: FY2028E | V14: FQ1 2029E | W14: FQ2 2029E | X14: FQ3 2029E | Y14: FQ4 2029E | Z14: FY2029E | AA14: FQ1 2030E | AB14: FQ2 2030E | AC14: FQ3 2030E | AD14: FQ4 2030E | AE14: FY2030E
A15: Number of Contributors Available | B15: 20 | C15: 20 | D15: 20 | E15: 20 | F15: 22 | G15: 21 | H15: 21 | I15: 21 of 22 | J15: 21 of 22 | K15: 22 of 22 | L15: 13 of 22 | M15: 13 of 22 | N15: 12 of 22 | O15: 12 of 22 | P15: 22 of 22 | Q15: 6 of 22 | R15: 6 of 22 | S15: 6 of 22 | T15: 6 of 22 | U15: 19 of 22 | V15: 5 of 22 | W15: 5 of 22 | X15: 5 of 22 | Y15: 5 of 22 | Z15: 15 of 22 | AA15: 4 of 22 | AB15: 4 of 22 | AC15: 4 of 22 | AD15: 4 of 22 | AE15: 14 of 22
A16: Total revenues | B16: 20886 | C16: 21132 | D16: 21957 | E16: 24334 | F16: 88309 | G16: 23107 | H16: 22791 | I16: 23184.12 | J16: 25344.2 | K16: 94367.96 | L16: 24125.87 | M16: 23845.32 | N16: 24252.48 | O16: 26435.68 | P16: 98611.83 | Q16: 25372.17 | R16: 24839.22 | S16: 25279.28 | T16: 27501.15 | U16: 102811.96 | V16: 26354.6 | W16: 25751.82 | X16: 26183.37 | Y16: 28388.02 | Z16: 106733.85 | AA16: 27186.61 | AB16: 26524.18 | AC16: 26982.17 | AD16: 29183.09 | AE16: 110416.98
A17: Cost of services - excl synergies & CTA | B17: 2582 | C17: 2689 | D17: 2811 | E17: 3031 | F17: 11113 | G17: 2894 | H17: 2865 | I17: 4258.82 | J17: 4463.67 | K17: 16938.99 | L17: 4365.85 | M17: 4253.27 | N17: 4485.24 | O17: 4701.79 | P17: 17806.15 | Q17: 4554.12 | R17: 4577.4 | S17: 4654.29 | T17: 4694.2 | U17: 18544.71 | V17: 4792.06 | W17: 4813.14 | X17: 4896.15 | Y17: 4925.93 | Z17: 19250.96 | AA17: 5043.81 | AB17: 5062.02 | AC17: 5150.06 | AD17: 5170.57 | AE17: 19845.92
A18: Cost of services - Synergies | B18: 20 | C18: 28 | D18: 55 | E18: 250 | F18: 353 | G18: 101 | H18: 69 | I18: -1337.5 | J18: -1375 | K18: -5345 | L18: -1397.5 | M18: -1422.5 | N18: -1450 | O18: -1450 | P18: -5720 | Q18: -1300 | R18: -1300 | S18: -1300 | T18: -1300 | U18: -5720 | V18: -1300 | W18: -1300 | X18: -1300 | Y18: -1300 | Z18: -5695 | AA18: -1300 | AB18: -1300 | AC18: -1300 | AD18: -1300 | AE18: -5670
A19: Cost of services excl. CTA | B19: 2602 | C19: 2717 | D19: 2873 | E19: 3305 | F19: 11497 | G19: 3339 | H19: 2978 | I19: 3068.14 | J19: 3214.48 | K19: 12304.89 | L19: 3088.38 | M19: 3022.66 | N19: 3086.54 | O19: 3175.06 | P19: 12360.35 | Q19: 3161.93 | R19: 3065.91 | S19: 3155.16 | T19: 3279.06 | U19: 12570.37 | V19: 3289.64 | W19: 3156.37 | X19: 3256.75 | Y19: 3388.5 | Z19: 13157.96 | AA19: 3449.75 | AB19: 3271.8 | AC19: 3402.84 | AD19: 3574.9 | AE19: 13634.67
A20: Merger related costs - cost of services | B20: 15.43 | C20: 25.8 | D20: 7 | E20: 24 | F20: 31 | G20: 344 | H20: 44 | I20: 148.91 | J20: 139.1 | K20: 719.42 | L20: 134.49 | M20: 151.09 | N20: 175.03 | O20: 164.82 | P20: 522.14 | Q20: 319.99 | R20: 343.8 | S20: 373.21 | T20: 399.22 | U20: 1436.23 | V20: 431.36 | W20: 459.59 | X20: 494.49 | Y20: 523.56 | Z20: 1909 | AA20: 559.86 | AB20: 590.28 | AC20: 628.54 | AD20: 659.34 | AE20: 2438.03
A21: Cost of services | B21: 2602 | C21: 2717 | D21: 2873 | E21: 3305 | F21: 11497 | G21: 3339 | H21: 2978 | I21: 3131.93 | J21: 3238.72 | K21: 12637.86 | L21: 3127.01 | M21: 3069.24 | N21: 3117.15 | O21: 3195.14 | P21: 12495.32 | Q21: 3163.65 | R21: 3090.57 | S21: 3174.35 | T21: 3284.28 | U21: 12592.4 | V21: 3294.19 | W21: 3196.18 | X21: 3288.41 | Y21: 3401.88 | Z21: 13185.12 | AA21: 3451.77 | AB21: 3328.93 | AC21: 3442.49 | AD21: 3581.49 | AE21: 13672.07
A22: Cost of equipment, excl. merger related costs | B22: 4798 | C22: 4659 | D22: 4851 | E22: 6959 | F22: 21267 | G22: 5466 | H22: 5032 | I22: 5002.26 | J22: 7223.96 | K22: 22737.6 | L22: 5535.22 | M22: 5101.4 | N22: 5195.21 | O22: 7363.88 | P22: 23201.57 | Q22: 5680.75 | R22: 5167.61 | S22: 5293.22 | T22: 7568.63 | U22: 23711.24 | V22: 5874.22 | W22: 5336.68 | X22: 5338.68 | Y22: 7809.82 | Z22: 24146.59 | AA22: 5935.9 | AB22: 5387.9 | AC22: 5387.48 | AD22: 7889.98 | AE22: 24539.25
A23: Merger related costs - cost of equipment sales | B23: - | C23: - | D23: 2 | E23: 8 | F23: 10 | G23: 22 | H23: 23 | I23: 23 | J23: 22.67 | K23: 75.25 | L23: 50 | M23: 50 | N23: - | O23: - | P23: 100 | Q23: - | R23: - | S23: - | T23: - | U23: - | V23: - | W23: - | X23: - | Y23: - | Z23: - | AA23: - | AB23: - | AC23: - | AD23: - | AE23: -
A24: Cost of equipment | B24: 4798 | C24: 4659 | D24: 4853 | E24: 6967 | F24: 21277 | G24: 5488 | H24: 5055 | I24: 5045.7 | J24: 7070.42 | K24: 22601.78 | L24: 5501.48 | M24: 5041.32 | N24: 5156.51 | O24: 7233.86 | P24: 22987.02 | Q24: 5707.99 | R24: 5157.68 | S24: 5312.18 | T24: 7407.3 | U24: 23536.37 | V24: 5860.55 | W24: 5280.35 | X24: 5391.7 | Y24: 7553.87 | Z24: 23849.09 | AA24: 5962.29 | AB24: 5423.43 | AC24: 5497.85 | AD24: 7675.6 | AE24: 24297.3
A25: Total cost of revenue | B25: 7400 | C25: 7376 | D25: 7726 | E25: 10272 | F25: 32774 | G25: 8827 | H25: 8033 | I25: 8172.32 | J25: 10311.61 | K25: 35277.95 | L25: 8628.49 | M25: 8110.57 | N25: 8273.67 | O25: 10429 | P25: 35491.89 | Q25: 8871.64 | R25: 8248.25 | S25: 8486.53 | T25: 10691.58 | U25: 36128.76 | V25: 9154.74 | W25: 8476.53 | X25: 8680.1 | Y25: 10955.75 | Z25: 37034.21 | AA25: 9414.06 | AB25: 8752.36 | AC25: 8940.34 | AD25: 11257.09 | AE25: 37969.37
A26: SG&A - excl synergies & CTA | B26: 5415 | C26: 5415 | D26: 5828 | E26: 6106 | F26: 22764 | G26: 5709 | H26: 5569 | I26: 5989.04 | J26: 6151.73 | K26: 23418.77 | L26: 5947.77 | M26: 5646.75 | N26: 6055.36 | O26: 6092.85 | P26: 23742.73 | Q26: 6109.04 | R26: 5789.11 | S26: 6205.07 | T26: 6235.36 | U26: 24338.56 | V26: 6242.3 | W26: 5905.02 | X26: 6327.87 | Y26: 6352.3 | Z26: 24827.49 | AA26: 6354 | AB26: 6001.16 | AC26: 6430.7 | AD26: 6450.38 | AE26: 25236.24
A27: SG&A - Wireline and other | B27: - | C27: - | D27: - | E27: - | F27: - | G27: - | H27: - | I27: - | J27: - | K27: - | L27: - | M27: - | N27: - | O27: - | P27: - | Q27: - | R27: - | S27: - | T27: - | U27: - | V27: - | W27: - | X27: - | Y27: - | Z27: - | AA27: - | AB27: - | AC27: - | AD27: - | AE27: -
A28: SG&A - Synergies | B28: 59 | C28: -51 | D28: 123 | E28: 353 | F28: 484 | G28: 209 | H28: 150 | I28: -350 | J28: -402.5 | K28: -1328 | L28: -447.5 | M28: -482.5 | N28: -1090 | O28: -1090 | P28: -4140 | Q28: - | R28: - | S28: - | T28: - | U28: -4140 | V28: - | W28: - | X28: - | Y28: - | Z28: -4140 | AA28: - | AB28: - | AC28: - | AD28: - | AE28: -4140
A29: SG&A - excl. merger related cost | B29: 5474 | C29: 5364 | D29: 5951 | E29: 6459 | F29: 23248 | G29: 5918 | H29: 5719 | I29: 5977.54 | J29: 6264.65 | K29: 23771.29 | L29: 5786.74 | M29: 5697.92 | N29: 5940.78 | O29: 6206.12 | P29: 23791.06 | Q29: 5989.08 | R29: 5884.78 | S29: 6086.99 | T29: 6463.9 | U29: 24381.79 | V29: 6222.07 | W29: 6036.14 | X29: 6347.92 | Y29: 6545.28 | Z29: 25005.19 | AA29: 6387.82 | AB29: 6192.65 | AC29: 6512.02 | AD29: 6706.74 | AE29: 25598.76
A30: Merger related costs/(gains) - SG&A | B30: 14 | C30: 33 | D30: 64 | E30: 111 | F30: 222 | G30: 48 | H30: 115 | I30: 142 | J30: 130.62 | K30: 539.67 | L30: 162.5 | M30: 181.25 | N30: 83.33 | O30: 33.33 | P30: 396.4 | Q30: - | R30: - | S30: - | T30: - | U30: - | V30: - | W30: - | X30: - | Y30: - | Z30: - | AA30: - | AB30: - | AC30: - | AD30: - | AE30: -
A31: Selling, general & administrative | B31: 5488 | C31: 5397 | D31: 6015 | E31: 6570 | F31: 23470 | G31: 5966 | H31: 5834 | I31: 6069.95 | J31: 6328.7 | K31: 24222.85 | L31: 5944.65 | M31: 5878 | N31: 6041.81 | O31: 6274.39 | P31: 24326.64 | Q31: 6048.52 | R31: 5910.29 | S31: 6165.94 | T31: 6377.79 | U31: 24817.49 | V31: 6258.78 | W31: 6096.89 | X31: 6382.21 | Y31: 6511.4 | Z31: 25286.91 | AA31: 6296.11 | AB31: 6074.8 | AC31: 6420.52 | AD31: 6565.23 | AE31: 25774.28
A32: Total other adjustments | B32: 79 | C32: -23 | D32: 278 | E32: 121 | F32: 278 | G32: 282 | H32: 156.33 | I32: 250 | J32: 250 | K32: 605 | L32: 250 | M32: 250 | N32: 250 | O32: 250 | P32: 1000 | Q32: - | R32: - | S32: - | T32: - | U32: - | V32: - | W32: - | X32: - | Y32: - | Z32: - | AA32: - | AB32: - | AC32: - | AD32: - | AE32: -
A33: Depreciation and amortization | B33: 3198 | C33: 3146 | D33: 3408 | E33: 3756 | F33: 13508 | G33: 3817 | H33: 3434 | I33: 3577.37 | J33: 3610.24 | K33: 14416.73 | L33: 3567.64 | M33: 3486.46 | N33: 3522.23 | O33: 3535.48 | P33: 14308.28 | Q33: 3528.41 | R33: 3462.92 | S33: 3504.13 | T33: 3512.84 | U33: 14279.96 | V33: 3524.11 | W33: 3443.97 | X33: 3499.6 | Y33: 3512.66 | Z33: 14257.62 | AA33: 3610.93 | AB33: 3479.38 | AC33: 3544.58 | AD33: 3566.1 | AE33: 14453.64
A34: Total cost and expenses | B34: 16086 | C34: 15919 | D34: 17427 | E34: 20598 | F34: 70030 | G34: 18610 | H34: 17301 | I34: 17828.07 | J34: 20250.16 | K34: 73987.98 | L34: 18160.02 | M34: 17494.25 | N34: 17858.54 | O34: 20259.7 | P34: 74148.79 | Q34: 18448.57 | R34: 17621.46 | S34: 18156.6 | T34: 20582.22 | U34: 75166.54 | V34: 18937.63 | W34: 18017.39 | X34: 18561.91 | Y34: 20979.81 | Z34: 76464.99 | AA34: 19321.1 | AB34: 18306.53 | AC34: 18905.44 | AD34: 21388.42 | AE34: 78033.85
A35: Operating income/(loss) | B35: 4800 | C35: 5213 | D35: 4530 | E35: 3736 | F35: 18279 | G35: 4497 | H35: 5490 | I35: 5321.15 | J35: 5062.42 | K35: 20369.03 | L35: 5950.2 | M35: 6302.68 | N35: 6341.46 | O35: 6170.89 | P35: 24319.91 | Q35: 6923.6 | R35: 7217.76 | S35: 7122.68 | T35: 6918.94 | U35: 27659.84 | V35: 7416.97 | W35: 7734.43 | X35: 7621.46 | Y35: 7408.22 | Z35: 30212.48 | AA35: 7865.5 | AB35: 8217.65 | AC35: 8076.74 | AD35: 7794.66 | AE35: 32273.95
A36: Total interest expense | B36: 916 | C36: 922 | D36: 924 | E36: 1012 | F36: 3774 | G36: 1031 | H36: 1055 | I36: 1039.14 | J36: 1037.73 | K36: 4162.87 | L36: 1176.61 | M36: 1184.12 | N36: 1183.57 | O36: 1225.84 | P36: 4604.88 | Q36: 1224.32 | R36: 1231.25 | S36: 1240.89 | T36: 1280.97 | U36: 4874.1 | V36: 1247.17 | W36: 1243.88 | X36: 1229.99 | Y36: 1287.69 | Z36: 5045.5 | AA36: 1272.9 | AB36: 1266.92 | AC36: 1249.64 | AD36: 1229.27 | AE36: 5147.9
A37: Interest income | B37: - | C37: - | D37: - | E37: - | F37: - | G37: - | H37: - | I37: 10.83 | J37: 12.78 | K37: 23.61 | L37: 3 | M37: 4 | N37: 4 | O37: 6 | P37: 42.88 | Q37: - | R37: - | S37: - | T37: - | U37: 43.26 | V37: - | W37: - | X37: - | Y37: - | Z37: 40.26 | AA37: - | AB37: - | AC37: - | AD37: - | AE37: 40.26
A38: Net interest income/(expense) | B38: -916 | C38: -922 | D38: -924 | E38: -1012 | F38: -3774 | G38: -1031 | H38: -1055 | I38: -1047.72 | J38: -1049.89 | K38: -4190.17 | L38: -1167.64 | M38: -1196.97 | N38: -1200.33 | O38: -1227.9 | P38: -4692.74 | Q38: -1258.12 | R38: -1280.18 | S38: -1275.88 | T38: -1296.32 | U38: -4978.46 | V38: -1302.66 | W38: -1315.67 | X38: -1298.96 | Y38: -1327.58 | Z38: -5210.87 | AA38: -1277.3 | AB38: -1287.68 | AC38: -1261.04 | AD38: -1249.63 | AE38: -5263.24
A39: Other expense, net | B39: -46 | C39: -11 | D39: -78 | E39: -89 | F39: -224 | G39: -132 | H39: -107 | I39: -97.29 | J39: -92.78 | K39: -358.43 | L39: -95.2 | M39: -93.75 | N39: -91.44 | O39: -92.58 | P39: -310.44 | Q39: -92.11 | R39: -86.14 | S39: -83.83 | T39: -82.99 | U39: -265.46 | V39: -87.01 | W39: -79.85 | X39: -77.25 | Y39: -76.46 | Z39: -235.31 | AA39: -65.31 | AB39: -56.07 | AC39: -52.89 | AD39: -52.1 | AE39: -167.71
A40: Total Non-operating expense, net | B40: -962 | C40: -933 | D40: -1002 | E40: -1101 | F40: -3998 | G40: -1163 | H40: -1162 | I40: -1129.25 | J40: -1124.47 | K40: -4547.13 | L40: -1245.58 | M40: -1280.15 | N40: -1277.13 | O40: -1308.23 | P40: -4952.83 | Q40: -1334.88 | R40: -1351.96 | S40: -1345.74 | T40: -1365.48 | U40: -5216.48 | V40: -1372.26 | W40: -1379.55 | X40: -1360.77 | Y40: -1388.75 | Z40: -5336.18 | AA40: -1326.29 | AB40: -1329.73 | AC40: -1300.71 | AD40: -1288.71 | AE40: -5289.83
A41: Income/(loss) before income taxes | B41: 3838 | C41: 4280 | D41: 3528 | E41: 2635 | F41: 14281 | G41: 3334 | H41: 4328 | I41: 4194.71 | J41: 3939.92 | K41: 15822.22 | L41: 4684.83 | M41: 5048.49 | N41: 5094.81 | O41: 4844.94 | P41: 19405.83 | Q41: 5588.72 | R41: 5865.8 | S41: 5776.94 | T41: 5553.45 | U41: 22484.84 | V41: 6044.71 | W41: 6354.88 | X41: 6260.7 | Y41: 6019.47 | Z41: 24859.9 | AA41: 6539.22 | AB41: 6887.92 | AC41: 6776.03 | AD41: 6505.95 | AE41: 26950.3
A42: Provision/(benefit) for income taxes | B42: 885 | C42: 1058 | D42: 814 | E42: 532 | F42: 3289 | G42: 830 | H42: 1089 | I42: 1068.02 | J42: 1009.19 | K42: 4024.25 | L42: 1181.5 | M42: 1275.35 | N42: 1288.18 | O42: 1226.72 | P42: 4914.74 | Q42: 1414.51 | R42: 1489.8 | S42: 1467.58 | T42: 1411.09 | U42: 5693.41 | V42: 1514.71 | W42: 1599.9 | X42: 1576.58 | Y42: 1516.23 | Z42: 6266.32 | AA42: 1641.19 | AB42: 1728.64 | AC42: 1701.02 | AD42: 1633.41 | AE42: 6787.9
A43: Income/(loss) from continuing operations | B43: 2953 | C43: 3222 | D43: 2714 | E43: 2103 | F43: 10992 | G43: 2504 | H43: 3239 | I43: 3135.84 | J43: 2945.41 | K43: 11821.78 | L43: 3503.34 | M43: 3773.14 | N43: 3806.63 | O43: 3618.22 | P43: 14554.97 | Q43: 4174.21 | R43: 4376 | S43: 4309.36 | T43: 4142.36 | U43: 16852.21 | V43: 4530 | W43: 4754.99 | X43: 4684.12 | Y43: 4503.24 | Z43: 18688.21 | AA43: 4898.02 | AB43: 5159.29 | AC43: 5075.01 | AD43: 4872.54 | AE43: 20282.1
A44: Income/(loss) from discontinued operations, net of tax | B44: - | C44: - | D44: - | E44: - | F44: - | G44: - | H44: - | I44: - | J44: - | K44: - | L44: - | M44: - | N44: - | O44: - | P44: - | Q44: - | R44: - | S44: - | T44: - | U44: - | V44: - | W44: - | X44: - | Y44: - | Z44: - | AA44: - | AB44: - | AC44: - | AD44: - | AE44: -
...

Sheet Balance sheet
A2: T-Mobile US, Inc. | Balance sheet
A3: NASDAQGS:TMUS (MI KEY: 4091145; SPCIQ KEY: 93339)
A5: Visible Alpha
A7: Period Type : Fiscal Quarter, Fiscal Halves, Fiscal Year
A8: Period Start : 2025
A9: Period End : 2030
A10: Currency : Reported
A11: Consensus View : Mean
A12: As Of: 10/28/2026
A14: All numbers in $M unless otherwise indicated | B14: FQ1 2025A | C14: FQ2 2025A | D14: FQ3 2025A | E14: FQ4 2025A | F14: FY2025A | G14: FQ1 2026A | H14: FQ2 2026A | I14: FQ3 2026E | J14: FQ4 2026E | K14: FY2026E | L14: FQ1 2027E | M14: FQ2 2027E | N14: FQ3 2027E | O14: FQ4 2027E | P14: FY2027E | Q14: FQ1 2028E | R14: FQ2 2028E | S14: FQ3 2028E | T14: FQ4 2028E | U14: FY2028E | V14: FQ1 2029E | W14: FQ2 2029E | X14: FQ3 2029E | Y14: FQ4 2029E | Z14: FY2029E | AA14: FQ1 2030E | AB14: FQ2 2030E | AC14: FQ3 2030E | AD14: FQ4 2030E | AE14: FY2030E
A15: Number of Contributors Available | B15: 20 | C15: 20 | D15: 20 | E15: 20 | F15: 22 | G15: 21 | H15: 21 | I15: 21 of 22 | J15: 21 of 22 | K15: 22 of 22 | L15: 13 of 22 | M15: 13 of 22 | N15: 12 of 22 | O15: 12 of 22 | P15: 22 of 22 | Q15: 6 of 22 | R15: 6 of 22 | S15: 6 of 22 | T15: 6 of 22 | U15: 19 of 22 | V15: 5 of 22 | W15: 5 of 22 | X15: 5 of 22 | Y15: 5 of 22 | Z15: 15 of 22 | AA15: 4 of 22 | AB15: 4 of 22 | AC15: 4 of 22 | AD15: 4 of 22 | AE15: 14 of 22
