Workbook
Name IQ_CH: 110000
Name IQ_CQ: 5000
Name IQ_CY: 10000
Name IQ_DAILY: 500000
Name IQ_FH: 100000
Name IQ_FQ: 500
Name IQ_FY: 1000
Name IQ_LTM: 2000
Name IQ_MONTH: 15000
Name IQ_NTM: 6000
Name IQ_WEEK: 50000
Name IQ_YTD: 3000

Sheet First look
A1: Verizon — Q3 2026 Earnings First Look
A2: $B (except as noted) | B2: Q3'25 | C2: Q2'26 | D2: Consensus 3Q'26 | E2: Actual 3Q'26 | F2: YoY Growth | G2: Beat/Miss
A3: Total Revenue | B3: ='Income statement'!D18/1000 -> 33.821 | C3: ='Income statement'!H18/1000 -> 34.253 | D3: ='Income statement'!I18/1000 -> 34.76799 | E3: 34.313 | F3: =IF(E3="","",E3/B3-1) -> 0.014547175 | G3: =IF(E3="","",E3/D3-1) -> -0.013086463
A4: Consumer Segment | B4: =Segment!D20/1000 -> 26.105 | C4: =Segment!H20/1000 -> 26.242 | D4: =Segment!I20/1000 -> 26.90166 | E4: 26.432 | F4: =IF(E4="","",E4/B4-1) -> 0.012526336 | G4: =IF(E4="","",E4/D4-1) -> -0.017458402
A5: Business Segment | B5: =Segment!D24/1000 -> 6.843 | C5: =Segment!H24/1000 -> 7.155 | D5: =Segment!I24/1000 -> 7.25908 | E5: 7.023 | F5: =IF(E5="","",E5/B5-1) -> 0.026304253 | G5: =IF(E5="","",E5/D5-1) -> -0.032522028
A6: Wireless Equipment | B6: ='Income statement'!D17/1000 -> 5.619 | C6: ='Income statement'!H17/1000 -> 5.024 | D6: ='Income statement'!I17/1000 -> 5.44478 | E6: 5.116 | F6: =IF(E6="","",E6/B6-1) -> -0.089517708 | G6: =IF(E6="","",E6/D6-1) -> -0.060384442
A8: Total Mobility and Broadband Service Rev | B8: =Segment!D29/1000 -> 22.839 | C8: =Segment!H29/1000 -> 23.365 | D8: =Segment!I29/1000 -> 23.53792 | E8: =E9+E10 -> 23.49 | F8: =IF(E8="","",E8/B8-1) -> 0.028503875 | G8: =IF(E8="","",E8/D8-1) -> -0.0020358638
A9: Cons. Mobility and broadband service | B9: =Segment!D17/1000 -> 19.096 | C9: =Segment!H17/1000 -> 19.637 | D9: =Segment!I17/1000 -> 19.77217 | E9: 19.777 | F9: =IF(E9="","",E9/B9-1) -> 0.035661919 | G9: =IF(E9="","",E9/D9-1) -> 0.00024428275
A10: Bus. Mobility and broadband service | B10: =Segment!D21/1000 -> 3.743 | C10: =Segment!H21/1000 -> 3.728 | D10: =Segment!I21/1000 -> 3.77446 | E10: 3.713 | F10: =IF(E10="","",E10/B10-1) -> -0.0080149613 | G10: =IF(E10="","",E10/D10-1) -> -0.016283124
A12: Total Adj. EBITDA | B12: ='Income statement'!D29/1000 -> 12.775 | C12: ='Income statement'!H29/1000 -> 13.723 | D12: ='Income statement'!I29/1000 -> 13.69151 | E12: 13.8 | F12: =IF(E12="","",E12/B12-1) -> 0.080234834 | G12: =IF(E12="","",E12/D12-1) -> 0.0079238886
A13: Consumer Segment | B13: =Segment!D82/1000 -> 11.232 | C13: =Segment!H82/1000 -> 11.819 | D13: =Segment!I82/1000 -> 11.90974 | E13: 11.965 | F13: =IF(E13="","",E13/B13-1) -> 0.065259972 | G13: =IF(E13="","",E13/D13-1) -> 0.0046398998
A14: Business Segment | B14: =Segment!D83/1000 -> 1.718 | C14: =Segment!H83/1000 -> 2.082 | D14: =Segment!I83/1000 -> 1.92104 | E14: 1.941 | F14: =IF(E14="","",E14/B14-1) -> 0.1298021 | G14: =IF(E14="","",E14/D14-1) -> 0.010390205
A15: Total EBITDA Margin | B15: =IF(B12="","",B12/B3) -> 0.3777239 | C15: =IF(C12="","",C12/C3) -> 0.40063644 | D15: =IF(D12="","",D12/D3) -> 0.39379642 | E15: =IF(E12="","",E12/E3) -> 0.40217993 | F15: =IF(E15="","",E15-B15) -> 0.024456032 | G15: =IF(E15="","",E15-D15) -> 0.0083835116
A16: Consumer EBITDA Margin | B16: =IF(B13="","",B13/B4) -> 0.4302624 | C16: =IF(C13="","",C13/C4) -> 0.45038488 | D16: =IF(D13="","",D13/D4) -> 0.44271394 | E16: =IF(E13="","",E13/E4) -> 0.452671 | F16: =IF(E16="","",E16-B16) -> 0.022408603 | G16: =IF(E16="","",E16-D16) -> 0.0099570608
A17: Business EBITDA Margin | B17: =IF(B14="","",B14/B5) -> 0.25105948 | C17: =IF(C14="","",C14/C5) -> 0.29098532 | D17: =IF(D14="","",D14/D5) -> 0.2646396 | E17: =IF(E14="","",E14/E5) -> 0.27637762 | F17: =IF(E17="","",E17-B17) -> 0.02531814 | G17: =IF(E17="","",E17-D17) -> 0.01173802
A18: Adjusted EPS | B18: ='Income statement'!D52 -> 1.21 | C18: ='Income statement'!H52 -> 1.3 | D18: ='Income statement'!I52 -> 1.27 | E18: 1.31 | F18: =IF(E18="","",E18/B18-1) -> 0.082644628 | G18: =IF(E18="","",E18/D18-1) -> 0.031496063
A20: Operational metrics
A21: Total Postpaid Net Adds (in 000') | B21: =Wireless!D21 -> 36 | C21: =Wireless!H21 -> 188 | D21: =Wireless!I21 -> 203.14 | E21: 231 | F21: =IF(E21="","",IF(B21<=0,"n.m",E21/B21-1)) -> 5.4166667 | G21: =IF(E21="","",IF(D21<=0,"n.m",E21/D21-1)) -> 0.1371468
A22: Total Postpaid Phone Net Adds (in 000') | B22: =Consumer!D164+Business!D89 -> 44 | C22: =Consumer!H164+Business!H89 -> 165.36 | D22: =Consumer!I164+Business!I89 -> 186.48 | E22: 406 | F22: =IF(E22="","",IF(B22<=0,"n.m",E22/B22-1)) -> 8.2272727 | G22: =IF(E22="","",IF(D22<=0,"n.m",E22/D22-1)) -> 1.1771772
A23: Total FWA Net Adds (in 000') | B23: =Wireless!D89 -> 261 | C23: =Wireless!H89 -> 193 | D23: =Wireless!I89 -> 194.3 | E23: 159 | F23: =IF(E23="","",IF(B23<=0,"n.m",E23/B23-1)) -> -0.3908046 | G23: =IF(E23="","",IF(D23<=0,"n.m",E23/D23-1)) -> -0.18167782
A24: Fios Internet Net Adds (in 000') | B24: =Wireline!D40 -> 61 | C24: =Wireline!H40 -> 155 | D24: =Wireline!I40 -> 167.68 | E24: 155 | F24: =IF(E24="","",IF(B24<=0,"n.m",E24/B24-1)) -> 1.5409836 | G24: =IF(E24="","",IF(D24<=0,"n.m",E24/D24-1)) -> -0.075620229
A25: Postpaid Phone Churn Rate | B25: =(Consumer!D163+Business!D88)/(Consumer!D168+Business!D93)/3 -> 0.0097880252 | C25: =(Consumer!H163+Business!H88)/(Consumer!H168+Business!H93)/3 -> 0.0091991412 | D25: =(Consumer!I163+Business!I88)/(Consumer!I168+Business!I93)/3 -> 0.0093659504 | E25: 0.0094 | F25: =IF(E25="","",E25/B25-1) -> -0.039642851 | G25: =IF(E25="","",E25/D25-1) -> 0.0036354709
A26: Prepaid Churn Rate | B26: =Wireless!D37 -> 3.73% | C26: =Wireless!H37 -> 3.59% | D26: =Wireless!I37 -> 3.77% | E26: 0.038 | F26: =IF(E26="","",E26/B26-1) -> 0.018766756 | G26: =IF(E26="","",E26/D26-1) -> 0.0079575597
A28: Note: Q3'25, Q2'26 and consensus linked to Visible Alpha consensus tabs (as of 10/25/2026). Enter actuals in column E (yellow); YoY & Beat/Miss populate automatically. Margin YoY/Beat shown as pct-pt change.
K37: 3Q26 Key Takeaways
K38: • Headline: Revenue $34.31B missed consensus by 1.3% (+1.5% YoY). Adj. EBITDA of $13.8B beat by about 0.8% (+8.0% YoY, a company record per mgmt), and adj. EPS of $1.31 beat the $1.27 consensus by 3.1% (+8.3% YoY). GAAP EPS was $1.25 (+6.8%). Adj. EBITDA is disclosed only to $0.1B, so the beat could be anywhere from +0.4% to +1.2%. [VZ 3Q26 PR excerpt; VZ 3Q26 FS p.1]
K39: • Segment EBITDA beat: Consumer $11.97B (+0.5% vs cons, +6.5% YoY) and Business $1.94B (+1.0% vs cons, +13.0% YoY), with combined segment EBITDA of $13.91B vs $13.83B consensus. Segment revenue missed: Consumer -1.7% and Business -3.3% vs cons. [VZ 3Q26 FS p.5-6]
K40: • Postpaid phone net adds of 406K were the biggest surprise: +118% vs 186K consensus and up from 44K in 3Q25. Total postpaid was only 231K (+14% vs cons), which implies about -175K non-phone. Core prepaid was -12K (prepaid phone -52K). The FS gives no explanation, and 3Q26 commentary was not provided. [VZ 3Q26 FS p.7]
K41: • Churn/ARPA: postpaid phone churn was 0.94%, in line with consensus and down 4 bps YoY. Core prepaid churn was 3.80% vs 3.73% YoY. The upgrade rate fell to 2.6% from 3.3%, ARPA fell 1.9% YoY to $168.08 and postpaid accounts were flat at 34.47M. No explanation given. [VZ 3Q26 FS p.7]
K42: • Broadband: FWA net adds of 159K missed by 18% vs 194K consensus and were down 39% YoY. Fiber net adds of 155K were 7.6% below consensus but up 154% YoY. Total broadband net adds were 314K. Fiber connections reached 11.07M (+44% YoY), which includes acquired fiber subs. No explanation given. [VZ 3Q26 FS p.7]
K43: • Equipment revenue was $5.12B: -9.0% YoY and -6.0% vs cons, consistent with the lower upgrade rate. In 2Q, management attributed the equipment decline to lower upgrade volumes and reduced device subsidies [2Q26 PR p.3]; there is no 3Q-specific explanation. Business 'Other' revenue grew 10.0% YoY. [VZ 3Q26 FS p.1, p.6]
K44: • Mobility and broadband service revenue was $23.49B: +2.9% YoY and in line with consensus (-0.2%). Consumer grew 3.6% and Business fell 0.8%. That is roughly in line with 2Q guidance for growth to 'approach 3.0 percent' in 3Q26. [VZ 3Q26 FS p.5-6; 2Q26 PR p.4]
K45: • Margins: Consumer EBITDA margin was 45.3% (+2.2pp YoY, +1.0pp vs cons) and Business was 27.6% (+2.5pp YoY, +1.2pp vs cons). Both match the reported segment margins. In the P&L, cost of equipment fell (Consumer -11.5%) and SG&A fell (-2.9% / -4.8%), partly offset by higher cost of services (+7.4% / +5.3%). No management explanation in the materials. [VZ 3Q26 FS p.5-6]
K46: • Guidance: no 3Q26 guidance update was in the uploaded materials. The last guidance (2Q26) was FY26 M&BB service revenue growth of 2.5-3.0%, adj. EPS of $4.99-5.04, FCF growth of 9-10%, capex of $16.0-16.5B, and postpaid phone net adds in the upper half of 750K-1.0M. Year to date: 645K phone net adds, 9M capex of $11.9B and 9M CFO of $29.9B (+6.8% YoY). [2Q26 PR p.4; VZ 3Q26 FS p.4, p.7]
K47: • Capital allocation/M&A: 9M buybacks were $4.0B (target up to $4.5B) and shares fell to 4,145M from 4,217M. Dividend was $0.7075/qtr. 9M cash paid for acquisitions was $9.48B (acquiree not named in the FS) and goodwill rose $7.9B. Cash fell to $4.5B from $19.0B. Net unsecured debt/adj. EBITDA was 2.3x (2.2x at YE25). [VZ 3Q26 FS p.2-4]
K48: • Recasts/definitions: 1Q26 segment revenue disaggregation was recast. In 2Q26, international wireline/managed network services moved from Business to Corporate & other. The 3Q25 figures in the FS match column B, so B and E are on the same basis. E22 uses reported phone net adds, while B-D use the sum of segment organic figures (2Q26: 165K vs 184K reported). 'Fios Internet' is now reported as 'Fiber broadband'. [VZ 3Q26 FS p.5-7]
K49: • Comparability/one-time items: the FS does not split organic vs. acquired net adds, and operating stats include M&A-related adjustments. Adj. EPS ($1.31) vs GAAP EPS ($1.25) implies about $0.06/share of special items, which are not itemized in the materials provided. D&A rose 10.3% YoY and interest expense rose 17.2% YoY. Implied Corporate & other: revenue about $0.86B and adj. EBITDA about -$0.1B. Still pending: segment phone net adds. [VZ 3Q26 FS p.1, p.7; PR excerpt]

Sheet first look fill instructions
A1: VZ 3Q26 First Look – Prompt for Claude Excel agent (copy cell A3)
A3: ROLE & GOAL You are filling in Verizon's (VZ) 3Q26 earnings "First look" table in this workbook as soon as results are out. I have uploaded the 3Q26 earnings materials (likely the press release, the financial and operating results / supplemental, and the trending schedules). Work fast but put accuracy first. Do not guess any number. STEP 1 – READ THE MATERIALS - Open every uploaded file and figure out which document holds which data. Use the financial and operating results and the trending schedules as the main sources for segment numbers and KPIs. Use the press release for headline numbers and management commentary. - Read the 'First look' sheet before writing anything. Columns B, C and D (Q3'25, Q2'26, Consensus 3Q'26) are formulas linked to the consensus tabs. Do NOT change them. Column E (Actual 3Q'26) is the only input column. Columns F (YoY Growth) and G (Beat/Miss) already contain formulas that fill in automatically once E has values. STEP 2 – FILL COLUMN E (Actual 3Q'26) ON 'First look' Enter reported 3Q26 values as hardcoded numbers in the units shown. Dollar rows are in $ billions (for example, $34,253M becomes 34.253; keep full precision and do not round). Net adds are in thousands. Churn is a decimal (0.92% is entered as 0.0092). - E3 Total Revenue = total operating revenues (consolidated) - E4 Consumer Segment revenue | E5 Business Segment revenue - E6 Wireless Equipment revenue (consolidated) - E8 Total Mobility & broadband service revenue (consolidated) - E9 Consumer mobility & broadband service revenue | E10 Business mobility & broadband service revenue - E12 Total Adjusted EBITDA (consolidated) - E13 Consumer segment EBITDA | E14 Business segment EBITDA - E15:E17 EBITDA margins: these are ALREADY FORMULAS (EBITDA / revenue). Do not overwrite them. Instead, check them against the company's reported segment EBITDA margins and flag any difference. - E18 Adjusted EPS (diluted, adjusted / non-GAAP) - E21 Total postpaid net adds: use the same definition as the source tab (Wireless tab row 21, organic, excluding acquired subscribers) - E22 Total postpaid phone net adds: use Verizon's REPORTED consolidated total (Consumer + Business). Note that C22 is built as Consumer organic + Business organic from the consensus tabs (165K for Q2'26 vs 184K reported). Flag that definitional gap in your summary. - E23 Total FWA net adds (organic) | E24 Fios Internet net adds (organic) - E25 Postpaid phone churn (total retail postpaid phone churn as reported) | E26 Prepaid churn (as reported) Match each line to the same definition the B–D columns use (organic vs. reported, segment vs. consolidated). If Verizon's reported line uses a different definition, use the one closest to ours and flag it. For every value you enter, add a cell note citing the document and the page or table it came from (e.g. "Source: VZ 3Q26 Financial & Operating Info, p.X, Consumer table"). STEP 3 – FORMATTING After filling column E, make it match columns B–D: - Remove the light-yellow input fill (#FFF2CC) from E3:E26. - Keep the grey band fill (#D9D9D9) on rows 3, 12 and 18 so E matches B–D on those rows. - Use blue font (#0000FF) for hardcoded actuals and keep black for the formula cells E15:E17. Keep bold on E3, E12 and E18. - Keep the existing number formats (0.0 for $B, 0.0% for margins, $0.00 for EPS, #,##0 for net adds, 0.00% for churn). - Do not touch the F:G formulas. Check that F3:G26 calculated with no #DIV/0!, #VALUE! or other errors, and that "n.m" shows where the base is zero or negative. STEP 4 – DOUBLE-CHECK (required before you report back) - Re-read E3:G26 and compare each number against the source document a second time. - Check that Consumer + Business + Corporate/other ties to total revenue and total EBITDA within rounding. - Sanity-check against Q2'26 (column C) and consensus (column D). Re-check any metric that is more than ±10% off consensus or more than ±15% off YoY before you accept it. - In chat, tell me which cells you verified. STEP 5 – REPORTING CHANGES / RECASTS (report in chat AND in column K) Tell me clearly if any of the following happened: - A KPI in this table is no longer disclosed, or has been renamed or redefined this quarter (leave that E cell blank, add a note explaining why, and tell me). - Prior-period numbers (e.g. 3Q25 or 2Q26) were RECAST or restated. Say which lines changed, the old vs. new values, and the reason given (segment realignment, acquisition such as Frontier, accounting change, subscriber base adjustment, etc.). If Q3'25 was recast, say whether our column B (consensus-tab actuals) is now on a different basis than column E. - Any new segment, KPI or disclosure appeared. - Any one-time items or adjustments that affect comparability (acquired subscribers, base adjustments, non-GAAP reconciling items). STEP 6 – KEY TAKEAWAYS IN COLUMN K ON 'First look' Read the press release, the CEO/CFO quotes and any commentary in the materials. Write in column K starting at K2: - K2: header "3Q26 Key Takeaways" (same style as the table header: dark blue #1F4E79 fill, white bold font). - K3 onward: one concise bullet per cell (about 8–12 bullets), with wrap text on and column K about 600px wide. Cover: 1. Headline: overall beat/miss on revenue, adj. EBITDA and adj. EPS vs. consensus, with the % from column G. 2. Biggest surprises: any line with a beat or miss of more than about 3% (more than about 10% for net adds and other KPIs) or a large YoY change (from column F). Say what happened and quote or paraphrase management's explanation, citing the document. 3. Subscriber trends: postpaid phone net adds, churn, FWA and Fios. Name the drivers management cited (pricing, promotions, competition, convergence, etc.). 4. Margin and cost story: EBITDA margin expansion or compression and its drivers. 5. Guidance: any change to 2026 guidance (raised, reaffirmed or lowered) and to FCF and capex outlook. 6. Anything else notable: capital allocation, M&A or integration updates, the reporting changes and recasts from Step 5, and one-time items. - If management gave no explanation for a big variance, say "no explanation given". Do not make one up. - Keep each bullet to 1–2 sentences, lead with the number, and cite the source document in brackets. FINAL CHAT REPLY Keep it short: (1) confirm column E was filled and which cells were verified, (2) list any KPIs that were missing, redefined or recast and why, (3) give the top 3 takeaways. Do not paste the whole table into chat.

Sheet Consunesus 10-25-26 ->

Sheet Cash flow
A2: Verizon Communications Inc. | Cash flow
A3: NYSE:VZ (MI KEY: 4057229; SPCIQ KEY: 415798)
A5: Visible Alpha
A7: Period Type : Fiscal Quarter, Fiscal Halves, Fiscal Year
A8: Period Start : 2025
A9: Period End : 2030
A10: Currency : Reported
A11: Consensus View : Mean
A12: As Of: 10/25/2026
A14: All numbers in $M unless otherwise indicated | B14: FQ1 2025A | C14: FQ2 2025A | D14: FQ3 2025A | E14: FQ4 2025A | F14: FY2025A | G14: FQ1 2026A | H14: FQ2 2026A | I14: FQ3 2026E | J14: FQ4 2026E | K14: FY2026E | L14: FQ1 2027E | M14: FQ2 2027E | N14: FQ3 2027E | O14: FQ4 2027E | P14: FY2027E | Q14: FQ1 2028E | R14: FQ2 2028E | S14: FQ3 2028E | T14: FQ4 2028E | U14: FY2028E | V14: FQ1 2029E | W14: FQ2 2029E | X14: FQ3 2029E | Y14: FQ4 2029E | Z14: FY2029E | AA14: FQ1 2030E | AB14: FQ2 2030E | AC14: FQ3 2030E | AD14: FQ4 2030E | AE14: FY2030E
A15: Number of Contributors Available | B15: 19 | C15: 19 | D15: 19 | E15: 19 | F15: 20 | G15: 20 | H15: 20 | I15: 20 of 20 | J15: 20 of 20 | K15: 20 of 20 | L15: 13 of 20 | M15: 13 of 20 | N15: 12 of 20 | O15: 12 of 20 | P15: 20 of 20 | Q15: 7 of 20 | R15: 7 of 20 | S15: 7 of 20 | T15: 7 of 20 | U15: 18 of 20 | V15: 5 of 20 | W15: 5 of 20 | X15: 5 of 20 | Y15: 5 of 20 | Z15: 14 of 20 | AA15: 5 of 20 | AB15: 5 of 20 | AC15: 5 of 20 | AD15: 5 of 20 | AE15: 14 of 20
A16: Net income (CF) | B16: 4983 | C16: 5121 | D16: 5056 | E16: 2448 | F16: 17608 | G16: 5146 | H16: 3949 | I16: 5303.09 | J16: 4752.37 | K16: 19133.86 | L16: 5444.26 | M16: 5415.87 | N16: 5602.89 | O16: 5041.72 | P16: 21494.47 | Q16: 5598.85 | R16: 5676.23 | S16: 5839.72 | T16: 5352.45 | U16: 22534.14 | V16: 5833.63 | W16: 5888.31 | X16: 6030.81 | Y16: 5564.66 | Z16: 23385.22 | AA16: 5984.87 | AB16: 6037.95 | AC16: 6177.96 | AD16: 5716.5 | AE16: 23890.43
A17: Depreciation and amortization | B17: 4577 | C17: 4635 | D17: 4618 | E17: 4519 | F17: 18349 | G17: 4892 | H17: 5008 | I17: 4908.03 | J17: 4917.89 | K17: 19650.53 | L17: 4884.88 | M17: 4903.96 | N17: 4909.15 | O17: 4908.2 | P17: 19719.89 | Q17: 4958.67 | R17: 4989.73 | S17: 4989.71 | T17: 4951.88 | U17: 19926.25 | V17: 5048.85 | W17: 5075.42 | X17: 5078.01 | Y17: 5049.66 | Z17: 20159.83 | AA17: 5079.13 | AB17: 5104.86 | AC17: 5106.84 | AD17: 5076.39 | AE17: 20293.9
A18: Employee retirement benefits | B18: 143 | C18: 188 | D18: 113 | E18: 581 | F18: 1025 | G18: -117 | H18: 152 | I18: -24.16 | J18: -6 | K18: -5.43 | L18: -36.38 | M18: 32.65 | N18: 27.66 | O18: -19.92 | P18: -67.54 | Q18: -51.83 | R18: 54.19 | S18: 23.41 | T18: -49.63 | U18: -79.9 | V18: -12.66 | W18: -12.66 | X18: -12.66 | Y18: -12.66 | Z18: -107.1 | AA18: -9.79 | AB18: -9.79 | AC18: -9.79 | AD18: -9.79 | AE18: -99.45
A19: Deferred income taxes | B19: 132 | C19: -37 | D19: 1714 | E19: 531 | F19: 2340 | G19: 703 | H19: 730 | I19: 555.76 | J19: 299.32 | K19: 2050.32 | L19: 345.17 | M19: 391.07 | N19: 413.37 | O19: 379.04 | P19: 1430.99 | Q19: 229.15 | R19: 370.54 | S19: 354.32 | T19: 324.63 | U19: 1078.24 | V19: 363.45 | W19: 363.8 | X19: 354.02 | Y19: 323.36 | Z19: 969.07 | AA19: 195.41 | AB19: 181.63 | AC19: 193.92 | AD19: 168.03 | AE19: 604.59
A20: Provision for uncollectible accounts | B20: 587 | C20: 548 | D20: 478 | E20: 736 | F20: 2349 | G20: 581 | H20: 462 | I20: 508.27 | J20: 525.25 | K20: 2004.21 | L20: 480.43 | M20: 453.58 | N20: 452.12 | O20: 476.71 | P20: 1969.84 | Q20: 466.44 | R20: 449.79 | S20: 448.3 | T20: 493.96 | U20: 1991.24 | V20: 465.64 | W20: 441.04 | X20: 443.55 | Y20: 499.93 | Z20: 2011.85 | AA20: 465.87 | AB20: 441.24 | AC20: 443.76 | AD20: 500.26 | AE20: 2012.14
A21: Equity in earnings of unconsolidated businesses, net of dividends received | B21: 20 | C21: 9 | D21: 12 | E21: 1 | F21: 42 | G21: 3 | H21: -38 | I21: 8.07 | J21: 3.61 | K21: -29.16 | L21: 3.92 | M21: -13.39 | N21: 8.06 | O21: 3.58 | P21: 2.17 | Q21: 3.87 | R21: -12.16 | S21: 7.87 | T21: 3.78 | U21: 6.13 | V21: 2.67 | W21: -24 | X21: 9.33 | Y21: 2.67 | Z21: -2 | AA21: 2.67 | AB21: -24 | AC21: 9.33 | AD21: 2.67 | AE21: -2
A22: Changes in current assets and liabilities, net of effects from acquisition/disposition of businesses | B22: -2618 | C22: -700 | D22: -736 | E22: 1734 | F22: -2320 | G22: -3082 | H22: -336 | I22: -776.04 | J22: 433.06 | K22: -3638.96 | L22: -1681.47 | M22: -1052.33 | N22: -201.78 | O22: 406.3 | P22: -2866.3 | Q22: -1548.28 | R22: -1373.8 | S22: 198.88 | T22: 648.29 | U22: -2427.72 | V22: -1443.31 | W22: -1589.2 | X22: 240.34 | Y22: 194.93 | Z22: -2517.18 | AA22: -1467.55 | AB22: -1598.96 | AC22: 242.38 | AD22: 148.62 | AE22: -2343.15
A23: Total other operating cash flow | B23: -42 | C23: -789 | D23: 11 | E23: -1436 | F23: -2256 | G23: -142 | H23: 508 | I23: -284.89 | J23: -987.04 | K23: -516.15 | L23: -236.39 | M23: -237.82 | N23: -341.36 | O23: -914.4 | P23: -1029.26 | Q23: -215.43 | R23: -554.2 | S23: -491.68 | T23: -1198.29 | U23: -1264.38 | V23: -427.13 | W23: -555.98 | X23: -560.25 | Y23: -783.38 | Z23: -775.63 | AA23: -317.78 | AB23: -430.89 | AC23: -454.53 | AD23: -706.94 | AE23: -661.63
A24: Net cash provided by/(used in) operating activities | B24: 7782 | C24: 8975 | D24: 11266 | E24: 9114 | F24: 37137 | G24: 7984 | H24: 10435 | I24: 10195.14 | J24: 9843.96 | K24: 38344.56 | L24: 9271.15 | M24: 9801.61 | N24: 10843.04 | O24: 10373.83 | P24: 40128.93 | Q24: 9453.19 | R24: 9614.53 | S24: 11381.22 | T24: 10664.98 | U24: 41155.82 | V24: 9918.03 | W24: 9710.06 | X24: 11694.01 | Y24: 10997.31 | Z24: 42390.26 | AA24: 9997.28 | AB24: 9799.76 | AC24: 11798.99 | AD24: 11038.02 | AE24: 42950.9
A25: Capital expenditures (including capitalized software) | B25: 4145 | C25: 3808 | D25: 4310 | E25: 4748 | F25: 17011 | G25: 4201 | H25: 4009 | I25: 4008.73 | J25: 4142.97 | K25: 16344.13 | L25: 4160.61 | M25: 4114.25 | N25: 4086.13 | O25: 4258.26 | P25: 16665.32 | Q25: 4287.07 | R25: 4168.59 | S25: 4166.07 | T25: 4256.04 | U25: 16949.72 | V25: 4309.76 | W25: 4177.1 | X25: 4153.67 | Y25: 4233.86 | Z25: 17063.41 | AA25: 4316.82 | AB25: 4186.32 | AC25: 4159.72 | AD25: 4239.67 | AE25: 17179.16
A26: Net (acquisitions)/disposals | B26: -122 | C26: -112 | D26: -106 | E26: -110 | F26: -450 | G26: -9563 | H26: -1072 | I26: -2306.69 | J26: -103.6 | K26: -13796.1 | L26: -229.25 | M26: -94 | N26: -6318 | O26: -87.33 | P26: -4508.5 | Q26: -84 | R26: -125 | S26: -5083.33 | T26: -1116.67 | U26: -5268.53 | V26: -150 | W26: -150 | X26: -2575 | Y26: -150 | Z26: -2766.8 | AA26: -150 | AB26: -150 | AC26: -150 | AD26: -2675 | AE26: -2825.36
A27: Other investing cash flow | B27: 515 | C27: 482 | D27: -74 | E27: -122 | F27: 801 | G27: 191 | H27: 154 | I27: -103.18 | J27: -100.09 | K27: 266.82 | L27: -106.22 | M27: -53.84 | N27: -105.36 | O27: -103.87 | P27: -321.84 | Q27: -112.63 | R27: -112.12 | S27: -111.68 | T27: -110.28 | U27: -417.37 | V27: -125.49 | W27: -124.48 | X27: -123.62 | Y27: -120.92 | Z27: -396.34 | AA27: -125.78 | AB27: -124.73 | AC27: -123.88 | AD27: -121.33 | AE27: -363.81
... A39: Free cash flow per share($) | B39: 0.86 | C39: 1.22 | D39: 1.64 | E39: 1.03 | F39: 4.76 | G39: 0.9 | H39: 1.54 | I39: 1.45 | J39: 1.4 | K39: 5.25 | L39: 1.21 | M39: 1.41 | N39: 1.67 | O39: 1.53 | P39: 5.75 | Q39: 1.31 | R39: 1.4 | S39: 1.88 | T39: 1.69 | U39: 6.29 | V39: 1.48 | W39: 1.49 | X39: 2.05 | Y39: 1.87 | Z39: 6.82 | AA39: 1.58 | AB39: 1.58 | AC39: 2.17 | AD39: 1.97 | AE39: 7.28

Sheet Balance sheet
A2: Verizon Communications Inc. | Balance sheet
A3: NYSE:VZ (MI KEY: 4057229; SPCIQ KEY: 415798)
A5: Visible Alpha
A7: Period Type : Fiscal Quarter, Fiscal Halves, Fiscal Year
A8: Period Start : 2025
A9: Period End : 2030
A10: Currency : Reported
A11: Consensus View : Mean
A12: As Of: 10/25/2026
A14: All numbers in $M unless otherwise indicated | B14: FQ1 2025A | C14: FQ2 2025A | D14: FQ3 2025A | E14: FQ4 2025A | F14: FY2025A | G14: FQ1 2026A | H14: FQ2 2026A | I14: FQ3 2026E | J14: FQ4 2026E | K14: FY2026E | L14: FQ1 2027E | M14: FQ2 2027E | N14: FQ3 2027E | O14: FQ4 2027E | P14: FY2027E | Q14: FQ1 2028E | R14: FQ2 2028E | S14: FQ3 2028E | T14: FQ4 2028E | U14: FY2028E | V14: FQ1 2029E | W14: FQ2 2029E | X14: FQ3 2029E | Y14: FQ4 2029E | Z14: FY2029E | AA14: FQ1 2030E | AB14: FQ2 2030E | AC14: FQ3 2030E | AD14: FQ4 2030E | AE14: FY2030E
A15: Number of Contributors Available | B15: 19 | C15: 19 | D15: 19 | E15: 19 | F15: 20 | G15: 20 | H15: 20 | I15: 20 of 20 | J15: 20 of 20 | K15: 20 of 20 | L15: 13 of 20 | M15: 13 of 20 | N15: 12 of 20 | O15: 12 of 20 | P15: 20 of 20 | Q15: 7 of 20 | R15: 7 of 20 | S15: 7 of 20 | T15: 7 of 20 | U15: 18 of 20 | V15: 5 of 20 | W15: 5 of 20 | X15: 5 of 20 | Y15: 5 of 20 | Z15: 14 of 20 | AA15: 5 of 20 | AB15: 5 of 20 | AC15: 5 of 20 | AD15: 5 of 20 | AE15: 14 of 20
A16: Cash and short-term investments | B16: 2257 | C16: 3435 | D16: 7706 | E16: 19048 | F16: 19048 | G16: 8366 | H16: 1752 | I16: 3509.75 | J16: 4829.82 | K16: 5010.65 | L16: 4019.84 | M16: 4027.01 | N16: 3382.77 | O16: 4141.25 | P16: 5279.76 | Q16: 2564.68 | R16: 2861.5 | S16: 2466.91 | T16: 2293.35 | U16: 6842.32 | V16: 2605.05 | W16: 2944.21 | X16: 5147.27 | Y16: 5075.03 | Z16: 12574.3 | AA16: 4439.21 | AB16: 5089.11 | AC16: 7434.46 | AD16: 7375.6 | AE16: 17359.43
A17: Accounts receivable, net of allowances | B17: 25889 | C17: 26275 | D17: 25920 | E17: 27097 | F17: 27097 | G17: 26655 | H17: 26486 | I17: 26976.88 | J17: 28099.76 | K17: 28041.15 | L17: 27288.15 | M17: 27146.94 | N17: 27229.65 | O17: 28664.42 | P17: 28731.44 | Q17: 28068.74 | R17: 28278.55 | S17: 27844.82 | T17: 29234.44 | U17: 29228.04 | V17: 28771.04 | W17: 28749.16 | X17: 28378.19 | Y17: 29838.6 | Z17: 29861.9 | AA17: 29033.1 | AB17: 28932.01 | AC17: 28549.54 | AD17: 30235.33 | AE17: 30247.71
A18: Inventories | B18: 2197 | C18: 2137 | D18: 2700 | E18: 2441 | F18: 2441 | G18: 2320 | H18: 2036 | I18: 2187.13 | J18: 2378.04 | K18: 2385.59 | L18: 2172.48 | M18: 2118.89 | N18: 2269.75 | O18: 2326.08 | P18: 2347.74 | Q18: 2038.31 | R18: 2059.24 | S18: 2083.67 | T18: 2224.92 | U18: 2348.75 | V18: 2036.23 | W18: 2003.99 | X18: 2012.72 | Y18: 2141.97 | Z18: 2359.38 | AA18: 2128.5 | AB18: 2094.09 | AC18: 2095.27 | AD18: 2241.28 | AE18: 2392.72
A19: Prepaid expenses and other current assets | B19: 7010 | C19: 6999 | D19: 7684 | E19: 8336 | F19: 8336 | G19: 7382 | H19: 7297 | I19: 7655.39 | J19: 8016.61 | K19: 8051.03 | L19: 8230.66 | M19: 8396.94 | N19: 8687.86 | O19: 9041.24 | P19: 8892.43 | Q19: 9128.67 | R19: 9316.49 | S19: 9475.03 | T19: 9869.24 | U19: 9363.19 | V19: 10584.86 | W19: 10829.66 | X19: 11040.57 | Y19: 11479.53 | Z19: 10304.15 | AA19: 10937.53 | AB19: 11106.71 | AC19: 11255.14 | AD19: 11764.67 | AE19: 10833.38
A20: Total current assets | B20: 37353 | C20: 38846 | D20: 44010 | E20: 56922 | F20: 56922 | G20: 44723 | H20: 37571 | I20: 40778.74 | J20: 43742.94 | K20: 43879.85 | L20: 41293.94 | M20: 40550.04 | N20: 40941.99 | O20: 43312.23 | P20: 45440.64 | Q20: 40965.78 | R20: 40969.58 | S20: 40695 | T20: 41801.81 | U20: 48247.41 | V20: 41108.06 | W20: 40893.78 | X20: 42937.98 | Y20: 43956.09 | Z20: 55007.19 | AA20: 42794.83 | AB20: 42850.29 | AC20: 44793.32 | AD20: 46211.93 | AE20: 59129.12
A21: Plant, property and equipment, gross | B21: 331888 | C21: 332529 | D21: 334765 | E21: 337991 | F21: 337991 | G21: 357650 | H21: 357086 | I21: 360802.25 | J21: 364017.27 | K21: 363758.22 | L21: 367574.51 | M21: 370539.54 | N21: 374169.93 | O21: 377343.86 | P21: 378519.22 | Q21: 382168.14 | R21: 385733 | S21: 389283.65 | T21: 392895.77 | U21: 394884.55 | V21: 393589.56 | W21: 396914.3 | X21: 400163.54 | Y21: 403403.99 | Z21: 409726.21 | AA21: 406990.09 | AB21: 410336.52 | AC21: 413605.65 | AD21: 416862.69 | AE21: 425470.25
A22: Accumulated depreciation | B22: 223965 | C22: 224460 | D22: 226298 | E22: 228524 | F22: 228524 | G22: 231678 | H22: 231589 | I22: 232545.54 | J22: 235738.67 | K22: 236658.09 | L22: 235945.26 | M22: 238652.59 | N22: 241338.09 | O22: 244119.83 | P22: 250503.71 | Q22: 252186.08 | R22: 255235.45 | S22: 258217.25 | T22: 261182.88 | U22: 269732.89 | V22: 274985.98 | W22: 279111.69 | X22: 283131.46 | Y22: 287137.81 | Z22: 291737.81 | AA22: 291300.38 | AB22: 295496.63 | AC22: 299583.97 | AD22: 303655.15 | AE22: 309288.59
A23: Plant, property and equipment, net | B23: 107923 | C23: 108069 | D23: 108467 | E23: 109467 | F23: 109467 | G23: 125972 | H23: 125497 | I23: 125354.72 | J23: 124953.21 | K23: 124498.16 | L23: 127187.82 | M23: 126912.38 | N23: 126973.46 | O23: 126798.17 | P23: 123740.31 | Q23: 124995.8 | R23: 124915.49 | S23: 124870.83 | T23: 124945.68 | U23: 120673.66 | V23: 117760.41 | W23: 116996.62 | X23: 116258.33 | Y23: 115632.04 | Z23: 115981.85 | AA23: 115653.75 | AB23: 114930.25 | AC23: 114231.88 | AD23: 113628.47 | AE23: 114448.48
A24: Investments in unconsolidated businesses | B24: 820 | C24: 807 | D24: 799 | E24: 785 | F24: 785 | G24: 730 | H24: 783 | I24: 779.67 | J24: 780.79 | K24: 781.05 | L24: 777.2 | M24: 781.59 | N24: 781.33 | O24: 781.79 | P24: 825.25 | Q24: 781.99 | R24: 789.85 | S24: 789.24 | T24: 790.05 | U24: 837.19 | V24: 793.25 | W24: 804.25 | X24: 802.75 | Y24: 803.5 | Z24: 851.81 | AA24: 800.4 | AB24: 809.2 | AC24: 808 | AD24: 808.6 | AE24: 852.1
A25: Operating lease assets | B25: 24175 | C25: 23949 | D25: 23760 | E25: 23498 | F25: 23498 | G25: 23401 | H25: 23158 | I25: 23133.01 | J25: 23226.83 | K25: 23302.38 | L25: 23104.87 | M25: 23104.42 | N25: 23148.93 | O25: 23257.27 | P25: 23405.19 | Q25: 23073.01 | R25: 23096.19 | S25: 23166.91 | T25: 23360.03 | U25: 23631.6 | V25: 23158 | W25: 23158 | X25: 23158 | Y25: 23158 | Z25: 23741.33 | AA25: 23158 | AB25: 23158 | AC25: 23158 | AD25: 23158 | AE25: 23756.72
A26: Other noncurrent assets | B26: 19678 | C26: 21318 | D26: 21012 | E26: 23248 | F26: 23248 | G26: 22547 | H26: 22037 | I26: 22402.22 | J26: 23555.11 | K26: 23594.14 | L26: 24556.73 | M26: 25387.62 | N26: 26098.37 | O26: 27073.47 | P26: 25825.21 | Q26: 21064.66 | R26: 21264.71 | S26: 21090.18 | T26: 21058.18 | U26: 21976.05 | V26: 19308.33 | W26: 19067.67 | X26: 18810.33 | Y26: 18556.67 | Z26: 21247.98 | AA26: 18160.22 | AB26: 17755.33 | AC26: 17357.72 | AD26: 17022.91 | AE26: 20770.94
A27: Total other noncurrent & operating lease assets | B27: 43853 | C27: 45267 | D27: 44772 | E27: 46746 | F27: 46746 | G27: 45948 | H27: 45195 | I27: 45597.43 | J27: 46642.98 | K27: 46728.63 | L27: 47269.47 | M27: 47910.67 | N27: 48601.29 | O27: 49830.44 | P27: 48400.85 | Q27: 44349.14 | R27: 44527.72 | S27: 44444.67 | T27: 44573.57 | U27: 45615.22 | V27: 43148.5 | W27: 42968 | X27: 42775 | Y27: 42584.75 | Z27: 45164.79 | AA27: 43341.82 | AB27: 42960.89 | AC27: 42610.44 | AD27: 43218.41 | AE27: 45224.82
... A57: Total liabilities and equity | B57: 380364 | C57: 383285 | D57: 388331 | E57: 404258 | F57: 404258 | G57: 417882 | H57: 410186 | I57: 414605.86 | J57: 417934.21 | K57: 417797.9 | L57: 417215.14 | M57: 416725.5 | N57: 420467.09 | O57: 423703.46 | P57: 421899.14 | Q57: 416118.06 | R57: 416095.77 | S57: 418104.25 | T57: 419808.35 | U57: 423040.43 | V57: 413223.35 | W57: 411909.59 | X57: 414104.81 | Y57: 414140.94 | Z57: 426208.25 | AA57: 412013 | AB57: 410887.47 | AC57: 411695.12 | AD57: 414073.54 | AE57: 429077.1
A59: Debt
A60: Supp - Total debt | B60: 143649 | C60: 145996 | D60: 146775 | E60: 158150 | F60: 158150 | G60: 172460 | H60: 165231 | I60: 164750.26 | J60: 163782.45 | K60: 163177.75 | L60: 163217.51 | M60: 162244.63 | N60: 162533.51 | O60: 162101.68 | P60: 161831.54 | Q60: 162273.96 | R60: 162542 | S60: 163434.4 | T60: 163369.22 | U60: 163045.41 | V60: 165683.02 | W60: 166045.41 | X60: 167153.84 | Y60: 166472.04 | Z60: 162928.97 | AA60: 166871.24 | AB60: 167457.44 | AC60: 167821.14 | AD60: 167895.54 | AE60: 161675.7
A61: Cash and short-term investments | B61: 2257 | C61: 3435 | D61: 7706 | E61: 19048 | F61: 19048 | G61: 8366 | H61: 1752 | I61: 3509.75 | J61: 4829.82 | K61: 5010.65 | L61: 4019.84 | M61: 4027.01 | N61: 3382.77 | O61: 4141.25 | P61: 5279.76 | Q61: 2564.68 | R61: 2861.5 | S61: 2466.91 | T61: 2293.35 | U61: 6842.32 | V61: 2605.05 | W61: 2944.21 | X61: 5147.27 | Y61: 5075.03 | Z61: 12574.3 | AA61: 4439.21 | AB61: 5089.11 | AC61: 7434.46 | AD61: 7375.6 | AE61: 17359.43
A62: Net Debt | B62: 141392 | C62: 142561 | D62: 139069 | E62: 139102 | F62: 139102 | G62: 164094 | H62: 163479 | I62: 160826.46 | J62: 158683.04 | K62: 157729.36 | L62: 159439.78 | M62: 159138.49 | N62: 160171.95 | O62: 159218.84 | P62: 156658.72 | Q62: 161219.84 | R62: 161906.06 | S62: 163036.9 | T62: 163740.84 | U62: 157222.01 | V62: 167716.75 | W62: 168650.19 | X62: 168078.66 | Y62: 168236.93 | Z62: 153278.47 | AA62: 166175.54 | AB62: 166739.95 | AC62: 164927.78 | AD62: 165924.89 | AE62: 148622.61
A63: Secured Debt | B63: 26336 | C63: 26600 | D63: 27061 | E63: 27067 | F63: 27067 | G63: 29962 | H63: 28760 | I63: 28950.25 | J63: 28950.25 | K63: 28627.73 | L63: 30932 | M63: 30932 | N63: 30932 | O63: 30932 | P63: 28682.41 | Q63: 34797 | R63: 34797 | S63: 34797 | T63: 34797 | U63: 29155.29 | V63: 34797 | W63: 34797 | X63: 34797 | Y63: 34797 | Z63: 29225.01 | AA63: 34797 | AB63: 34797 | AC63: 34797 | AD63: 34797 | AE63: 29295.42
A64: Net unsecured debt | B64: 115056 | C64: 115961 | D64: 112008 | E64: 110053 | F64: 110053 | G64: 130053 | H64: 128682 | I64: 133760.41 | J64: 131681.55 | K64: 129082.37 | L64: 129995.91 | M64: 131436.48 | N64: 129333.31 | O64: 128451.61 | P64: 128754.19 | Q64: 127057.54 | R64: 129572.88 | S64: 127806.04 | T64: 129523.17 | U64: 129754.71 | V64: 133312.47 | W64: 136716.76 | X64: 134543.82 | Y64: 138369.14 | Z64: 128751.22 | AA64: 139406.35 | AB64: 143710.01 | AC64: 142212.05 | AD64: 146590.16 | AE64: 127232.17

Sheet Income statement
A2: Verizon Communications Inc. | Income statement
A3: NYSE:VZ (MI KEY: 4057229; SPCIQ KEY: 415798)
A5: Visible Alpha
A7: Period Type : Fiscal Quarter, Fiscal Halves, Fiscal Year
A8: Period Start : 2025
A9: Period End : 2030
A10: Currency : Reported
A11: Consensus View : Mean
A12: As Of: 10/25/2026
A14: All numbers in $M unless otherwise indicated | B14: FQ1 2025A | C14: FQ2 2025A | D14: FQ3 2025A | E14: FQ4 2025A | F14: FY2025A | G14: FQ1 2026A | H14: FQ2 2026A | I14: FQ3 2026E | J14: FQ4 2026E | K14: FY2026E | L14: FQ1 2027E | M14: FQ2 2027E | N14: FQ3 2027E | O14: FQ4 2027E | P14: FY2027E | Q14: FQ1 2028E | R14: FQ2 2028E | S14: FQ3 2028E | T14: FQ4 2028E | U14: FY2028E | V14: FQ1 2029E | W14: FQ2 2029E | X14: FQ3 2029E | Y14: FQ4 2029E | Z14: FY2029E | AA14: FQ1 2030E | AB14: FQ2 2030E | AC14: FQ3 2030E | AD14: FQ4 2030E | AE14: FY2030E
A15: Number of Contributors Available | B15: 19 | C15: 19 | D15: 19 | E15: 19 | F15: 20 | G15: 20 | H15: 20 | I15: 20 of 20 | J15: 20 of 20 | K15: 20 of 20 | L15: 13 of 20 | M15: 13 of 20 | N15: 12 of 20 | O15: 12 of 20 | P15: 20 of 20 | Q15: 7 of 20 | R15: 7 of 20 | S15: 7 of 20 | T15: 7 of 20 | U15: 18 of 20 | V15: 5 of 20 | W15: 5 of 20 | X15: 5 of 20 | Y15: 5 of 20 | Z15: 14 of 20 | AA15: 5 of 20 | AB15: 5 of 20 | AC15: 5 of 20 | AD15: 5 of 20 | AE15: 14 of 20
A16: Service revenues and other | B16: 28087 | C16: 28249 | D16: 28202 | E16: 28183 | F16: 112721 | G16: 28759 | H16: 29229 | I16: 29275.35 | J16: 29485.76 | K16: 116755.23 | L16: 29425.41 | M16: 29620.34 | N16: 29606.36 | O16: 29869.15 | P16: 118456.24 | Q16: 29655.14 | R16: 29850.03 | S16: 29784 | T16: 30023.76 | U16: 119410.82 | V16: 29901.34 | W16: 30092.34 | X16: 29917.36 | Y16: 30158.97 | Z16: 120899.01 | AA16: 30090.4 | AB16: 30284.4 | AC16: 30083.58 | AD16: 30318.98 | AE16: 121698.25
A17: Wireless equipment revenues | B17: 5398 | C17: 6255 | D17: 5619 | E17: 8198 | F17: 25470 | G17: 5681 | H17: 5024 | I17: 5444.78 | J17: 7798.8 | K17: 23942.47 | L17: 5909.46 | M17: 5441.35 | N17: 5551.61 | O17: 7926.31 | P17: 24821.18 | Q17: 6063.63 | R17: 5735.04 | S17: 5643.93 | T17: 8158.98 | U17: 25342.68 | V17: 6123.01 | W17: 5460.13 | X17: 5526.68 | Y17: 7893.21 | Z17: 25100.87 | AA17: 6212.16 | AB17: 5537.56 | AC17: 5603.24 | AD17: 8006.64 | AE17: 25426.3
A18: Operating revenues | B18: 33485 | C18: 34504 | D18: 33821 | E18: 36381 | F18: 138191 | G18: 34440 | H18: 34253 | I18: 34767.99 | J18: 37338.71 | K18: 140869.69 | L18: 35282.92 | M18: 35119.78 | N18: 35157.97 | O18: 37795.46 | P18: 143512.71 | Q18: 35718.77 | R18: 35585.08 | S18: 35427.93 | T18: 38182.74 | U18: 145247.85 | V18: 36024.35 | W18: 35552.48 | X18: 35444.04 | Y18: 38052.19 | Z18: 146846.84 | AA18: 36302.56 | AB18: 35821.97 | AC18: 35686.82 | AD18: 38325.61 | AE18: 148307.92
A19: Cost of services | B19: 6950 | C19: 6878 | D19: 6863 | E19: 7098 | F19: 27789 | G19: 7167 | H19: 7225 | I19: 7159.92 | J19: 7235.2 | K19: 28770.42 | L19: 7272.3 | M19: 7222.54 | N19: 7148.92 | O19: 7273.7 | P19: 28909 | Q19: 7282.86 | R19: 7231.33 | S19: 7114.56 | T19: 7247.3 | U19: 29032.54 | V19: 7350.49 | W19: 7303.06 | X19: 7124.68 | Y19: 7258.22 | Z19: 29295.24 | AA19: 7369.69 | AB19: 7326.85 | AC19: 7136.53 | AD19: 7268.69 | AE19: 29400.68
A20: Cost of wireless equipment | B20: 6106 | C20: 7007 | D20: 6483 | E20: 9380 | F20: 28976 | G20: 6506 | H20: 5859 | I20: 6300.47 | J20: 8928.79 | K20: 27592.79 | L20: 6758.1 | M20: 6263.52 | N20: 6438.11 | O20: 9168.88 | P20: 28649.58 | Q20: 6920.3 | R20: 6568.38 | S20: 6443.63 | T20: 9295.96 | U20: 29028.6 | V20: 6961.02 | W20: 6266.3 | X20: 6298.82 | Y20: 8927.48 | Z20: 28912.26 | AA20: 7051.53 | AB20: 6345.12 | AC20: 6376.91 | AD20: 9044.97 | AE20: 29319.41
A21: Cost of services and sales -Operating | B21: 13056 | C21: 13885 | D21: 13346 | E21: 16478 | F21: 56765 | G21: 13673 | H21: 13084 | I21: 13451.92 | J21: 16149.04 | K21: 56340.79 | L21: 14030.4 | M21: 13486.06 | N21: 13587.03 | O21: 16442.58 | P21: 57482.57 | Q21: 14203.15 | R21: 13799.71 | S21: 13558.19 | T21: 16543.26 | U21: 57977.78 | V21: 14311.51 | W21: 13569.37 | X21: 13423.5 | Y21: 16185.7 | Z21: 58145.06 | AA21: 14421.22 | AB21: 13671.97 | AC21: 13513.44 | AD21: 16313.66 | AE21: 58663.3
A22: Selling, general and admin. exp. - Operating | B22: 7874 | C22: 7812 | D22: 7700 | E22: 8043 | F22: 31429 | G22: 7372 | H22: 7446 | I22: 7586.89 | J22: 8042.84 | K22: 31112.36 | L22: 7429.02 | M22: 7745.23 | N22: 7467.75 | O22: 8422.53 | P22: 30851.31 | Q22: 7377.62 | R22: 7529.5 | S22: 7404.82 | T22: 7822.66 | U22: 30071.08 | V22: 7204.9 | W22: 7400.9 | X22: 7236.81 | Y22: 7720.71 | Z22: 29963.66 | AA22: 7169.04 | AB22: 7364.24 | AC22: 7190.75 | AD22: 7676.01 | AE22: 29947.07
A23: Total adjustment to Selling, general and administrative exp. | B23: 352.54 | C23: 326.53 | D23: 52 | E23: 2337 | F23: 2389 | G23: 261 | H23: 1536 | I23: 261 | J23: 261 | K23: 1579.38 | L23: 261 | M23: 261 | N23: 130.5 | O23: -2969.33 | P23: -2577.83 | Q23: - | R23: - | S23: - | T23: - | U23: - | V23: - | W23: - | X23: - | Y23: - | Z23: - | AA23: - | AB23: - | AC23: - | AD23: - | AE23: -
A24: Selling, general and administrative expense | B24: 7874 | C24: 7812 | D24: 7752 | E24: 10380 | F24: 33818 | G24: 7633 | H24: 8982 | I24: 7611.47 | J24: 8110.16 | K24: 32464.99 | L24: 7433.15 | M24: 7748.86 | N24: 7468.65 | O24: 7911.33 | P24: 30648.2 | Q24: 7386.98 | R24: 7536.38 | S24: 7400.6 | T24: 7839.14 | U24: 30034.78 | V24: 7204.9 | W24: 7400.9 | X24: 7236.81 | Y24: 7720.71 | Z24: 29892.15 | AA24: 7169.04 | AB24: 7364.24 | AC24: 7190.75 | AD24: 7676.01 | AE24: 29888.16
A25: Total operations and support - Operating | B25: 20930 | C25: 21697 | D25: 21046 | E25: 24521 | F25: 88194 | G25: 21045 | H25: 20530 | I25: 21064.64 | J25: 24270.53 | K25: 87629.44 | L25: 21459.42 | M25: 21231.29 | N25: 21054.78 | O25: 24865.11 | P25: 88538.84 | Q25: 21580.78 | R25: 21329.21 | S25: 20963.01 | T25: 24365.92 | U25: 88392.43 | V25: 21516.41 | W25: 20970.26 | X25: 20660.3 | Y25: 23906.41 | Z25: 88614.61 | AA25: 21590.26 | AB25: 21036.21 | AC25: 20704.18 | AD25: 23989.66 | AE25: 89176.95
A26: Depreciation and amortization expense | B26: 4577 | C26: 4635 | D26: 4618 | E26: 4519 | F26: 18349 | G26: 4892 | H26: 5008 | I26: 4975.75 | J26: 5015.47 | K26: 19886.06 | L26: 5020.06 | M26: 5049.13 | N26: 5064.56 | O26: 5070.69 | P26: 19972.73 | Q26: 5075.42 | R26: 5123.95 | S26: 5128.67 | T26: 5079.46 | U26: 20017.81 | V26: 5132.81 | W26: 5167.99 | X26: 5173.01 | Y26: 5139.19 | Z26: 20229.77 | AA26: 5200.65 | AB26: 5235.13 | AC26: 5239.79 | AD26: 5203.89 | AE26: 20394.95
A27: Total operating expenses | B27: 25507 | C27: 26332 | D27: 25716 | E27: 31377 | F27: 108932 | G27: 26198 | H27: 27074 | I27: 25977.67 | J27: 29232.07 | K27: 108555.39 | L27: 26417.49 | M27: 26087.11 | N27: 26047.53 | O27: 29197.18 | P27: 108002.97 | Q27: 26417.22 | R27: 25936.01 | S27: 25841.31 | T27: 28809.23 | U27: 107896.57 | V27: 26565.26 | W27: 26045.69 | X27: 25738.31 | Y27: 28956.07 | Z27: 108065.24 | AA27: 26669.4 | AB27: 26141.07 | AC27: 25811.02 | AD27: 29066.05 | AE27: 108679.72
A28: Total operating expenses -Operating | B28: 25507 | C28: 26332 | D28: 25664 | E28: 29040 | F28: 106543 | G28: 25937 | H28: 25538 | I28: 26004.84 | J28: 29265.43 | K28: 107527.58 | L28: 26393.76 | M28: 26063.38 | N28: 26023.81 | O28: 29737.06 | P28: 108464.66 | Q28: 26417.22 | R28: 25936.01 | S28: 25841.31 | T28: 28809.23 | U28: 108149.87 | V28: 26565.26 | W28: 26045.69 | X28: 25738.31 | Y28: 28956.07 | Z28: 108454.61 | AA28: 26669.4 | AB28: 26141.07 | AC28: 25811.02 | AD28: 29066.05 | AE28: 109101.17
A29: Adjusted EBITDA | B29: 12555 | C29: 12807 | D29: 12775 | E29: 11860 | F29: 49997 | G29: 13395 | H29: 13723 | I29: 13691.51 | J29: 13088.18 | K29: 53752.39 | L29: 13911.4 | M29: 13958.05 | N29: 14127.43 | O29: 13449.57 | P29: 55419.85 | Q29: 14128.63 | R29: 14248.99 | S29: 14469.15 | T29: 13800.33 | U29: 56817.42 | V29: 14507.94 | W29: 14582.21 | X29: 14783.74 | Y29: 14145.78 | Z29: 58232.23 | AA29: 14712.29 | AB29: 14785.76 | AC29: 14982.64 | AD29: 14335.95 | AE29: 59130.97
A30: Operating income/(loss) -Operating | B30: 7978 | C30: 8172 | D30: 8157 | E30: 7341 | F30: 31648 | G30: 8503 | H30: 8715 | I30: 8728.72 | J30: 8080.7 | K30: 34040.45 | L30: 8930.57 | M30: 8931.91 | N30: 9087.29 | O30: 8454.13 | P30: 35508.19 | Q30: 9169.92 | R30: 9219.83 | S30: 9412.6 | T30: 8938.4 | U30: 36934.38 | V30: 9459.09 | W30: 9506.79 | X30: 9705.73 | Y30: 9096.12 | Z30: 38154.03 | AA30: 9633.16 | AB30: 9680.9 | AC30: 9875.8 | AD30: 9259.56 | AE30: 38934.35
A31: Total adjustments in Operating income/(loss) | B31: 63 | C31: 116 | D31: 52 | E31: 2337 | F31: 2389 | G31: 261 | H31: 1536 | I31: 109.86 | J31: 1092.41 | K31: 1808.91 | L31: 39.15 | M31: 768 | N31: 17.89 | O31: 602.95 | P31: 340.92 | Q31: - | R31: - | S31: - | T31: - | U31: -208.78 | V31: - | W31: - | X31: - | Y31: - | Z31: 700 | AA31: - | AB31: - | AC31: - | AD31: - | AE31: 700
A32: Operating income/(loss) | B32: 7978 | C32: 8172 | D32: 8105 | E32: 5004 | F32: 29259 | G32: 8242 | H32: 7179 | I32: 8742.86 | J32: 7984.1 | K32: 32281.17 | L32: 8953.39 | M32: 8843.97 | N32: 9085.66 | O32: 8399.32 | P32: 35454.59 | Q32: 9169.92 | R32: 9219.83 | S32: 9412.6 | T32: 8938.4 | U32: 36860.72 | V32: 9459.09 | W32: 9506.79 | X32: 9705.73 | Y32: 9096.12 | Z32: 37940.08 | AA32: 9633.16 | AB32: 9680.9 | AC32: 9875.8 | AD32: 9259.56 | AE32: 38590.13
A33: Equity in earnings of unconsolidated businesses | B33: 6 | C33: -3 | D33: -6 | E33: 3 | F33: - | G33: 5 | H33: 44 | I33: 11.9 | J33: 14.4 | K33: 60.21 | L33: 3.93 | M33: 18.62 | N33: 1.93 | O33: 3.32 | P33: 47.41 | Q33: 9.66 | R33: 29.2 | S33: 4.16 | T33: 8.77 | U33: 43.63 | V33: 5 | W33: 44 | X33: -6 | Y33: 3 | Z33: 37.88 | AA33: 5 | AB33: 44 | AC33: -6 | AD33: 3 | AE33: 37.71
A34: Other income, net | B34: 121 | C34: 79 | D34: 92 | E34: -185 | F34: 107 | G34: 477 | H34: 36 | I34: 87.55 | J34: 76.83 | K34: 636.77 | L34: 118.1 | M34: 115.14 | N34: 113.48 | O34: 117.73 | P34: 396 | Q34: 55.88 | R34: 53.72 | S34: 53.05 | T34: 55.98 | U34: 230.81 | V34: 27.87 | W34: 27.93 | X34: 29.61 | Y34: 28.98 | Z34: 221.71 | AA34: 31.29 | AB34: 34.41 | AC34: 36.98 | AD34: 41.45 | AE34: 242.19
A35: Other income, net - Operating | B35: -5.45 | C35: -12.34 | D35: -25.51 | E35: 224.64 | F35: 81.77 | G35: 185 | H35: -92.05 | I35: 45.92 | J35: 117.78 | K35: 210.18 | L35: 26.89 | M35: 3.45 | N35: 3.45 | O35: -71.55 | P35: -37.75 | Q35: -81.53 | R35: -95.59 | S35: -95.59 | T35: -95.59 | U35: -368.3 | V35: -106.29 | W35: -101.6 | X35: -101.6 | Y35: -101.6 | Z35: -411.08 | AA35: -107.57 | AB35: -108.44 | AC35: -99.16 | AD35: -77.37 | AE35: -392.55
A36: Interest expense | B36: 1632 | C36: 1639 | D36: 1664 | E36: 1759 | F36: 6694 | G36: 1940 | H36: 1985 | I36: 1939.74 | J36: 1922.08 | K36: 7781.91 | L36: 1940.05 | M36: 1932.61 | N36: 1927.83 | O36: 1941.54 | P36: 7712.69 | Q36: 1949.8 | R36: 1943.92 | S36: 1940.34 | T36: 1952.01 | U36: 7771.81 | V36: 1964.68 | W36: 1953.01 | X36: 1955.46 | Y36: 1952.81 | Z36: 7776.55 | AA36: 1945.7 | AB36: 1938.62 | AC36: 1941.06 | AD36: 1929.86 | AE36: 7722.77
A37: Total non-operating expenses | B37: -1505 | C37: -1563 | D37: -1578 | E37: -1941 | F37: -6587 | G37: -1458 | H37: -1905 | I37: -1852.27 | J37: -1840.68 | K37: -7090.35 | L37: -1846.85 | M37: -1834.82 | N37: -1840.64 | O37: -1851.27 | P37: -7348.7 | Q37: -1922.5 | R37: -1904.68 | S37: -1918.32 | T37: -1927.23 | U37: -7593.91 | V37: -1940.39 | W37: -1913.07 | X37: -1934.17 | Y37: -1928.42 | Z37: -7611.42 | AA37: -1918.67 | AB37: -1893.49 | AC37: -1913.88 | AD37: -1895.5 | AE37: -7588.07
A38: Income before provision for income taxes | B38: 6473 | C38: 6609 | D38: 6527 | E38: 3063 | F38: 22672 | G38: 6784 | H38: 5274 | I38: 6891.42 | J38: 6192.62 | K38: 25208.79 | L38: 7088.49 | M38: 7065.11 | N38: 7283.13 | O38: 6543.72 | P38: 28049.19 | Q38: 7273.58 | R38: 7378.07 | S38: 7586.95 | T38: 6949.44 | U38: 29332.41 | V38: 7518.7 | W38: 7593.72 | X38: 7771.56 | Y38: 7167.7 | Z38: 30374.39 | AA38: 7714.49 | AB38: 7787.41 | AC38: 7961.93 | AD38: 7364.07 | AE38: 31046.61
A39: Income before provision for income taxes - Operating | B39: 6576.02 | C39: 6731.06 | D39: 6692.5 | E39: 6287.33 | F39: 26286.91 | G39: 6933.25 | H39: 6995.99 | I39: 7020.2 | J39: 6335.93 | K39: 27138.05 | L39: 6969.84 | M39: 7761.35 | N39: 7230.87 | O39: 6471.9 | P39: 28569.61 | Q39: 7242.58 | R39: 8056.67 | S39: 7524.89 | T39: 6832.27 | U39: 30402.47 | V39: 7371.47 | W39: 8232.61 | X39: 7693.23 | Y39: 6974.57 | Z39: 31913.75 | AA39: 7674.21 | AB39: 8526.54 | AC39: 8001.25 | AD39: 7296.82 | AE39: 33519.27
A40: Provision for income taxes | B40: 1490 | C40: 1488 | D40: 1471 | E40: 615 | F40: 5064 | G40: 1638 | H40: 1325 | I40: 1567.3 | J40: 1396.84 | K40: 5934.82 | L40: 1645.65 | M40: 1638.91 | N40: 1694.22 | O40: 1522.3 | P40: 6445.71 | Q40: 1687.58 | R40: 1714.69 | S40: 1760.08 | T40: 1609.84 | U40: 6694.68 | V40: 1710.55 | W40: 1730.88 | X40: 1766.22 | Y40: 1628.51 | Z40: 6863.26 | AA40: 1755.1 | AB40: 1774.94 | AC40: 1809.45 | AD40: 1673.04 | AE40: 7020.9
A41: Provision for income taxes - Operating | B41: 1448.61 | C41: 1543.06 | D41: 1457.88 | E41: 1230.44 | F41: 5679.98 | G41: 1470.35 | H41: 1486.34 | I41: 1607.58 | J41: 1416.18 | K41: 5927.68 | L41: 1646.06 | M41: 1833.45 | N41: 1707.7 | O41: 1527.24 | P41: 6597.26 | Q41: 1710.31 | R41: 1903.17 | S41: 1777.01 | T41: 1612.54 | U41: 6993.92 | V41: 1740.02 | W41: 1944.02 | X41: 1816.2 | Y41: 1645.56 | Z41: 7367.59 | AA41: 1811.56 | AB41: 2013.41 | AC41: 1888.89 | AD41: 1721.59 | AE41: 7774.35
A42: Net income attri. to Verizon | B42: 4879 | C42: 5003 | D42: 4950 | E42: 2342 | F42: 17174 | G42: 5045 | H42: 3835 | I42: 5186.64 | J42: 4664.27 | K42: 18784.99 | L42: 5334.85 | M42: 5311.09 | N42: 5477.76 | O42: 4912.63 | P42: 21182.71 | Q42: 5474.03 | R42: 5544.51 | S42: 5712.66 | T42: 5228.03 | U42: 22262.93 | V42: 5690.55 | W42: 5738.16 | X42: 5885.52 | Y42: 5424.31 | Z42: 23235.55 | AA42: 5840.05 | AB42: 5885.81 | AC42: 6030.83 | AD42: 5574.49 | AE42: 23891.15
A43: Total post tax adjustments | B43: 142 | C43: 143 | D43: 193 | E43: 2262 | F43: 2740 | G43: 331 | H43: 1591 | I43: 181.14 | J43: 315.45 | K43: 2139.82 | L43: 121.48 | M43: 228.58 | N43: 113.09 | O43: 187.32 | P43: 483.75 | Q43: 123.31 | R43: 133.43 | S43: 114.37 | T43: 108.02 | U43: 372.73 | V43: 126.73 | W43: 135.52 | X43: 118.87 | Y43: 115.35 | Z43: 384.52 | AA43: 119.24 | AB43: 128.81 | AC43: 110.6 | AD43: 110.42 | AE43: 353.74
A44: Net income attri. to Verizon - Operating | B44: 5021 | C44: 5146 | D44: 5143 | E44: 4604 | F44: 19914 | G44: 5376 | H44: 5426 | I44: 5316.48 | J44: 4851.76 | K44: 20971.14 | L44: 5414.05 | M44: 5452.76 | N44: 5552.06 | O44: 5030.23 | P44: 21553.11 | Q44: 5544.5 | R44: 5620.75 | S44: 5778.02 | T44: 5289.75 | U44: 22521.06 | V44: 5791.93 | W44: 5846.58 | X44: 5980.61 | Y44: 5516.59 | Z44: 23562.73 | AA44: 5935.44 | AB44: 5988.86 | AC44: 6119.31 | AD44: 5662.83 | AE44: 24193.28
...

Sheet Segment
A2: Verizon Communications Inc. | Segment
A3: NYSE:VZ (MI KEY: 4057229; SPCIQ KEY: 415798)
A5: Visible Alpha
A7: Period Type : Fiscal Quarter, Fiscal Halves, Fiscal Year
A8: Period Start : 2025
A9: Period End : 2030
A10: Currency : Reported
A11: Consensus View : Mean
A12: As Of: 10/25/2026
A14: All numbers in $M unless otherwise indicated | B14: FQ1 2025A | C14: FQ2 2025A | D14: FQ3 2025A | E14: FQ4 2025A | F14: FY2025A | G14: FQ1 2026A | H14: FQ2 2026A | I14: FQ3 2026E | J14: FQ4 2026E | K14: FY2026E | L14: FQ1 2027E | M14: FQ2 2027E | N14: FQ3 2027E | O14: FQ4 2027E | P14: FY2027E | Q14: FQ1 2028E | R14: FQ2 2028E | S14: FQ3 2028E | T14: FQ4 2028E | U14: FY2028E | V14: FQ1 2029E | W14: FQ2 2029E | X14: FQ3 2029E | Y14: FQ4 2029E | Z14: FY2029E | AA14: FQ1 2030E | AB14: FQ2 2030E | AC14: FQ3 2030E | AD14: FQ4 2030E | AE14: FY2030E
A15: Number of Contributors Available | B15: 19 | C15: 19 | D15: 19 | E15: 19 | F15: 20 | G15: 20 | H15: 20 | I15: 20 of 20 | J15: 20 of 20 | K15: 20 of 20 | L15: 13 of 20 | M15: 13 of 20 | N15: 12 of 20 | O15: 12 of 20 | P15: 20 of 20 | Q15: 7 of 20 | R15: 7 of 20 | S15: 7 of 20 | T15: 7 of 20 | U15: 18 of 20 | V15: 5 of 20 | W15: 5 of 20 | X15: 5 of 20 | Y15: 5 of 20 | Z15: 14 of 20 | AA15: 5 of 20 | AB15: 5 of 20 | AC15: 5 of 20 | AD15: 5 of 20 | AE15: 14 of 20
A16: Total Revenue
A17: Mobility and broadband service - Consumer revenue | B17: 18801 | C17: 19002 | D17: 19096 | E17: 19024 | F17: 75923 | G17: 19180 | H17: 19637 | I17: 19772.17 | J17: 19892.47 | K17: 78481.64 | L17: 19811.36 | M17: 20060.92 | N17: 20205.41 | O17: 20384.12 | P17: 80428.37 | Q17: 20314.57 | R17: 20384.6 | S17: 20600.29 | T17: 20782.71 | U17: 82264.66 | V17: 20736.49 | W17: 20805.2 | X17: 21021.81 | Y17: 21198.39 | Z17: 84629.72 | AA17: 21128.11 | AB17: 21193.1 | AC17: 21410.57 | AD17: 21582.48 | AE17: 86156.61
A18: Wireless equipment - Consumer revenue | B18: 4532 | C18: 5369 | D18: 4766 | E18: 7112 | F18: 21779 | G18: 4824 | H18: 4178 | I18: 4702.67 | J18: 6850.42 | K18: 20555.08 | L18: 5022.61 | M18: 4478.76 | N18: 4764.71 | O18: 6950.22 | P18: 21192.17 | Q18: 5200.2 | R18: 4637.88 | S18: 4750.49 | T18: 6943.42 | U18: 21558.91 | V18: 5275.6 | W18: 4711.31 | X18: 4826.76 | Y18: 7051.47 | Z18: 21905.92 | AA18: 5365.12 | AB18: 4791.66 | AC18: 4907.12 | AD18: 7169.39 | AE18: 22317.36
A19: Other - Consumer revenue | B19: 2285 | C19: 2277 | D19: 2243 | E19: 2300 | F19: 9105 | G19: 2449 | H19: 2427 | I19: 2367.38 | J19: 2423.71 | K19: 9667.09 | L19: 2396.45 | M19: 2509.83 | N19: 2350.69 | O19: 2428.81 | P19: 9626.98 | Q19: 2356.92 | R19: 2327.01 | S19: 2276.2 | T19: 2311.13 | U19: 9531.25 | V19: 2300.54 | W19: 2277.57 | X19: 2226.4 | Y19: 2263.09 | Z19: 9472.41 | AA19: 2245.59 | AB19: 2227.58 | AC19: 2177.78 | AD19: 2217.77 | AE19: 9435.79
A20: Consumer revenue | B20: 25618 | C20: 26648 | D20: 26105 | E20: 28436 | F20: 106807 | G20: 26453 | H20: 26242 | I20: 26901.66 | J20: 29297.33 | K20: 109199.99 | L20: 27260.45 | M20: 27452.45 | N20: 27365.61 | O20: 29899.88 | P20: 111777.76 | Q20: 27859.95 | R20: 28078.08 | S20: 27814.54 | T20: 30452.56 | U20: 113914.48 | V20: 28134.02 | W20: 27892.22 | X20: 27893.33 | Y20: 30291.06 | Z20: 115768.21 | AA20: 28473.62 | AB20: 28254.1 | AC20: 28220.46 | AD20: 30652.32 | AE20: 117513.61
A21: Mobility and broadband service - Business revenue | B21: 3717 | C21: 3733 | D21: 3743 | E21: 3747 | F21: 14940 | G21: 3688 | H21: 3728 | I21: 3774.46 | J21: 3770.83 | K21: 14961.29 | L21: 3733.38 | M21: 3724.54 | N21: 3786.06 | O21: 3825.12 | P21: 15118.9 | Q21: 3774.25 | R21: 3695.16 | S21: 3744.27 | T21: 3801.58 | U21: 15271.95 | V21: 3817.21 | W21: 3716.71 | X21: 3763.66 | Y21: 3826.73 | Z21: 15478.85 | AA21: 3855.36 | AB21: 3735.67 | AC21: 3781.37 | AD21: 3850.15 | AE21: 15658.96
A22: Wireless equipment - Business revenue | B22: 866 | C22: 886 | D22: 853 | E22: 1087 | F22: 3692 | G22: 857 | H22: 846 | I22: 857.09 | J22: 1129.68 | K22: 3689.77 | L22: 906.08 | M22: 862.47 | N22: 864.69 | O22: 1141.51 | P22: 3806.25 | Q22: 947.72 | R22: 903.37 | S22: 886.29 | T22: 1174.39 | U22: 3976.44 | V22: 963.62 | W22: 918.62 | X22: 902.29 | Y22: 1194.92 | Z22: 3983.11 | AA22: 982.32 | AB22: 935.47 | AC22: 919.26 | AD22: 1217.35 | AE22: 4049.76
A23: Other - Business revenue | B23: 2419 | C23: 2354 | D23: 2247 | E23: 2243 | F23: 9263 | G23: 2585 | H23: 2581 | I23: 2616.77 | J23: 2595.61 | K23: 10475.49 | L23: 2662.78 | M23: 2633.98 | N23: 2521.53 | O23: 2536.6 | P23: 10369.27 | Q23: 2505.48 | R23: 2487.61 | S23: 2396.96 | T23: 2412.27 | U23: 9974.55 | V23: 2387.32 | W23: 2357.29 | X23: 2272.11 | Y23: 2285.25 | Z23: 9543.19 | AA23: 2283.26 | AB23: 2241.95 | AC23: 2161.63 | AD23: 2172.83 | AE23: 9234.42
A24: Business revenue | B24: 7002 | C24: 6973 | D24: 6843 | E24: 7077 | F24: 29069 | G24: 7130 | H24: 7155 | I24: 7259.08 | J24: 7509.81 | K24: 29256.56 | L24: 7337.87 | M24: 7238.86 | N24: 7168.08 | O24: 7482.67 | P24: 29322.39 | Q24: 7289.21 | R24: 7154.03 | S24: 7057.54 | T24: 7393.92 | U24: 29344.89 | V24: 7152.35 | W24: 6909.13 | X24: 6849.87 | Y24: 7184.08 | Z24: 29078.38 | AA24: 7042.65 | AB24: 6776.71 | AC24: 6723.68 | AD24: 7065.25 | AE24: 28938.32
A25: Total telecom revenue | B25: 32620 | C25: 33621 | D25: 32948 | E25: 35513 | F25: 135876 | G25: 33583 | H25: 33397 | I25: 34160.75 | J25: 36807.14 | K25: 138474.32 | L25: 34598.31 | M25: 34691.3 | N25: 34533.69 | O25: 37382.55 | P25: 141100.15 | Q25: 35149.16 | R25: 35232.1 | S25: 34872.08 | T25: 37846.47 | U25: 143259.36 | V25: 35286.37 | W25: 34801.35 | X25: 34743.2 | Y25: 37475.14 | Z25: 144846.59 | AA25: 35516.27 | AB25: 35030.8 | AC25: 34944.14 | AD25: 37717.56 | AE25: 146451.93
A26: Corporate and other revenue | B26: 865 | C26: 883 | D26: 873 | E26: 868 | F26: 3489 | G26: 857 | H26: 856 | I26: 773.72 | J26: 769.62 | K26: 3136.01 | L26: 774.32 | M26: 793.99 | N26: 777.42 | O26: 774.93 | P26: 3124.38 | Q26: 707.2 | R26: 743.8 | S26: 711.59 | T26: 708.1 | U26: 2885.55 | V26: 685.06 | W26: 735.67 | X26: 690.95 | Y26: 686 | Z26: 2818.49 | AA26: 686.05 | AB26: 735.92 | AC26: 691.71 | AD26: 686.52 | AE26: 2746.51
A27: Operating revenues | B27: 33485 | C27: 34504 | D27: 33821 | E27: 36381 | F27: 138191 | G27: 34440 | H27: 34253 | I27: 34767.99 | J27: 37338.71 | K27: 140869.69 | L27: 35282.92 | M27: 35119.78 | N27: 35157.97 | O27: 37795.46 | P27: 143512.71 | Q27: 35718.77 | R27: 35585.08 | S27: 35427.93 | T27: 38182.74 | U27: 145247.85 | V27: 36024.35 | W27: 35552.48 | X27: 35444.04 | Y27: 38052.19 | Z27: 146846.84 | AA27: 36302.56 | AB27: 35821.97 | AC27: 35686.82 | AD27: 38325.61 | AE27: 148307.92
A29: Mobility and broadband service revenue | B29: 22518 | C29: 22735 | D29: 22839 | E29: 22771 | F29: 90863 | G29: 22868 | H29: 23365 | I29: 23537.92 | J29: 23668.13 | K29: 93439.05 | L29: 23567.31 | M29: 23887.5 | N29: 24002.34 | O29: 24198.56 | P29: 95636.76 | Q29: 24096.84 | R29: 24393.11 | S29: 24426.98 | T29: 24625.65 | U29: 97628.4 | V29: 24546.27 | W29: 24873.83 | X29: 24787.53 | Y29: 24989.43 | Z29: 99953.23 | AA29: 24940.61 | AB29: 25266.74 | AC29: 25153.4 | AD29: 25350.98 | AE29: 101594.52
... A33: Operating revenues | B33: 33485 | C33: 34504 | D33: 33821 | E33: 36381 | F33: 138191 | G33: 34440 | H33: 34253 | I33: 34767.99 | J33: 37338.71 | K33: 140869.69 | L33: 35282.92 | M33: 35119.78 | N33: 35157.97 | O33: 37795.46 | P33: 143512.71 | Q33: 35718.77 | R33: 35585.08 | S33: 35427.93 | T33: 38182.74 | U33: 145247.85 | V33: 36024.35 | W33: 35552.48 | X33: 35444.04 | Y33: 38052.19 | Z33: 146846.84 | AA33: 36302.56 | AB33: 35821.97 | AC33: 35686.82 | AD33: 38325.61 | AE33: 148307.92
A35: FiOS Revenue
A36: FiOS Total digital revenue - Consumer | B36: 2896 | C36: 2924 | D36: 2937 | E36: 2921 | F36: 11678 | G36: 3249.42 | H36: 3540.64 | I36: 3610.55 | J36: 3646.33 | K36: 13648.6 | L36: 3630.55 | M36: 3741.5 | N36: 3690.29 | O36: 3710.84 | P36: 14764.48 | Q36: 3816.56 | R36: 4003.03 | S36: 3883.42 | T36: 3879 | U36: 15560.79 | V36: 4071.38 | W36: 4358.72 | X36: 4100.96 | Y36: 4137.91 | Z36: 16200.47 | AA36: 4163.93 | AB36: 4497.1 | AC36: 4191.72 | AD36: 4222.82 | AE36: 16573.59
A37: FiOS Total digital revenue - Business | B37: 310 | C37: 310 | D37: 310 | E37: 314 | F37: 1244 | G37: 342.24 | H37: 370.89 | I37: 359.23 | J37: 360.84 | K37: 1390.75 | L37: 375.72 | M37: 367.84 | N37: 364.95 | O37: 371.93 | P37: 1430.94 | Q37: 397.21 | R37: 384.01 | S37: 379.05 | T37: 389.13 | U37: 1436.75 | V37: 413.51 | W37: 391.32 | X37: 381.52 | Y37: 387.53 | Z37: 1426.62 | AA37: 410.82 | AB37: 388.09 | AC37: 378.23 | AD37: 383.86 | AE37: 1431.84
A38: FiOS Total digital revenue | B38: 3206 | C38: 3234 | D38: 3247 | E38: 3235 | F38: 12922 | G38: 3631.51 | H38: 3977.32 | I38: 4047.14 | J38: 4095.48 | K38: 15347.92 | L38: 4140.16 | M38: 4251.45 | N38: 4189.81 | O38: 4212.64 | P38: 16526.26 | Q38: 4213.78 | R38: 4387.04 | S38: 4262.47 | T38: 4268.13 | U38: 16949.28 | V38: 4484.89 | W38: 4750.04 | X38: 4482.48 | Y38: 4525.43 | Z38: 17529.11 | AA38: 4574.75 | AB38: 4885.19 | AC38: 4569.95 | AD38: 4606.68 | AE38: 17832.41
A40: Cost of services - Consumer | B40: 4574 | C40: 4581 | D40: 4635 | E40: 4643 | F40: 18433 | G40: 4820 | H40: 4928 | I40: 4813.24 | J40: 4832.84 | K40: 19328.05 | L40: 4824.56 | M40: 4806.68 | N40: 4806.46 | O40: 4868.49 | P40: 19362.53 | Q40: 4733.83 | R40: 4813.52 | S40: 4739.33 | T40: 4799.49 | U40: 19608.64 | V40: 4876.32 | W40: 4983.68 | X40: 4854.68 | Y40: 4933.69 | Z40: 20073.1 | AA40: 4892.88 | AB40: 5016.92 | AC40: 4873.24 | AD40: 4951.8 | AE40: 20214.79
A41: Cost of services - Business | B41: 2154 | C41: 2060 | D41: 1985 | E41: 2083 | F41: 8282 | G41: 2117 | H41: 2023 | I41: 2165.54 | J41: 2209.86 | K41: 8695.74 | L41: 2277.22 | M41: 2154.27 | N41: 2164.01 | O41: 2195.33 | P41: 8861.88 | Q41: 2189.71 | R41: 2044.08 | S41: 2021.06 | T41: 2043.69 | U41: 8707.2 | V41: 2057.42 | W41: 1873.92 | X41: 1866.29 | Y41: 1866.19 | Z41: 8546.92 | AA41: 1987.86 | AB41: 1798.11 | AC41: 1790.9 | AD41: 1790.92 | AE41: 8461.44
A42: Cost of revenue - Total telecom | B42: 6728 | C42: 6641 | D42: 6620 | E42: 6726 | F42: 26715 | G42: 6937 | H42: 6951 | I42: 6978.78 | J42: 7042.69 | K42: 28013.54 | L42: 7101.78 | M42: 6960.94 | N42: 6970.47 | O42: 7063.82 | P42: 28226.17 | Q42: 6923.54 | R42: 6857.6 | S42: 6760.39 | T42: 6843.18 | U42: 28329.31 | V42: 6933.74 | W42: 6857.6 | X42: 6720.97 | Y42: 6799.88 | Z42: 28620.02 | AA42: 6880.73 | AB42: 6815.03 | AC42: 6664.14 | AD42: 6742.72 | AE42: 28676.23
